Workbook
Name ____ML1: '[1]Material List '!$M$4:$M$5
Name ___ph1: [2]NPV!$B$40
Name __aoc1: '[4]01'!$H$43
Name __aoc10: #N/A
Name __aoc11: #REF!
Name __aoc2: '[4]02'!$H$24
Name __aoc3: '[4]03'!$H$21
Name __aoc4: '[4]04'!$H$33
Name __aoc7: #REF!
Name __aoc8: #REF!
Name __aoc9: #REF!
Name __ph1: [2]NPV!$B$40
Name __vut02533: #REF!
Name __xlnm.Print_Area: "$#REF!.$A$2:$I$161"
Name __xlnm.Print_Area_1: #REF!
Name __xlnm.Print_Area_10: #REF!
Name __xlnm.Print_Area_11: #REF!
Name __xlnm.Print_Area_12: #REF!
Name __xlnm.Print_Area_13: #REF!
Name __xlnm.Print_Area_14: #REF!
Name __xlnm.Print_Area_15: #REF!
Name __xlnm.Print_Area_16: #REF!
Name __xlnm.Print_Area_17: #REF!
Name __xlnm.Print_Area_18: #REF!
Name __xlnm.Print_Area_19: #REF!
Name __xlnm.Print_Area_2: #REF!
Name __xlnm.Print_Area_20: #REF!
Name __xlnm.Print_Area_22: #REF!
Name __xlnm.Print_Area_25: #REF!
Name __xlnm.Print_Area_26: #REF!
Name __xlnm.Print_Area_27: #REF!
Name __xlnm.Print_Area_3: #REF!
Name __xlnm.Print_Area_4: #REF!
Name __xlnm.Print_Area_5: #REF!
Name __xlnm.Print_Area_6: #REF!
Name __xlnm.Print_Area_8: #REF!
Name __xlnm.Print_Area_9: #REF!
Name __xlnm.Print_Titles: #N/A
Name __xlnm.Print_Titles_1: "$'Soft landscape'.$A$4:$AMJ$5"
Name __xlnm.Print_Titles_10: #REF!
Name __xlnm.Print_Titles_11: #REF!
Name __xlnm.Print_Titles_12: #REF!
Name __xlnm.Print_Titles_14: #REF!
Name __xlnm.Print_Titles_15: #REF!
Name __xlnm.Print_Titles_16: #REF!
Name __xlnm.Print_Titles_17: #REF!
Name __xlnm.Print_Titles_18: #REF!
Name __xlnm.Print_Titles_19: #REF!
Name __xlnm.Print_Titles_2: #REF!
Name __xlnm.Print_Titles_20: #REF!
Name __xlnm.Print_Titles_22: #REF!
Name __xlnm.Print_Titles_23: #REF!
Name __xlnm.Print_Titles_24: #REF!
Name __xlnm.Print_Titles_27: #REF!
Name __xlnm.Print_Titles_3: #REF!
Name __xlnm.Print_Titles_4: #REF!
Name __xlnm.Print_Titles_5: #REF!
Name __xlnm.Print_Titles_6: #REF!
Name __xlnm.Print_Titles_7: #REF!
Name __xlnm.Print_Titles_8: #REF!

Sheet Budget Tower-E
A1: OMAXE AANANDA, ALLAHABAD
A2: SUMMARY OF COST OF CIVIL WORK
A4: S.No. | B4: Description of Items | C4: Amount (Rs.) | D4: COST PER SQFT
D5: 259280 | E5: Salable Area
A6: A | B6: BUILDING WORK
A7: I. | B7: EARTH WORK & P.C.C. | C7: =+D7*$D$5 -> 4667040 | D7: 18
A9: II. | B9: R.C.C. | C9: =+D9*$D$5 -> 53152400 | D9: 205
A11: III. | B11: SHUTTERING | C11: =+D11*$D$5 -> 16075360 | D11: 62
A13: IV. | B13: STEEL REINFORCEMENT | C13: =+D13*$D$5 -> 84266000 | D13: 325
A15: V. | B15: BRICK WORK | C15: =+D15*$D$5 -> 29817200 | D15: 115
A17: VI | B17: WOOD WORK | C17: =+D17*$D$5 -> 32410000 | D17: 125
A19: VII. | B19: STEEL WORK | C19: =+D19*$D$5 -> 4634291.3 | D19: 17.873694
A21: VIII. | B21: FLOORING | C21: =+D21*$D$5 -> 30595040 | D21: 118
A23: IX. | B23: ROOFING | C23: =+D23*$D$5 -> 1555680 | D23: 6
A25: X. | B25: FINISHING | C25: =+D25*$D$5 -> 45374000 | D25: 175
A27: XI | B27: SPECIAL FEATURES (AC, Gyser, RO, Modular Kitchen, Dish Washer, Cup board, Home Theater) | C27: 66327503 | D27: =+C27/$D$5 -> 255.81419
A29: XII. | B29: MISCELLANEOUS | C29: =+D29*$D$5 -> 2312777.6 | D29: 8.92
A31: XIII. | B31: ENTRY AND ELEVATION | C31: =+D31*$D$5 -> 7778400 | D31: 30
B33: TOTAL OF CIVIL WORK Rs. = | C33: =SUM(C7:C32) -> 3.7896569e+08 | D33: =SUM(D7:D32) -> 1461.6079
A35: B | B35: OTHER WORK
A36: I. | B36: INTERNAL ELECTRICAL | C36: =+D36*$D$5 -> 18149600 | D36: 70
A38: II. | B38: PLUMBING WORK | C38: =+D38*$D$5 -> 18149600 | D38: 70
A40: III. | B40: LIFT | C40: =+D40*$D$5 -> 12964000 | D40: 50
A42: IV. | B42: EXTERNAL DEVELOPMENT | C42: =+D42*$D$5 -> 12964000 | D42: 50
A44: V. | B44: FIRE FIGHTING | C44: =+D44*$D$5 -> 7778400 | D44: 30
A46: VI. | B46: MECHANICAL VENT | C46: =+D46*$D$5 -> 0 | D46: 0
A48: VII. | B48: CLUB | C48: =+D48*$D$5 -> 12964000 | D48: 50
B50: TOTAL AMOUNT | C50: =SUM(C36:C48) -> 82969600 | D50: =SUM(D36:D48) -> 320
A52: C | B52: EXTERNAL DEVELOPMENT
A54: a | B54: ROAD WORK | D54: =C54/$D$5 -> 0
D55: =C55/$D$5 -> 0
A56: b | B56: SEWER AND STORM LINE WORK | D56: =C56/$D$5 -> 0
D57: =C57/$D$5 -> 0
A58: c | B58: UGT | D58: =C58/$D$5 -> 0
D59: =C59/$D$5 -> 0
A60: d | B60: STP | D60: =C60/$D$5 -> 0
D61: =C61/$D$5 -> 0
A62: e | B62: BOUNDARY WALL | D62: =C62/$D$5 -> 0
D63: =C63/$D$5 -> 0
A64: f | B64: DG/LT/PANEL ROOM | D64: =C64/$D$5 -> 0
...

Sheet Schedule-Tower-E
B3: Tower-E Estimated Budget | E3: Schedule of Work
B4: S.No. | C4: Description | D4: Amount | E4: Months
B5: A | C5: Building Work | E5: 45619 | F5: 45649 | G5: 45680 | H5: 45711 | I5: 45739 | J5: 45770 | K5: 45800 | L5: 45831 | M5: 45861 | N5: 45892 | O5: 45923 | P5: 45953 | Q5: 45984 | R5: 46014 | S5: 46045 | T5: 46076 | U5: 46104 | V5: 46135 | W5: 46165 | X5: 46196 | Y5: 46226 | Z5: 46257 | AA5: 46288 | AB5: 46318 | AC5: 46349 | AD5: 46379 | AE5: 46410 | AF5: 46441 | AG5: 46469 | AH5: 46500 | AI5: 46530 | AJ5: 46561 | AK5: 46591 | AL5: 46622 | AM5: 46653 | AN5: 46683 | AO5: 46714 | AP5: 46744 | AQ5: 46775 | AR5: 46806 | AS5: 46835 | AT5: 46866 | AU5: 46896 | AV5: 46927 | AW5: 46957
B6: 1 | C6: Earthwork & PCC (including other works over existing structure) | D6: =+'Budget Tower-E'!C7 -> 4667040 | E6: =+D6/5 -> 933408 | F6: =+E6 -> 933408 | G6: =+F6 -> 933408 | H6: =+G6 -> 933408 | I6: =+H6 -> 933408 | AY6: =SUM(E6:AW6) -> 4667040
B7: 2 | C7: RCC | D7: =+'Budget Tower-E'!C9 -> 53152400 | G7: =+D7/17 -> 3126611.8 | H7: =G7 -> 3126611.8 | I7: =H7 -> 3126611.8 | J7: =I7 -> 3126611.8 | K7: =J7 -> 3126611.8 | L7: =K7 -> 3126611.8 | M7: =L7 -> 3126611.8 | N7: =M7 -> 3126611.8 | O7: =N7 -> 3126611.8 | ... W7: =V7 -> 3126611.8 | AY7: =SUM(E7:AW7) -> 53152400
B8: 3 | C8: Shuttering | D8: =+'Budget Tower-E'!C11 -> 16075360 | G8: =+D8/17 -> 945609.41 | H8: =G8 -> 945609.41 | I8: =H8 -> 945609.41 | J8: =I8 -> 945609.41 | K8: =J8 -> 945609.41 | L8: =K8 -> 945609.41 | M8: =L8 -> 945609.41 | N8: =M8 -> 945609.41 | O8: =N8 -> 945609.41 | ... W8: =V8 -> 945609.41 | AY8: =SUM(E8:AW8) -> 16075360
B9: 4 | C9: Steel | D9: =+'Budget Tower-E'!C13 -> 84266000 | G9: =+D9/17 -> 4956823.5 | H9: =G9 -> 4956823.5 | I9: =H9 -> 4956823.5 | J9: =+I9 -> 4956823.5 | K9: =+J9 -> 4956823.5 | L9: =+K9 -> 4956823.5 | M9: =+L9 -> 4956823.5 | N9: =+M9 -> 4956823.5 | O9: =+N9 -> 4956823.5 | P9: =+O9 -> 4956823.5 | Q9: =+P9 -> 4956823.5 | ... W9: =+V9 -> 4956823.5 | AY9: =SUM(E9:AW9) -> 84266000
B10: 5 | C10: Brickwork | D10: =+'Budget Tower-E'!C15 -> 29817200 | N10: =+D10/20 -> 1490860 | O10: =+N10 -> 1490860 | P10: =+O10 -> 1490860 | Q10: =+P10 -> 1490860 | R10: =+Q10 -> 1490860 | S10: =+R10 -> 1490860 | T10: =+S10 -> 1490860 | U10: =+T10 -> 1490860 | V10: =+U10 -> 1490860 | ... AG10: =+AF10 -> 1490860 | AY10: =SUM(E10:AW10) -> 29817200
B11: 6 | C11: UPVC & Woodwork etc. | D11: =+'Budget Tower-E'!C17 -> 32410000 | AA11: =+AB11 -> 1543333.3 | AB11: =+AC11 -> 1543333.3 | AC11: =+AD11 -> 1543333.3 | AD11: =+AE11 -> 1543333.3 | AE11: =+AF11 -> 1543333.3 | AF11: =+AG11 -> 1543333.3 | AG11: =+AH11 -> 1543333.3 | AH11: =+D11/21 -> 1543333.3 | AI11: =+AH11 -> 1543333.3 | AJ11: =+AI11 -> 1543333.3 | AK11: =+AJ11 -> 1543333.3 | AL11: =+AK11 -> 1543333.3 | AM11: =+AL11 -> 1543333.3 | AN11: =+AM11 -> 1543333.3 | AO11: =+AN11 -> 1543333.3 | AP11: =+AO11 -> 1543333.3 | ... AU11: =+AT11 -> 1543333.3 | AY11: =SUM(E11:AW11) -> 32410000
B12: 7 | C12: MS Work | D12: =+'Budget Tower-E'!C19 -> 4634291.3 | V12: =+D12/20 -> 231714.57 | W12: =+V12 -> 231714.57 | X12: =+W12 -> 231714.57 | Y12: =+X12 -> 231714.57 | Z12: =+Y12 -> 231714.57 | AA12: =+Z12 -> 231714.57 | AB12: =+AA12 -> 231714.57 | AC12: =+AB12 -> 231714.57 | AD12: =+AC12 -> 231714.57 | ... AO12: =+AN12 -> 231714.57 | AY12: =SUM(E12:AW12) -> 4634291.3
B13: 8 | C13: Flooring Work | D13: =+'Budget Tower-E'!C21 -> 30595040 | Y13: =+Z13 -> 1223801.6 | Z13: =+AA13 -> 1223801.6 | AA13: =+D13/25 -> 1223801.6 | AB13: =+AA13 -> 1223801.6 | AC13: =+AB13 -> 1223801.6 | AD13: =+AC13 -> 1223801.6 | AE13: =+AD13 -> 1223801.6 | AF13: =+AE13 -> 1223801.6 | AG13: =+AF13 -> 1223801.6 | AH13: =+AG13 -> 1223801.6 | AI13: =+AH13 -> 1223801.6 | ... AW13: =+AV13 -> 1223801.6 | AY13: =SUM(E13:AW13) -> 30595040
B14: 9 | C14: Roofing Work | D14: =+'Budget Tower-E'!C23 -> 1555680 | AN14: =+AO14 -> 388920 | AO14: =+AP14 -> 388920 | AP14: =+AQ14 -> 388920 | AQ14: =+D14/4 -> 388920 | AY14: =SUM(E14:AW14) -> 1555680
B15: 10 | C15: Finishing Work | D15: =+'Budget Tower-E'!C25 -> 45374000 | U15: =+D15/25 -> 1814960 | V15: =+U15 -> 1814960 | W15: =+V15 -> 1814960 | X15: =+W15 -> 1814960 | Y15: =+X15 -> 1814960 | Z15: =+Y15 -> 1814960 | AA15: =+Z15 -> 1814960 | AB15: =+AA15 -> 1814960 | AC15: =+AB15 -> 1814960 | ... AS15: =+AR15 -> 1814960 | AY15: =SUM(E15:AW15) -> 45374000
B16: 11 | C16: =+'Budget Tower-E'!B27 -> SPECIAL FEATURES (AC, Gyser, RO, Modular Kitchen, Dish Washer, Cup board, Home Theater) | D16: =+'Budget Tower-E'!C27 -> 66327503 | AD16: =+AE16 -> 3316375.2 | AE16: =+AF16 -> 3316375.2 | AF16: =+AG16 -> 3316375.2 | AG16: =+AH16 -> 3316375.2 | AH16: =+AI16 -> 3316375.2 | AI16: =+AJ16 -> 3316375.2 | AJ16: =+AK16 -> 3316375.2 | AK16: =+AL16 -> 3316375.2 | ... AV16: =+AW16 -> 3316375.2 | AW16: =+D16/20 -> 3316375.2 | AY16: =SUM(E16:AW16) -> 66327503
B17: 12 | C17: Miscellaneous | D17: =+'Budget Tower-E'!C29 -> 2312777.6 | AC17: =+D17/8 -> 289097.2 | AD17: =+AC17 -> 289097.2 | AE17: =+AD17 -> 289097.2 | AF17: =+AE17 -> 289097.2 | AG17: =+AF17 -> 289097.2 | AH17: =+AG17 -> 289097.2 | AI17: =+AH17 -> 289097.2 | AJ17: =+AI17 -> 289097.2 | AW17: =N17 -> 0 | AY17: =SUM(E17:AW17) -> 2312777.6
B18: 13 | C18: =+'Budget Tower-E'!B31 -> ENTRY AND ELEVATION | D18: =+'Budget Tower-E'!C31 -> 7778400 | U18: =+D18/8 -> 972300 | V18: =+U18 -> 972300 | W18: =+V18 -> 972300 | X18: =+W18 -> 972300 | Y18: =+X18 -> 972300 | Z18: =+Y18 -> 972300 | AA18: =+Z18 -> 972300 | AB18: =+AA18 -> 972300 | AY18: =SUM(E18:AW18) -> 7778400
C19: Total of Civil Work(i) | D19: =SUM(D6:D18) -> 3.7896569e+08 | E19: =SUM(E6:E18) -> 933408 | F19: =SUM(F6:F18) -> 933408 | G19: =SUM(G6:G18) -> 9962452.7 | H19: =SUM(H6:H18) -> 9962452.7 | I19: =SUM(I6:I18) -> 9962452.7 | J19: =SUM(J6:J18) -> 9029044.7 | K19: =SUM(K6:K18) -> 9029044.7 | ... AW19: =SUM(AW6:AW18) -> 4540176.8 | AY19: =SUM(E19:AW19) -> 3.7896569e+08
D20: =+D19/10000000 -> 37.896569 | E20: =+E19/10000000 -> 0.0933408 | F20: =+F19/10000000 -> 0.0933408 | G20: =+G19/10000000 -> 0.99624527 | H20: =+H19/10000000 -> 0.99624527 | I20: =+I19/10000000 -> 0.99624527 | J20: =+J19/10000000 -> 0.90290447 | K20: =+K19/10000000 -> 0.90290447 | ... AW20: =+AW19/10000000 -> 0.45401768 | AY20: =+AY19/10000000 -> 37.896569
B21: B | C21: Other Work
B22: 1 | C22: Electrical Work-Internal | D22: =+'Budget Tower-E'!C36 -> 18149600 | S22: =+D22/25 -> 725984 | T22: =+S22 -> 725984 | U22: =+T22 -> 725984 | V22: =+U22 -> 725984 | W22: =+V22 -> 725984 | X22: =+W22 -> 725984 | Y22: =+X22 -> 725984 | Z22: =+Y22 -> 725984 | AA22: =+Z22 -> 725984 | ... AQ22: =+AP22 -> 725984 | AY22: =SUM(E22:AW22) -> 18149600
B23: 2 | C23: Plumbing work- Internal | D23: =+'Budget Tower-E'!C38 -> 18149600 | X23: =+D23/15 -> 1209973.3 | Y23: =+X23 -> 1209973.3 | Z23: =+Y23 -> 1209973.3 | AA23: =+Z23 -> 1209973.3 | AB23: =+AA23 -> 1209973.3 | AC23: =+AB23 -> 1209973.3 | AD23: =+AC23 -> 1209973.3 | AE23: =+AD23 -> 1209973.3 | AF23: =+AE23 -> 1209973.3 | ... AL23: =+AK23 -> 1209973.3 | AY23: =SUM(E23:AW23) -> 18149600
B24: 3 | C24: Fire fighting | D24: =+'Budget Tower-E'!C44 -> 7778400 | AH24: =+D24/8 -> 972300 | AI24: =+AH24 -> 972300 | AJ24: =+AI24 -> 972300 | AK24: =+AJ24 -> 972300 | AL24: =+AK24 -> 972300 | AM24: =+AL24 -> 972300 | AN24: =+AM24 -> 972300 | AO24: =+AN24 -> 972300 | AY24: =SUM(E24:AW24) -> 7778400
B25: 4 | C25: Lift | D25: =+'Budget Tower-E'!C40 -> 12964000 | AH25: =+D25/8 -> 1620500 | AI25: =+AH25 -> 1620500 | AJ25: =+AI25 -> 1620500 | AK25: =+AJ25 -> 1620500 | AL25: =+AK25 -> 1620500 | AM25: =+AL25 -> 1620500 | AN25: =+AM25 -> 1620500 | AO25: =+AN25 -> 1620500 | AY25: =SUM(E25:AW25) -> 12964000
B26: 5 | C26: External Development | D26: =+'Budget Tower-E'!C42 -> 12964000 | X26: =+D26/15 -> 864266.67 | Y26: =+X26 -> 864266.67 | Z26: =+Y26 -> 864266.67 | AA26: =+Z26 -> 864266.67 | AB26: =+AA26 -> 864266.67 | AC26: =+AB26 -> 864266.67 | AD26: =+AC26 -> 864266.67 | AE26: =+AD26 -> 864266.67 | AF26: =+AE26 -> 864266.67 | ... AL26: =+AK26 -> 864266.67 | AY26: =SUM(E26:AW26) -> 12964000
B27: 6 | C27: =+'Budget Tower-E'!B48 -> CLUB | D27: =+'Budget Tower-E'!C48 -> 12964000 | AK27: =+D27/10 -> 1296400 | AL27: =+AK27 -> 1296400 | AM27: =+AL27 -> 1296400 | AN27: =+AM27 -> 1296400 | AO27: =+AN27 -> 1296400 | AP27: =+AO27 -> 1296400 | AQ27: =+AP27 -> 1296400 | AR27: =+AQ27 -> 1296400 | AS27: =+AR27 -> 1296400 | AT27: =+AS27 -> 1296400
C28: Total of Other works(ii) | D28: =SUM(D22:D27) -> 82969600 | E28: =SUM(E22:E27) -> 0 | F28: =SUM(F22:F27) -> 0 | G28: =SUM(G22:G27) -> 0 | H28: =SUM(H22:H27) -> 0 | I28: =SUM(I22:I27) -> 0 | J28: =SUM(J22:J27) -> 0 | K28: =SUM(K22:K27) -> 0 | ... AW28: =SUM(AW22:AW27) -> 0 | AY28: =SUM(E28:AW28) -> 82969600
D29: =+D28/10^7 -> 8.29696 | E29: =+E28/10^7 -> 0 | F29: =+F28/10^7 -> 0 | G29: =+G28/10^7 -> 0 | H29: =+H28/10^7 -> 0 | I29: =+I28/10^7 -> 0 | J29: =+J28/10^7 -> 0 | K29: =+K28/10^7 -> 0 | ... AW29: =+AW28/10^7 -> 0 | AY29: =+AY28/10^7 -> 8.29696
B30: C | C30: Extra Parking work(Basement+Ground) | D30: ='Budget Tower-E'!C80 -> 92610518 | G30: =D30/8 -> 11576315 | H30: =G30 -> 11576315 | I30: =H30 -> 11576315 | J30: =I30 -> 11576315 | K30: =J30 -> 11576315 | L30: =K30 -> 11576315 | M30: =L30 -> 11576315 | N30: =M30 -> 11576315 | AY30: =SUM(E30:AW30) -> 92610518
D31: =+D30/10000000 -> 9.2610518 | G31: 0.779375 | H31: 0.779375 | I31: 0.779375 | J31: 0.779375 | K31: 0.779375 | L31: 0.779375 | M31: 0.779375 | N31: 0.779375
C32: Total of Civil,Other Works & Parkings(A+B+C) | D32: =D19+D28+D30 -> 5.5454581e+08 | E32: =E19+E28+E30 -> 933408 | F32: =F19+F28+F30 -> 933408 | G32: =G19+G28+G30 -> 21538767 | H32: =H19+H28+H30 -> 21538767 | I32: =I19+I28+I30 -> 21538767 | J32: =J19+J28+J30 -> 20605359 | K32: =K19+K28+K30 -> 20605359 | ... AW32: =AW19+AW28+AW30 -> 4540176.8 | AY32: =AY19+AY28+AY30 -> 5.5454581e+08
C34: Gross Total --(Rs.) | D34: =D32 -> 5.5454581e+08 | E34: =E32 -> 933408 | F34: =F32 -> 933408 | G34: =G32 -> 21538767 | H34: =H32 -> 21538767 | I34: =I32 -> 21538767 | J34: =J32 -> 20605359 | K34: =K32 -> 20605359 | ... AW34: =AW32 -> 4540176.8 | AY34: =AY32 -> 5.5454581e+08
C35: Gross Total --(Cr.) | D35: =D34/10^7 -> 55.454581 | E35: =E34/10^7 -> 0.0933408 | F35: =F34/10^7 -> 0.0933408 | G35: =G34/10^7 -> 2.1538767 | H35: =H34/10^7 -> 2.1538767 | I35: =I34/10^7 -> 2.1538767 | J35: =J34/10^7 -> 2.0605359 | K35: =K34/10^7 -> 2.0605359 | ... AW35: =AW34/10^7 -> 0.45401768 | AY35: =AY34/10^7 -> 55.454581

Sheet BOQ
A1: BOQ of Civil & Structure Works (Stilt + 14) Tower-E - Prayagraj
A2: S.No. | B2: Description | C2: Unit | D2: Qty | E2: Rate | F2: Amount
B3: General Notes - The following notes shall apply to all Sections and Bills contained in this Bill of Quantities:
A4: 1 | B4: The quantities, classes and kinds of work set out in this Bill of Quantities are provisional. They do not purport to or represent the final quantities, classes or kinds of work eventually required to be done.
A5: 2 | B5: This Bill of Quantities is not intended for and shall not be used for ordering purposes.
A6: 3 | B6: This Bill of Quantities is to be read in conjunction with the Drawings, Specifications & Preambles to Work Sections which shall be construed as being complementary to one another. Any discrepancy shall be dealt in accordance with the Conditions of Contract.
A7: 4 | B7: Works shall be executed at all heights / depths, levels, floors and locations all complete as per Drawings, Specifications and to the complete satisfaction of the Engineer-In-Charge.
A8: 5 | B8: Unless otherwise specified, mode and method of measurement shall be in accordance with IS:1200.
A9: 6 | B9: Contractor should strictly follow the Site Safety Manual and provide & install all the safety measures required as per Manual.
A10: 7 | B10: The description of an item shall be deemed to include all preambles, headings, sub-headings and references to other documents. The detailed description of work and materials, given in the Specification are not necessarily repeated in the Bill of Quantities.
A11: 8 | B11: The Preamble to the Bills of Quantities must be read with the Drawings, Conditions of Contract and the Specification and the tenderer shall be deemed to have examined the Drawings, Specifications, Conditions of Contract and to have acquainted himself with the Works to be done and the way in which they are to be carried out. This preamble to the Bills of Quantities shall form part of the Contract.
A12: 9 | B12: Providing and maintaining Field Laboratory in a satisfactory manner till the completion of work to ensure site control on quality of materials and the works and shall strictly comply with provision of Indian/ International Standards at no extra cost. All other regular tests including requisite materials shall be carried out as directed either at approved laboratory or at site at no extra cost.
A13: 10 | B13: The Tenderers are requested to inspect the site and obtain for themselves at their own expense all necessary information and particulars to enable them to submit the tender.
A14: 11 | B14: The dimensions shown in the drawings shall have to be verified by the contractor at site before execution of the items and necessary allowance's have to be made as per the actual dimensions available at site.
A15: 12 | B15: For the items of works having Basic rate of material, price adjustment will be made only on the actual quantity measured. Wastage shall be to Contractors account. Basic rate indicates landed cost at site including transportation charges, loading-unloading as applicable.
... A30: 27 | B30: Keeping the site clear, clean, and meeting the hygiene standards- Cost of providing and maintaining the workers toilets shall be covered in the scope of contractor. As per safety norms mentioned elsewhere.
B32: EARTH WORK
A33: 1.1. | B33: Earth work in excavation in foundation trenches, column pits, plinth beam, under grade/ raft slab etc. by mechanical and/or manual means up to a depth of 1.5 mtr in soil from existing excavated soil level, stacking/spreading the excavated material within site premises (within a stretch of 1500 M) as per direction of Project Manager including dressing of bottom, sides strutting, timbering, shoring, trimming of sides, all leads and lifts, bailing or pumping out the water from the excavated areas collected from any source including subsoil water and keeping the excavated surface dry for subsequent works incidentals, etc. complete with ramming of bottom, surface preparation as per specifications to receive the PCC. | C33: CUM | D33: 1000 | F33: =$D33*E33 -> 0
B34: Excavation shall be payable only for vertical cut up to the outer edge of foundation lean concrete as indicated in drawings for all depths. Cost of extra excavation required for working space, supporting side shuttering of foundations and retaining walls, planking, dewatering, strutting etc. and that required for making slopes for stability of excavation shall be deemed to be included in the rate quoted. This item is not for Mass Excavation.
A35: 1.2. | B35: Prepare the surface for PCC by manual excavation upto 30 cm depth including dressing the surface, ramming the bottom, disposal and spreading of the surplus earth at the specified location within premises including proper levelling, watering and consolidation complete as directed by E I C. (The item shall be measured as per plan area of PCC, Working space shall not be taken into measurement, deemed to be included into rates) (This item is only applicable if excavation item is not being executed by contractor and excavation already done by client for the location) | C35: SQM | D35: 1500 | F35: =$D35*E35 -> 0
A36: 1.3. | B36: Filling available excavated earth in trenches, plinth, sides of foundations etc. in layers not exceeding 20cm in depth: consolidating each deposited layer by ramming and watering, lead within the premises and upto any depth. (Compacted Volume shall be payable as per drawing) - Actual volume shall be paid incase excavation is done by Client. | C36: CUM | D36: 2400 | F36: =$D36*E36 -> 0
B37: Total of Earthwork | F37: =SUBTOTAL(9,F33:F36) -> 0
A39: 2 | B39: CONCRETE WORK
B40: Rates for all cement concrete items plain and reinforced described below shall include work from Basement Level to top of last roof including roof of machine room, mumty, over head water tanks and parapets above at all floors and for all heights. The contractor should provide full time sufficient pipes with accessories and pumps based on the site requirement for pumping and laying of concrete as directed by the EIC. The rate inclusive of standard rigid pipe line and its supports, lifting, laying charges, etc., at all heights and levels. No additional payment shall be payable to the contractor on account of using or change in any size of coarse aggregate in PCC/ RCC work at any stage during currency of works. (This section covers cast in situ structural and architectural as well.)
A41: 2.1 | B41: Plain Cement Concrete: Providing and laying plain cement concrete of specified grade as bed concrete under foundation, bases for rafts, underground water tank, building machine equipments, column footing, under floor landings, below road and pathways, cill, coping, screeding at roof to required slope and other locations as called for laid, consolidated and cured etc. complete including finishing the top surface to receive the next course / layer as per specification and drawing. (Shuttering shall be paid in Item No.3.1.1) M10 Grade (Basic Rate of PCC - Rs. 4200/cum) without pump | C41: CUM | D41: 100 | F41: =$D41*E41 -> 0
A42: 2.2. | B42: Providing and laying cement concrete 1:2:4 (1 cement : 2 coarse sand : 4 graded stone aggregate 20mm nominal size) for ledge wall below balcony railings, band, mullion, lintel etc. (Shuttering shall be paid separately in respective item) as per drawing and as directed by the Project Manager. | C42: CUM | D42: 50 | F42: =$D42*E42 -> 0
A43: 2.3. | B43: Providing and laying damp proof course 40mm thick including shttering with cement concrete 1:2:4 (1 cement : 2 coarse sand : 4 graded stone aggregate 20mm nominal size) including mixing of water proofing compound @ 2% of cement content and applying two layers of bitumen @ 1.70 Kg/Sqm of grade 85/25 and as directed by the Project Manager. | C43: SQM | D43: 200 | F43: =$D43*E43 -> 0
A45: 2.4. | B45: RCC WORK
B46: Providing & Laying RMC M-25 Grade as per approved design mix concrete (strictly controlled conditions) with flyash (as per approved design mix) with automatic batching plant machine mixed and machine vibrated RCC with melamine based plasticisers etc., upto any level, including finishing the exposed surface, fixing/ removal of pockets, fixing of sleeves and inserts (sleeves provided by client), curing etc complete, as per drawing (including all size and shape like circular, semi-circular, oval etc.) and as directed for all lead and lift, excluding cost of centering, shuttering and steel reinforcement but including cost of making shear keys and provision of construction / contraction / control joints in various locations. Checking from Client should not be considered as final and any defects arising during or after casting should be borne & bear by contractor at his own cost. This is inclusive of leaving shuttering & centring for pour strip, slab in slope, RCC members in curved, etc., nothing is payable extra on this account. RMC (M-25) Basic Rate - Rs. 5200/cum without pump excluding GST
A47: 2.4.1. | B47: Foundation, column footings, raft slab, raft beams, plinth beam, lift pits, sump pits, pedestals / bases of column, column upto plinth, swimming pool, Retaining wall foundations, grade slab etc. | C47: CUM | D47: 2080 | F47: =$D47*E47 -> 0
A48: 2.4.2. | B48: Suspended floors, roofs, balconies, shelves/ counters, stair waist slabs, folded plate stairs and landings, swimming pool slab, lintel and floor beams, landing beams, girders (deep beams), RCC bands, swimming pool beam, cantilever projections, coping, cills, slab of tank etc at all levels.
A49: 2.4.2.1. | B49: Stilt Floor level to 7th Floor level | C49: CUM | D49: 2200 | F49: =$D49*E49 -> 0
A50: 2.4.2.2. | B50: 7th Floor level to to Terrace Including OHT, Mumty, Machine Room, Parapet | C50: CUM | D50: 2440 | F50: =$D50*E50 -> 0
A51: 2.4.2.3. | B51: All type of Moulding, Bands, Elevation/Architectural Features as per drawing and as directed by EIC. at all level | C51: CUM | D51: 70 | F51: =$D51*E51 -> 0
A53: 2.5. | B53: Columns, Wall, pillars, piers, abutments, posts and struts, offset and projection of columns, water tank walls, lift walls, Retaining Wall, swimming pool, Parapets, planters, vertical projection of pergolas, wall and ramp walls etc. at all levels.
A54: 2.5.1. | B54: Stilt Floor level to 7th Floor level | C54: CUM | D54: 860 | F54: =$D54*E54 -> 0
A55: 2.5.2. | B55: 7th Floor level to to Terrace Including OHT, Mumty, Machine Room, Parapet | C55: CUM | D55: 950 | F55: =$D55*E55 -> 0
A56: 2.5.3. | B56: All type of Moulding, Bands, Elevation/Architectural Features as per drawing and as directed by EIC. at all level | C56: CUM | D56: 30 | F56: =$D56*E56 -> 0
A57: 2.5.4. | B57: Finishing vaccum dewatering continuous concrete flooring 100-150 mm thick with specified grade concrete including necessary formwork in required level, vibrating concrete both by poker vibrators / leveling vaccum processing of the concrete and planning the surface by skin powered floater trowels with broom/plain finish including groove cutting & filling etc. complete. (Concrete shall be paid in the respective items above). | C57: SQM | D57: 1625 | F57: =$D57*E57 -> 0
B59: Total of RCC Work | F59: =SUBTOTAL(9,F41:F58) -> 0
...

Sheet Sheet6
A1: S. No. | B1: DESCRIPTION OF ITEMS | C1: UNIT | D1: BOQ DETAIL
D2: QUANTITY | E2: RATE | F2: AMOUNT
A3: S.H.-I | B3: MAIN WORK
A4: 1 | B4: EARTH WORK IN EXCAVATION
A5: 1.1 | B5: A) ALL KINDS OF SOIL, LIFT UPTO 3 M | C5: CUM
A6: 1.3 | B6: FILLING OF EARTH | C6: CUM
A8: 2 | B8: REINFORCED CEMENT CONCRETE
B9: PROVIDING & LAYING RMC DESIGN MIX CONCRETE
A10: 2.1 | B10: FOUNDATION, RAFTS, FOOTINGS, BASES OF COLUMNS, IN M-25 GRADE | C10: CUM
A11: 2.2 | B11: IN SUSPENDED FLOORS, ROOFS,BEAMS, LANDING, CHAJJAS, CANTILEVERS, BALCONIES,
B12: M25 GRADE | C12: CUM
A13: 2.3 | B13: IN PLINTH BEAMS, LANDING BEAM CANTILEVERS BEAM ETC ON PLINTH LVL.
B14: M25 GRADE | C14: CUM
A15: 2.4 | B15: IN GRADE SLAB FOR FLOORING AT GROUND FLOOR LVL.
B16: M25 GRADE | C16: CUM
A17: 2.5 | B17: IN STAIRCASE ETC. IN M-25 GRADE CONCRETE ALL WORK .
B18: M25 GRADE | C18: CUM
A19: 2.6 | B19: IN SHEAR WALLS, LIFT WALLS, RETAINING WALL | C19: CUM
B20: M25 GRADE | C20: CUM
B21: M30 GRADE | C21: CUM
A22: 2.7 | B22: IN COLUMNS, PILLARS & PIERS, POSTS, STRUTS
B23: M25 GRADE | C23: CUM
B24: M30 GRADE | C24: CUM
A25: 2.8 | B25: IN WALLS (ANY THICKNESS) AND BASE SLAB AND COVER SLAB OF OVERHEAD TANKS ETC., IN M-25 GRADE | C25: CUM
A26: 2.9 | B26: EXTRA OVER 5TH FLOOR LEVEL TO 8TH FLOOR | C26: CUM
A27: 2.1 | B27: EXTRA OVER 9TH FLOOR LEVEL TO 12TH FLOOR | C27: CUM
A28: 2.11 | B28: EXTRA OVER 13TH FLOOR LEVEL TO 16TH FLOOR | C28: CUM
A29: 2.12 | B29: RCC IN KITCHEN COUNTER INCLUDING SHUTTERING REINFORCEMENT COMPLETE IN FLAT | C29: NOS
A30: 2.13 | B30: RCC IN LINTEL OF AVG SIZE 100X125X1200MM INCLUDING SHUTTERING REINFORCEMENT COMPLETE | C30: NOS
A31: 2.14 | B31: RCC IN LEDGE WALL/CONCRET BLOCK OF COMPLETE | C31: CUM
A34: 3 | B34: P/F SHUTTERING WORK
A35: 3.1 | B35: FOUNDATIONS, RAFT, FOOTINGS, | C35: Sqm
A36: 3.2 | B36: OUTER SHEAR WALLS, LIFT WALLS, | C36: Sqm
A37: 3.3 | B37: PLINTH BEAM, LANDING BEAM, AT PLINTH LVL. | C37: Sqm
A38: 3.4 | B38: STAIRCASE, TIE-BEAMS, ETC UP TO ANY HEIGHT. | C38: Sqm
A39: 3.5 | B39: SUSPENDED/FLAT FLOOR, ROOFS AND BEAM, LANDINGS, CANTILEVER SLABS, CHAJJAS, | C39: Sqm
A40: 3.6 | B40: COLUMNS, PILLARS, PIERS, POSTS, STRUTS | C40: Sqm
A41: 3.7 | B41: ABOVE TERRACE WORK WALLS | C41: Sqm
A42: 3.7 | B42: ABOVE TERRACE WORK WALLS | C42: Sqm
A44: 4 | B44: P/F REINFORCEMENT WORK
...

Sheet Summary
A1: S. No. | B1: Description | C1: Unit | D1: QTY
A2: 1 | B2: Excavation upto 3 Mtr. | C2: CUM | D2: =1532.83*2.5 -> 3832.075 | F2: =4000 -> 4000 | G2: =F2-1600 -> 2400
A3: 2 | B3: PCC | C3: CUM | D3: =+#REF!+#REF!+#REF! -> #REF!
A4: 3 | B4: RCC M-25 | C4: CUM | D4: =+#REF!-Summary!D3-Summary!D5 -> #REF!
A5: 4 | B5: RCC M-30 | C5: CUM | D5: =+#REF!+#REF!+#REF!+#REF!+#REF!+#REF!+#REF!+#REF!+#REF!+#REF!+#REF!+#REF!+#REF! -> #REF!
A6: 5 | B6: RCC in Ladge Wall | C6: CUM | D6: =+#REF! -> #REF!
A7: 6 | B7: Shuttering | C7: SQM
A8: 6.1 | B8: RAFT | C8: SQM | D8: =+#REF! -> #REF!
A9: 6.2 | B9: COLUMN | C9: SQM | D9: =+#REF!+#REF! -> #REF!
A10: 6.3 | B10: SHEAR WALL | C10: SQM | D10: =+#REF!+#REF! -> #REF!
A11: 6.4 | B11: STAIR CASE | C11: SQM | D11: =+#REF!+#REF! -> #REF!
A12: 6.5 | B12: PLINTH BEAM | C12: SQM | D12: =+#REF! -> #REF!
A13: 6.6 | B13: Slab | C13: SQM | D13: =+#REF! -> #REF!
A14: 7 | B14: Steel | C14: MT | D14: =+#REF! -> #REF!
A15: 8 | B15: DPC | C15: CUM | D15: =(#REF!+#REF!)*15 -> #REF!
A16: 9 | B16: Brick Work 115mm | C16: SQM | D16: =+#REF!*15 -> #REF!
A17: 10 | B17: Brick Work 230mm | C17: CUM | D17: =+#REF!*15 -> #REF!
A18: 11 | B18: Internal Wall Plaster | C18: SQM | D18: =+#REF!*15 -> #REF!
A19: 12 | B19: Internal Ceiling Plaster | C19: SQM | D19: =+#REF!*15 -> #REF!
A20: 13 | B20: External Plaster | C20: SQM | D20: =+#REF!+#REF! -> #REF!

Sheet Sheet2
B7: 259280 | D7: =1598*15 -> 23970 | E7: =1500*15 -> 22500
B8: =+B7/10.764 -> 24087.7 | D8: =+D7*10.764 -> 258013.08 | E8: =+E7*10.764 -> 242190
B9: =+B8/15 -> 1605.8466 | D9: =1600*15*10.764 -> 258336
B11: =1605*10.764*15 -> 259143.3
B12: =0.847*15*10.764 -> 136.75662 | C12: =+B12/15 -> 9.117108
B13: =+B12*900 -> 123080.96 | C13: =+C12*900 -> 8205.3972 | D13: =+B11*900 -> 2.3322897e+08
D14: =+D13/10000000 -> 23.322897
F18: 230mm Wall
F19: Flat No.2
F20: Bed Room-1 | G20: 6 | H20: 1 | I20: 3.165 | J20: =3-0.5 -> 2.5 | K20: =+PRODUCT(G20:J20) -> 47.475
G21: 6 | H21: -1 | I21: 2.065 | J21: =3-0.5 -> 2.5 | K21: =+PRODUCT(G21:J21) -> -30.975
G22: 6 | H22: 1 | I22: 0.985 | J22: =3-0.5 -> 2.5 | K22: =+PRODUCT(G22:J22) -> 14.775
F23: Bed Room-2 | G23: 6 | H23: 1 | I23: 2.165 | J23: =3-0.5 -> 2.5 | K23: =+PRODUCT(G23:J23) -> 32.475
G24: 6 | H24: -1 | I24: 2.065 | J24: =3-0.5 -> 2.5 | K24: =+PRODUCT(G24:J24) -> -30.975
F25: Bed Room-3 | G25: 6 | H25: 1 | I25: 3.55 | J25: =3-0.5 -> 2.5 | K25: =+PRODUCT(G25:J25) -> 53.25
G26: 6 | H26: 1 | I26: 1.92 | J26: =3-0.5 -> 2.5 | K26: =+PRODUCT(G26:J26) -> 28.8
G27: 6 | H27: -1 | I27: 1.5 | J27: 1.5 | K27: =+PRODUCT(G27:J27) -> -13.5
F28: Toilet Wall | G28: 6 | H28: 1 | I28: 2.58 | J28: =3-0.5 -> 2.5 | K28: =+PRODUCT(G28:J28) -> 38.7
G29: 6 | H29: -2 | I29: 0.55 | J29: 1 | K29: =+PRODUCT(G29:J29) -> -6.6
G30: 6 | H30: 1 | I30: 2.3 | J30: =3-0.35 -> 2.65 | K30: =+PRODUCT(G30:J30) -> 36.57
F31: Drawing Room | G31: 6 | H31: 1 | I31: 3.19 | J31: =3-0.5 -> 2.5 | K31: =+PRODUCT(G31:J31) -> 47.85
G32: 6 | H32: -1 | I32: 2.45 | J32: =3-0.5 -> 2.5 | K32: =+PRODUCT(G32:J32) -> -36.75
F33: Kitchen | G33: 6 | H33: 1 | I33: 0.415 | J33: =3-0.35 -> 2.65 | K33: =+PRODUCT(G33:J33) -> 6.5985
F34: Entry Wall | G34: 6 | H34: 1 | I34: 1.515 | J34: =3-0.125 -> 2.875 | K34: =+PRODUCT(G34:J34) -> 26.13375
G35: 6 | H35: -1 | I35: 1.2 | J35: 2.4 | K35: =+PRODUCT(G35:J35) -> -17.28
F36: Toilet Wall | G36: 6 | H36: 1 | I36: 0.515 | J36: =3-0.5 -> 2.5 | K36: =+PRODUCT(G36:J36) -> 7.725
F37: Toilet Wall | G37: 6 | H37: 1 | I37: 1.81 | J37: =3-0.5 -> 2.5 | K37: =+PRODUCT(G37:J37) -> 27.15
F38: Kitchen Common Wall for Flat 2 & 3 | G38: 2 | H38: 1 | I38: 4.735 | J38: =3-0.35 -> 2.65 | K38: =+PRODUCT(G38:J38) -> 25.0955
F39: Drawing Room Common Wall for Flat 1 & 2 | G39: 2 | H39: 1 | I39: 1.5 | J39: =3-0.45 -> 2.55 | K39: =+PRODUCT(G39:J39) -> 7.65
G40: 2 | H40: 1 | I40: 5.245 | J40: =3-0.45 -> 2.55 | K40: =+PRODUCT(G40:J40) -> 26.7495
G41: 2 | H41: 1 | I41: 1.075 | J41: =3-0.125 -> 2.875 | K41: =+PRODUCT(G41:J41) -> 6.18125
F42: Drawing Room Common Wall for Flat 3 | G42: 2 | H42: 1 | I42: 2.57 | J42: =3-0.5 -> 2.5 | K42: =+PRODUCT(G42:J42) -> 12.85
F43: Flat No.4
F44: Bed Room-1 | G44: 2 | H44: 1 | I44: 3.025 | J44: =3-0.5 -> 2.5 | K44: =+PRODUCT(G44:J44) -> 15.125
G45: 2 | H45: -1 | I45: 2.065 | J45: =3-0.5 -> 2.5 | K45: =+PRODUCT(G45:J45) -> -10.325
G46: 2 | H46: 1 | I46: 3.8 | J46: =3-0.5 -> 2.5 | K46: =+PRODUCT(G46:J46) -> 19
G47: 2 | H47: -1 | I47: 0.55 | J47: 1 | K47: =+PRODUCT(G47:J47) -> -1.1
F48: Bed Room-2 | G48: 2 | H48: 1 | I48: 2.8 | J48: =3-0.5 -> 2.5 | K48: =+PRODUCT(G48:J48) -> 14
G49: 2 | H49: -1 | I49: 2.065 | J49: =3-0.5 -> 2.5 | K49: =+PRODUCT(G49:J49) -> -10.325
F50: Living Room | G50: 2 | H50: 1 | I50: 3.3 | J50: =3-0.5 -> 2.5 | K50: =+PRODUCT(G50:J50) -> 16.5
...
