Workbook

Sheet Summary Qty
A1: Summary
A2: S. No | B2: Particular | C2: Steel (MT) | D2: shuttering (Sqm) | E2: Concrete (Cum) | F2: Bloclwork 200mm (Cum) | G2: Bloclwork 100mm (Sqm) | H2: Brickwork 230mm (cum) | I2: Brickwork 115mm (Sqm) | J2: Plaster
J3: Ceiling | K3: Internal walls | L3: Lift well (Total Qty) | M3: Outer
A4: 1 | B4: Raft | C4: =+'Steel Summary'!J4 -> 92.87 | D4: =+'Shuttering summary'!C4 -> 216.07 | E4: =+'RCC Summary'!C4 -> 1552.355
A5: 2 | B5: Columns Upto Plinth Lvl | C5: =+'Steel Summary'!J8 -> 25.8 | D5: =+'Shuttering summary'!C5 -> 609.741 | E5: =+'RCC Summary'!C5 -> 80.35671
A6: 3 | B6: Plinth Beam | C6: =+'Steel Summary'!J5 -> 10.836 | D6: =+'Shuttering summary'!C6 -> 843.4487 | E6: =+'RCC Summary'!C6 -> 69.31584
A7: 4 | B7: Stilt Floor
B8: Column | C8: =+'Steel Summary'!J8 -> 25.8 | D8: =+'Shuttering summary'!$C$7 -> 1043.9505 | E8: =+'RCC Summary'!$C$7 -> 112.88205
B9: Slab | C9: 32.88 | D9: =+'Shuttering summary'!$C$8 -> 2234.6038 | E9: =+'RCC Summary'!$C$8 -> 17.145513
A10: 5 | B10: 1st Floor
B11: Column | C11: =+'Steel Summary'!J10 -> 20.43 | D11: =+'Shuttering summary'!$C$7 -> 1043.9505 | E11: =+'RCC Summary'!$C$7 -> 112.88205
B12: Slab | C12: 32.88 | D12: =+'Shuttering summary'!$C$8 -> 2234.6038 | E12: =+'RCC Summary'!$C$8 -> 17.145513
A13: 6 | B13: Typical Floor | F13: =+Blockwork!G308 -> 86.19 | G13: =+Blockwork!G311 -> 3920.03 | H13: =+Blockwork!G309 -> 55.17 | I13: =+Blockwork!G310 -> 30.8 | J13: =+Plaster!G544 -> 1187.3025 | K13: =+Plaster!G545 -> 2536.9035 | L13: =+Plaster!G552 -> 829.9544
B14: Column (Average) | C14: 20 | D14: =+'Shuttering summary'!$C$7 -> 1043.9505 | E14: =+'RCC Summary'!$C$7 -> 112.88205
B15: Slab | C15: 32.88 | D15: =+'Shuttering summary'!$C$8 -> 2234.6038 | E15: =+'RCC Summary'!$C$8 -> 17.145513

Sheet Summary Amt
A2: TOWER-E
C3: UNIT | D3: RATE | E3: QTY | F3: AMOUNT
B4: GRID(1-22)
A5: 1 | B5: COLUMN STEEL | C5: MT | D5: 9400 | E5: =25.83/2 -> 12.915 | F5: =D5*E5 -> 121401
A6: 2 | B6: COLUMN SHUTTERING | C6: SQM | D6: 465 | E6: =929.85/2 -> 464.925 | F6: =D6*E6 -> 216190.12
A7: 3 | B7: COLUMN RCC | C7: CUM | D7: 6850 | E7: 47.015 | F7: =D7*E7 -> 322052.75
A8: 4 | B8: SLAB SHUTTERING | C8: SQM | D8: 465 | E8: 1195.81 | F8: =D8*E8 -> 556051.65
A9: 5 | B9: SLAB STEEL | C9: MT | D9: 9400 | E9: 17.795 | F9: =D9*E9 -> 167273
A10: 6 | B10: SLAB RCC | C10: CUM | D10: 6850 | E10: 153.79 | F10: =D10*E10 -> 1053461.5
E12: A | F12: =SUBTOTAL(9,F4:F11) -> 2436430
B13: GRID(22-43)
A14: 1 | B14: COLUMN STEEL | C14: MT | D14: 9400 | E14: =25.83/2 -> 12.915 | F14: =D14*E14 -> 121401
A15: 2 | B15: COLUMN SHUTTERING | C15: SQM | D15: 465 | E15: =929.85/2 -> 464.925 | F15: =D15*E15 -> 216190.12
A16: 3 | B16: COLUMN RCC | C16: CUM | D16: 6850 | E16: 47.015 | F16: =D16*E16 -> 322052.75
A17: 4 | B17: SLAB SHUTTERING | C17: SQM | D17: 465 | E17: 1195.81 | F17: =D17*E17 -> 556051.65
A18: 5 | B18: SLAB STEEL | C18: MT | D18: 9400 | E18: 17.795 | F18: =D18*E18 -> 167273
A19: 6 | B19: SLAB RCC | C19: CUM | D19: 6850 | E19: 153.79 | F19: =D19*E19 -> 1053461.5
E21: B | F21: =SUBTOTAL(9,F13:F20) -> 2436430
E23: TOTAL (A+B) | F23: =SUBTOTAL(9,F5:F22) -> 4872860

Sheet Steel Summary
A1: Steel Summary
A2: S. No | B2: Particular | C2: Percentage | D2: Qty | J2: Total Qty
D3: 8mm | E3: 10mm | F3: 12mm | G3: 16mm | H3: 20mm | I3: 25mm
A4: 1 | B4: Raft | C4: 1 | D4: =+ROUND('Raft Steel'!M193/1000,2)*C4 -> 0 | E4: =+ROUND('Raft Steel'!N193/1000,2)*C4 -> 0.78 | F4: =+ROUND('Raft Steel'!O193/1000,2)*C4 -> 2.19 | G4: =+ROUND('Raft Steel'!P193/1000,2)*C4 -> 55.77 | H4: =+ROUND('Raft Steel'!Q193/1000,2)*C4 -> 17.32 | I4: =+ROUND('Raft Steel'!R193/1000,2)*C4 -> 16.81 | J4: =SUM(D4:I4) -> 92.87
A5: 2 | B5: Plinth Beam | C5: 1.05 | D5: =+ROUND('Plinth Steel'!M382/1000,2)*C5 -> 3.8115 | E5: =+ROUND('Plinth Steel'!N382/1000,2)*C5 -> 0.21 | F5: =+ROUND('Plinth Steel'!O382/1000,2)*C5 -> 1.5645 | G5: =+ROUND('Plinth Steel'!P382/1000,2)*C5 -> 5.0925 | H5: =+ROUND('Plinth Steel'!Q382/1000,2)*C5 -> 0.1575 | I5: =+ROUND('Plinth Steel'!R382/1000,2)*C5 -> 0 | J5: =SUM(D5:I5) -> 10.836
A6: 3 | B6: Typical Floor | C6: 1 | D6: =+ROUND('Typical floor STEEL'!M1155/1000,2)*$C$6 -> 33.03 | E6: =+ROUND('Typical floor STEEL'!N1155/1000,2)*$C$6 -> 6.74 | F6: =+ROUND('Typical floor STEEL'!O1155/1000,2)*$C$6 -> 4.41 | G6: =+ROUND('Typical floor STEEL'!P1155/1000,2)*$C$6 -> 0 | H6: =+ROUND('Typical floor STEEL'!Q1155/1000,2)*$C$6 -> 0.08 | I6: =+ROUND('Typical floor STEEL'!R1155/1000,2)*$C$6 -> 0 | J6: =SUM(D6:I6) -> 44.26
B7: Columns
A8: 2 | B8: Upto Plinth Lvl | C8: 1 | D8: =+ROUND('Columns Steel'!M180/1000,2)*C8 -> 2.68 | E8: =+ROUND('Columns Steel'!N180/1000,2)*C8 -> 5.69 | F8: =+ROUND('Columns Steel'!O180/1000,2)*C8 -> 2.93 | G8: =+ROUND('Columns Steel'!P180/1000,2)*C8 -> 7.89 | H8: =+ROUND('Columns Steel'!Q180/1000,2)*C8 -> 5.92 | I8: =+ROUND('Columns Steel'!R180/1000,2)*C8 -> 0.69 | J8: =SUM(D8:I8) -> 25.8
A9: 3 | B9: From Plinth to 1st floor lvl | C9: 1 | D9: =+ROUND('Columns Steel'!M365/1000,2)*C9 -> 4.76 | E9: =+ROUND('Columns Steel'!N365/1000,2)*C9 -> 5.85 | F9: =+ROUND('Columns Steel'!O365/1000,2)*C9 -> 3.02 | G9: =+ROUND('Columns Steel'!P365/1000,2)*C9 -> 5.97 | H9: =+ROUND('Columns Steel'!Q365/1000,2)*C9 -> 4.24 | I9: =+ROUND('Columns Steel'!R365/1000,2)*C9 -> 0.36 | J9: =SUM(D9:I9) -> 24.2
A10: 4 | B10: From 1st to 2nd Floor Lvl | C10: 1 | D10: =+ROUND('Columns Steel'!M549/1000,2)*C10 -> 4.29 | E10: =+ROUND('Columns Steel'!N549/1000,2)*C10 -> 5.42 | F10: =+ROUND('Columns Steel'!O549/1000,2)*C10 -> 3.79 | G10: =+ROUND('Columns Steel'!P549/1000,2)*C10 -> 4.94 | H10: =+ROUND('Columns Steel'!Q549/1000,2)*C10 -> 1.78 | I10: =+ROUND('Columns Steel'!R549/1000,2)*C10 -> 0.21 | J10: =SUM(D10:I10) -> 20.43
A11: 5 | B11: From 2nd to 3rd Floor Lvl | C11: 1 | D11: =+ROUND('Columns Steel'!M736/1000,2)*C11 -> 4.04 | E11: =+ROUND('Columns Steel'!N736/1000,2)*C11 -> 5.61 | F11: =+ROUND('Columns Steel'!O736/1000,2)*C11 -> 3.69 | G11: =+ROUND('Columns Steel'!P736/1000,2)*C11 -> 5.02 | H11: =+ROUND('Columns Steel'!Q736/1000,2)*C11 -> 0.86 | I11: =+ROUND('Columns Steel'!R736/1000,2)*C11 -> 0 | J11: =SUM(D11:I11) -> 19.22
A12: 5 | B12: From 3rd to 4rth Floor Lvl | C12: 1 | D12: =+'Columns Steel'!M926/1000 -> 4.0015238 | E12: =+'Columns Steel'!N926/1000 -> 5.6836189 | F12: =+'Columns Steel'!O926/1000 -> 4.129085 | G12: =+'Columns Steel'!P926/1000 -> 4.443276 | H12: =+'Columns Steel'!Q926/1000 -> 0.131856 | I12: =+'Columns Steel'!R926/1000 -> 0 | J12: =SUM(D12:I12) -> 18.38936

Sheet RCC Summary
A1: RCC Summary
A2: S. No | B2: Particular | C2: Qty
A4: 1 | B4: Raft | C4: =+RCC!G3 -> 1552.355
A5: 2 | B5: Column Upto Plinth Lvl | C5: =+RCC!G30 -> 80.35671
A6: 3 | B6: Plinth Beam | C6: =+RCC!G103 -> 69.31584
A7: 4 | B7: Typical floor Column | C7: =+'RCC Typical floor'!G30 -> 112.88205
A8: 5 | B8: Typical Floor | C8: =+'RCC Typical floor'!H128+'RCC Typical floor'!G240 -> 17.145513

Sheet Shuttering summary
A1: Shuttering Summary
A2: S. No | B2: Particular | C2: Qty
A4: 1 | B4: Raft | C4: =+'Shuttering Raft'!G4 -> 216.07
A5: 2 | B5: Column Upto Plinth Lvl | C5: =+'Shuttering Raft'!G31 -> 609.741
A6: 3 | B6: Plinth Beam | C6: =+'Shuttering Raft'!H172 -> 843.4487
A7: 4 | B7: Typical floor Column | C7: =+'Floor Shuttering'!G30 -> 1043.9505
A8: 5 | B8: Typical Floor | C8: =+'Floor Shuttering'!H316+'Floor Shuttering'!G428 -> 2234.6038

Sheet Raft Steel
A1: Reinforcement
A2: Sr. No. | B2: Beam Designation | C2: Dia | D2: C/C (mm) | E2: No | F2: No | G2: No of Bars | H2: Bar Length (mtr) | K2: Lap Length | L2: One Bar Length (MTR) | M2: Dia Wise Weight (Kg)
H3: a | I3: b | J3: c | M3: 8mm | N3: 10mm | O3: 12mm | P3: 16mm | Q3: 20MM | R3: 25mm
B5: Raft
B6: Main Bar @16 Dia (Top & Bottom) | C6: 16 | D6: 250 | E6: 2 | F6: 2 | G6: =+ROUND(8555/D6+1,0) -> 35 | H6: 0.65 | I6: =21.65-0.05*2 -> 21.55 | J6: 0.65 | K6: =50*C6/1000 -> 0.8 | L6: =SUM(H6:J6)+K6 -> 23.65 | M6: =+ROUND(IF(C6=8,PRODUCT(E6,F6,G6,L6),0),2) -> 0 | N6: =+ROUND(IF(C6=10,PRODUCT(E6,F6,G6,L6),0),2) -> 0 | O6: =+ROUND(IF(C6=12,PRODUCT(E6,F6,G6,L6),0),2) -> 0 | P6: =+ROUND(IF(C6=16,PRODUCT(E6,F6,G6,L6),0),2) -> 3311 | Q6: =+ROUND(IF(C6=20,PRODUCT(E6,F6,G6,L6),0),2) -> 0 | R6: =+ROUND(IF(C6=25,PRODUCT(E6,F6,G6,L6),0),2) -> 0
C7: 16 | D7: 250 | E7: 2 | F7: 2 | G7: =+ROUND(2535/D7,0) -> 10 | H7: 0.65 | I7: =+I6+0.515 -> 22.065 | J7: 0.65 | K7: =2*50*C7/1000 -> 1.6 | L7: =SUM(H7:J7)+K7 -> 24.965 | M7: =+ROUND(IF(C7=8,PRODUCT(E7,F7,G7,L7),0),2) -> 0 | N7: =+ROUND(IF(C7=10,PRODUCT(E7,F7,G7,L7),0),2) -> 0 | O7: =+ROUND(IF(C7=12,PRODUCT(E7,F7,G7,L7),0),2) -> 0 | P7: =+ROUND(IF(C7=16,PRODUCT(E7,F7,G7,L7),0),2) -> 998.6 | Q7: =+ROUND(IF(C7=20,PRODUCT(E7,F7,G7,L7),0),2) -> 0 | R7: =+ROUND(IF(C7=25,PRODUCT(E7,F7,G7,L7),0),2) -> 0
C8: 16 | D8: 250 | E8: 2 | F8: 2 | G8: =+ROUND(3660/D8,0) -> 15 | H8: 0.65 | I8: =32.45-0.1 -> 32.35 | J8: 0.65 | K8: =2*50*C8/1000 -> 1.6 | L8: =SUM(H8:J8)+K8 -> 35.25 | M8: =+ROUND(IF(C8=8,PRODUCT(E8,F8,G8,L8),0),2) -> 0 | N8: =+ROUND(IF(C8=10,PRODUCT(E8,F8,G8,L8),0),2) -> 0 | O8: =+ROUND(IF(C8=12,PRODUCT(E8,F8,G8,L8),0),2) -> 0 | P8: =+ROUND(IF(C8=16,PRODUCT(E8,F8,G8,L8),0),2) -> 2115 | Q8: =+ROUND(IF(C8=20,PRODUCT(E8,F8,G8,L8),0),2) -> 0 | R8: =+ROUND(IF(C8=25,PRODUCT(E8,F8,G8,L8),0),2) -> 0
C9: 16 | D9: 250 | E9: 2 | F9: 2 | G9: =+ROUND(2485/D9,0) -> 10 | H9: 0.65 | I9: 11.355 | J9: 0.65 | L9: =SUM(H9:J9)+K9 -> 12.655 | M9: =+ROUND(IF(C9=8,PRODUCT(E9,F9,G9,L9),0),2) -> 0 | N9: =+ROUND(IF(C9=10,PRODUCT(E9,F9,G9,L9),0),2) -> 0 | O9: =+ROUND(IF(C9=12,PRODUCT(E9,F9,G9,L9),0),2) -> 0 | P9: =+ROUND(IF(C9=16,PRODUCT(E9,F9,G9,L9),0),2) -> 506.2 | Q9: =+ROUND(IF(C9=20,PRODUCT(E9,F9,G9,L9),0),2) -> 0 | R9: =+ROUND(IF(C9=25,PRODUCT(E9,F9,G9,L9),0),2) -> 0
C10: 16 | D10: 250 | E10: 2 | F10: 2 | G10: =+ROUND(1420/D10,0) -> 6 | H10: 0.65 | I10: =11.355+0.515 -> 11.87 | J10: 0.65 | L10: =SUM(H10:J10)+K10 -> 13.17 | M10: =+ROUND(IF(C10=8,PRODUCT(E10,F10,G10,L10),0),2) -> 0 | N10: =+ROUND(IF(C10=10,PRODUCT(E10,F10,G10,L10),0),2) -> 0 | O10: =+ROUND(IF(C10=12,PRODUCT(E10,F10,G10,L10),0),2) -> 0 | P10: =+ROUND(IF(C10=16,PRODUCT(E10,F10,G10,L10),0),2) -> 316.08 | Q10: =+ROUND(IF(C10=20,PRODUCT(E10,F10,G10,L10),0),2) -> 0 | R10: =+ROUND(IF(C10=25,PRODUCT(E10,F10,G10,L10),0),2) -> 0
C11: 16 | D11: 250 | E11: 2 | F11: 2 | G11: =+ROUND(4005/D11,0) -> 16 | H11: 0.65 | I11: =18.01-0.1 -> 17.91 | J11: 0.65 | K11: =50*C11/1000 -> 0.8 | L11: =SUM(H11:J11)+K11 -> 20.01 | M11: =+ROUND(IF(C11=8,PRODUCT(E11,F11,G11,L11),0),2) -> 0 | N11: =+ROUND(IF(C11=10,PRODUCT(E11,F11,G11,L11),0),2) -> 0 | O11: =+ROUND(IF(C11=12,PRODUCT(E11,F11,G11,L11),0),2) -> 0 | P11: =+ROUND(IF(C11=16,PRODUCT(E11,F11,G11,L11),0),2) -> 1280.64 | Q11: =+ROUND(IF(C11=20,PRODUCT(E11,F11,G11,L11),0),2) -> 0 | R11: =+ROUND(IF(C11=25,PRODUCT(E11,F11,G11,L11),0),2) -> 0
C12: 16 | D12: 250 | E12: 2 | F12: 2 | G12: =+ROUND(1210/D12,0) -> 5 | H12: 0.65 | I12: =32.45-0.1 -> 32.35 | J12: 0.65 | K12: =2*50*C12/1000 -> 1.6 | L12: =SUM(H12:J12)+K12 -> 35.25 | M12: =+ROUND(IF(C12=8,PRODUCT(E12,F12,G12,L12),0),2) -> 0 | N12: =+ROUND(IF(C12=10,PRODUCT(E12,F12,G12,L12),0),2) -> 0 | O12: =+ROUND(IF(C12=12,PRODUCT(E12,F12,G12,L12),0),2) -> 0 | P12: =+ROUND(IF(C12=16,PRODUCT(E12,F12,G12,L12),0),2) -> 705 | Q12: =+ROUND(IF(C12=20,PRODUCT(E12,F12,G12,L12),0),2) -> 0 | R12: =+ROUND(IF(C12=25,PRODUCT(E12,F12,G12,L12),0),2) -> 0
C13: 16 | D13: 250 | E13: 2 | F13: 2 | G13: =+ROUND(3950/D13,0) -> 16 | H13: 0.65 | I13: =32.45-0.1-1.5 -> 30.85 | J13: 0.65 | K13: =2*50*C13/1000 -> 1.6 | L13: =SUM(H13:J13)+K13 -> 33.75 | M13: =+ROUND(IF(C13=8,PRODUCT(E13,F13,G13,L13),0),2) -> 0 | N13: =+ROUND(IF(C13=10,PRODUCT(E13,F13,G13,L13),0),2) -> 0 | O13: =+ROUND(IF(C13=12,PRODUCT(E13,F13,G13,L13),0),2) -> 0 | P13: =+ROUND(IF(C13=16,PRODUCT(E13,F13,G13,L13),0),2) -> 2160 | Q13: =+ROUND(IF(C13=20,PRODUCT(E13,F13,G13,L13),0),2) -> 0 | R13: =+ROUND(IF(C13=25,PRODUCT(E13,F13,G13,L13),0),2) -> 0
C14: 16 | D14: 250 | E14: 2 | F14: 2 | G14: =+ROUND(1595/D14,0) -> 6 | H14: 0.65 | I14: =32.45-0.1-1.5-0.815 -> 30.035 | J14: 0.65 | K14: =2*50*C14/1000 -> 1.6 | L14: =SUM(H14:J14)+K14 -> 32.935 | M14: =+ROUND(IF(C14=8,PRODUCT(E14,F14,G14,L14),0),2) -> 0 | N14: =+ROUND(IF(C14=10,PRODUCT(E14,F14,G14,L14),0),2) -> 0 | O14: =+ROUND(IF(C14=12,PRODUCT(E14,F14,G14,L14),0),2) -> 0 | P14: =+ROUND(IF(C14=16,PRODUCT(E14,F14,G14,L14),0),2) -> 790.44 | Q14: =+ROUND(IF(C14=20,PRODUCT(E14,F14,G14,L14),0),2) -> 0 | R14: =+ROUND(IF(C14=25,PRODUCT(E14,F14,G14,L14),0),2) -> 0
C15: 16 | D15: 250 | E15: 2 | F15: 2 | G15: =+ROUND(280/D15,0) -> 1 | H15: 0.65 | I15: =+I14-1.405 -> 28.63 | J15: 0.65 | K15: =2*50*C15/1000 -> 1.6 | L15: =SUM(H15:J15)+K15 -> 31.53 | M15: =+ROUND(IF(C15=8,PRODUCT(E15,F15,G15,L15),0),2) -> 0 | N15: =+ROUND(IF(C15=10,PRODUCT(E15,F15,G15,L15),0),2) -> 0 | O15: =+ROUND(IF(C15=12,PRODUCT(E15,F15,G15,L15),0),2) -> 0 | P15: =+ROUND(IF(C15=16,PRODUCT(E15,F15,G15,L15),0),2) -> 126.12 | Q15: =+ROUND(IF(C15=20,PRODUCT(E15,F15,G15,L15),0),2) -> 0 | R15: =+ROUND(IF(C15=25,PRODUCT(E15,F15,G15,L15),0),2) -> 0
C16: 16 | D16: 250 | E16: 2 | F16: 2 | G16: =+ROUND(13090/D16,0) -> 52 | H16: 0.65 | I16: 15.7 | J16: 0.65 | K16: =50*C16/1000 -> 0.8 | L16: =SUM(H16:J16)+K16 -> 17.8 | M16: =+ROUND(IF(C16=8,PRODUCT(E16,F16,G16,L16),0),2) -> 0 | N16: =+ROUND(IF(C16=10,PRODUCT(E16,F16,G16,L16),0),2) -> 0 | O16: =+ROUND(IF(C16=12,PRODUCT(E16,F16,G16,L16),0),2) -> 0 | P16: =+ROUND(IF(C16=16,PRODUCT(E16,F16,G16,L16),0),2) -> 3702.4 | Q16: =+ROUND(IF(C16=20,PRODUCT(E16,F16,G16,L16),0),2) -> 0 | R16: =+ROUND(IF(C16=25,PRODUCT(E16,F16,G16,L16),0),2) -> 0
B17: Dist. Bar @16 Dia (Top & Bottom) | C17: 16 | D17: 250 | E17: 2 | F17: 2 | G17: =+ROUND(465/D17,0) -> 2 | H17: 0.65 | I17: 8.68 | J17: 0.65 | L17: =SUM(H17:J17)+K17 -> 9.98 | M17: =+ROUND(IF(C17=8,PRODUCT(E17,F17,G17,L17),0),2) -> 0 | N17: =+ROUND(IF(C17=10,PRODUCT(E17,F17,G17,L17),0),2) -> 0 | O17: =+ROUND(IF(C17=12,PRODUCT(E17,F17,G17,L17),0),2) -> 0 | P17: =+ROUND(IF(C17=16,PRODUCT(E17,F17,G17,L17),0),2) -> 79.84 | Q17: =+ROUND(IF(C17=20,PRODUCT(E17,F17,G17,L17),0),2) -> 0 | R17: =+ROUND(IF(C17=25,PRODUCT(E17,F17,G17,L17),0),2) -> 0
C18: 16 | D18: 250 | E18: 2 | F18: 2 | G18: =+ROUND(10840/D18,0) -> 43 | H18: 0.65 | I18: 25.79 | J18: 0.65 | K18: =2*50*C18/1000 -> 1.6 | L18: =SUM(H18:J18)+K18 -> 28.69 | M18: =+ROUND(IF(C18=8,PRODUCT(E18,F18,G18,L18),0),2) -> 0 | N18: =+ROUND(IF(C18=10,PRODUCT(E18,F18,G18,L18),0),2) -> 0 | O18: =+ROUND(IF(C18=12,PRODUCT(E18,F18,G18,L18),0),2) -> 0 | P18: =+ROUND(IF(C18=16,PRODUCT(E18,F18,G18,L18),0),2) -> 4934.68 | Q18: =+ROUND(IF(C18=20,PRODUCT(E18,F18,G18,L18),0),2) -> 0 | R18: =+ROUND(IF(C18=25,PRODUCT(E18,F18,G18,L18),0),2) -> 0
C19: 16 | D19: 250 | E19: 2 | F19: 2 | G19: =+ROUND(2985/D19,0) -> 12 | H19: 0.65 | I19: 14.65 | J19: 0.65 | K19: 0.8 | L19: =SUM(H19:J19)+K19 -> 16.75 | M19: =+ROUND(IF(C19=8,PRODUCT(E19,F19,G19,L19),0),2) -> 0 | N19: =+ROUND(IF(C19=10,PRODUCT(E19,F19,G19,L19),0),2) -> 0 | O19: =+ROUND(IF(C19=12,PRODUCT(E19,F19,G19,L19),0),2) -> 0 | P19: =+ROUND(IF(C19=16,PRODUCT(E19,F19,G19,L19),0),2) -> 804 | Q19: =+ROUND(IF(C19=20,PRODUCT(E19,F19,G19,L19),0),2) -> 0 | R19: =+ROUND(IF(C19=25,PRODUCT(E19,F19,G19,L19),0),2) -> 0
C20: 16 | D20: 250 | E20: 2 | F20: 2 | G20: =+ROUND(1475/D20,0) -> 6 | H20: 0.65 | I20: 7.035 | J20: 0.65 | L20: =SUM(H20:J20)+K20 -> 8.335 | M20: =+ROUND(IF(C20=8,PRODUCT(E20,F20,G20,L20),0),2) -> 0 | N20: =+ROUND(IF(C20=10,PRODUCT(E20,F20,G20,L20),0),2) -> 0 | O20: =+ROUND(IF(C20=12,PRODUCT(E20,F20,G20,L20),0),2) -> 0 | P20: =+ROUND(IF(C20=16,PRODUCT(E20,F20,G20,L20),0),2) -> 200.04 | Q20: =+ROUND(IF(C20=20,PRODUCT(E20,F20,G20,L20),0),2) -> 0 | R20: =+ROUND(IF(C20=25,PRODUCT(E20,F20,G20,L20),0),2) -> 0
C21: 16 | D21: 250 | E21: 1 | F21: 2 | G21: =+ROUND(1510/D21,0) -> 6 | H21: 0.65 | I21: 40.35 | J21: 0.65 | K21: 2.4 | L21: =SUM(H21:J21)+K21 -> 44.05 | M21: =+ROUND(IF(C21=8,PRODUCT(E21,F21,G21,L21),0),2) -> 0 | N21: =+ROUND(IF(C21=10,PRODUCT(E21,F21,G21,L21),0),2) -> 0 | O21: =+ROUND(IF(C21=12,PRODUCT(E21,F21,G21,L21),0),2) -> 0 | P21: =+ROUND(IF(C21=16,PRODUCT(E21,F21,G21,L21),0),2) -> 528.6 | Q21: =+ROUND(IF(C21=20,PRODUCT(E21,F21,G21,L21),0),2) -> 0 | R21: =+ROUND(IF(C21=25,PRODUCT(E21,F21,G21,L21),0),2) -> 0
C22: 16 | D22: 250 | E22: 1 | F22: 2 | G22: =+ROUND(7725/D22,0) -> 31 | H22: 0.65 | I22: 77.86 | J22: 0.65 | K22: =0.8*7 -> 5.6 | L22: =SUM(H22:J22)+K22 -> 84.76 | M22: =+ROUND(IF(C22=8,PRODUCT(E22,F22,G22,L22),0),2) -> 0 | N22: =+ROUND(IF(C22=10,PRODUCT(E22,F22,G22,L22),0),2) -> 0 | O22: =+ROUND(IF(C22=12,PRODUCT(E22,F22,G22,L22),0),2) -> 0 | P22: =+ROUND(IF(C22=16,PRODUCT(E22,F22,G22,L22),0),2) -> 5255.12 | Q22: =+ROUND(IF(C22=20,PRODUCT(E22,F22,G22,L22),0),2) -> 0 | R22: =+ROUND(IF(C22=25,PRODUCT(E22,F22,G22,L22),0),2) -> 0
C23: 16 | D23: 250 | E23: 1 | F23: 2 | G23: =+ROUND(6565/D23,0) -> 26 | H23: 0.65 | I23: 55.68 | J23: 0.65 | K23: 4 | L23: =SUM(H23:J23)+K23 -> 60.98 | M23: =+ROUND(IF(C23=8,PRODUCT(E23,F23,G23,L23),0),2) -> 0 | N23: =+ROUND(IF(C23=10,PRODUCT(E23,F23,G23,L23),0),2) -> 0 | O23: =+ROUND(IF(C23=12,PRODUCT(E23,F23,G23,L23),0),2) -> 0 | P23: =+ROUND(IF(C23=16,PRODUCT(E23,F23,G23,L23),0),2) -> 3170.96 | Q23: =+ROUND(IF(C23=20,PRODUCT(E23,F23,G23,L23),0),2) -> 0 | R23: =+ROUND(IF(C23=25,PRODUCT(E23,F23,G23,L23),0),2) -> 0
C24: 16 | D24: 250 | E24: 2 | F24: 2 | G24: =+ROUND(1405/D24,0) -> 6 | H24: 0.65 | I24: 14.42 | J24: 0.65 | K24: 0.8 | L24: =SUM(H24:J24)+K24 -> 16.52 | M24: =+ROUND(IF(C24=8,PRODUCT(E24,F24,G24,L24),0),2) -> 0 | N24: =+ROUND(IF(C24=10,PRODUCT(E24,F24,G24,L24),0),2) -> 0 | O24: =+ROUND(IF(C24=12,PRODUCT(E24,F24,G24,L24),0),2) -> 0 | P24: =+ROUND(IF(C24=16,PRODUCT(E24,F24,G24,L24),0),2) -> 396.48 | Q24: =+ROUND(IF(C24=20,PRODUCT(E24,F24,G24,L24),0),2) -> 0 | R24: =+ROUND(IF(C24=25,PRODUCT(E24,F24,G24,L24),0),2) -> 0
C25: 16 | D25: 250 | E25: 2 | F25: 2 | G25: =+ROUND(815/D25,0) -> 3 | H25: 0.65 | I25: 12.725 | J25: 0.65 | K25: 0.8 | L25: =SUM(H25:J25)+K25 -> 14.825 | M25: =+ROUND(IF(C25=8,PRODUCT(E25,F25,G25,L25),0),2) -> 0 | N25: =+ROUND(IF(C25=10,PRODUCT(E25,F25,G25,L25),0),2) -> 0 | O25: =+ROUND(IF(C25=12,PRODUCT(E25,F25,G25,L25),0),2) -> 0 | P25: =+ROUND(IF(C25=16,PRODUCT(E25,F25,G25,L25),0),2) -> 177.9 | Q25: =+ROUND(IF(C25=20,PRODUCT(E25,F25,G25,L25),0),2) -> 0 | R25: =+ROUND(IF(C25=25,PRODUCT(E25,F25,G25,L25),0),2) -> 0
C26: 16 | D26: 250 | E26: 2 | F26: 2 | G26: =+ROUND(1500/D26,0) -> 6 | H26: 0.65 | I26: 8.775 | J26: 0.65 | L26: =SUM(H26:J26)+K26 -> 10.075 | M26: =+ROUND(IF(C26=8,PRODUCT(E26,F26,G26,L26),0),2) -> 0 | N26: =+ROUND(IF(C26=10,PRODUCT(E26,F26,G26,L26),0),2) -> 0 | O26: =+ROUND(IF(C26=12,PRODUCT(E26,F26,G26,L26),0),2) -> 0 | P26: =+ROUND(IF(C26=16,PRODUCT(E26,F26,G26,L26),0),2) -> 241.8 | Q26: =+ROUND(IF(C26=20,PRODUCT(E26,F26,G26,L26),0),2) -> 0 | R26: =+ROUND(IF(C26=25,PRODUCT(E26,F26,G26,L26),0),2) -> 0
B27: Lift Pit Raft | L27: =SUM(H27:J27)+K27 -> 0 | M27: =+ROUND(IF(C27=8,PRODUCT(E27,F27,G27,L27),0),2) -> 0 | N27: =+ROUND(IF(C27=10,PRODUCT(E27,F27,G27,L27),0),2) -> 0 | O27: =+ROUND(IF(C27=12,PRODUCT(E27,F27,G27,L27),0),2) -> 0 | P27: =+ROUND(IF(C27=16,PRODUCT(E27,F27,G27,L27),0),2) -> 0 | Q27: =+ROUND(IF(C27=20,PRODUCT(E27,F27,G27,L27),0),2) -> 0 | R27: =+ROUND(IF(C27=25,PRODUCT(E27,F27,G27,L27),0),2) -> 0
B28: Main Bar @16 Dia (Top & Bottom) | C28: 16 | D28: 250 | E28: 2 | F28: 2 | G28: =+ROUND(6065/D28,0) -> 24 | H28: 0.65 | I28: 5.045 | J28: 0.65 | L28: =SUM(H28:J28)+K28 -> 6.345 | M28: =+ROUND(IF(C28=8,PRODUCT(E28,F28,G28,L28),0),2) -> 0 | N28: =+ROUND(IF(C28=10,PRODUCT(E28,F28,G28,L28),0),2) -> 0 | O28: =+ROUND(IF(C28=12,PRODUCT(E28,F28,G28,L28),0),2) -> 0 | P28: =+ROUND(IF(C28=16,PRODUCT(E28,F28,G28,L28),0),2) -> 609.12 | Q28: =+ROUND(IF(C28=20,PRODUCT(E28,F28,G28,L28),0),2) -> 0 | R28: =+ROUND(IF(C28=25,PRODUCT(E28,F28,G28,L28),0),2) -> 0
C29: 16 | D29: 250 | E29: 2 | F29: 2 | G29: =+ROUND(5145/D29,0) -> 21 | H29: 0.65 | I29: 6.065 | J29: 0.65 | L29: =SUM(H29:J29)+K29 -> 7.365 | M29: =+ROUND(IF(C29=8,PRODUCT(E29,F29,G29,L29),0),2) -> 0 | N29: =+ROUND(IF(C29=10,PRODUCT(E29,F29,G29,L29),0),2) -> 0 | O29: =+ROUND(IF(C29=12,PRODUCT(E29,F29,G29,L29),0),2) -> 0 | P29: =+ROUND(IF(C29=16,PRODUCT(E29,F29,G29,L29),0),2) -> 618.66 | Q29: =+ROUND(IF(C29=20,PRODUCT(E29,F29,G29,L29),0),2) -> 0 | R29: =+ROUND(IF(C29=25,PRODUCT(E29,F29,G29,L29),0),2) -> 0
B30: Bottom Extra R/F | L30: =SUM(H30:J30)+K30 -> 0 | M30: =+ROUND(IF(C30=8,PRODUCT(E30,F30,G30,L30),0),2) -> 0 | N30: =+ROUND(IF(C30=10,PRODUCT(E30,F30,G30,L30),0),2) -> 0 | O30: =+ROUND(IF(C30=12,PRODUCT(E30,F30,G30,L30),0),2) -> 0 | P30: =+ROUND(IF(C30=16,PRODUCT(E30,F30,G30,L30),0),2) -> 0 | Q30: =+ROUND(IF(C30=20,PRODUCT(E30,F30,G30,L30),0),2) -> 0 | R30: =+ROUND(IF(C30=25,PRODUCT(E30,F30,G30,L30),0),2) -> 0
B31: Grid 1/P-Q (D & H) | C31: 25 | D31: 250 | E31: 2 | F31: 2 | G31: =+ROUND(2650/D31+1,0) -> 12 | I31: =6.01-0.05 -> 5.96 | L31: =SUM(H31:J31)+K31 -> 5.96 | M31: =+ROUND(IF(C31=8,PRODUCT(E31,F31,G31,L31),0),2) -> 0 | N31: =+ROUND(IF(C31=10,PRODUCT(E31,F31,G31,L31),0),2) -> 0 | O31: =+ROUND(IF(C31=12,PRODUCT(E31,F31,G31,L31),0),2) -> 0 | P31: =+ROUND(IF(C31=16,PRODUCT(E31,F31,G31,L31),0),2) -> 0 | Q31: =+ROUND(IF(C31=20,PRODUCT(E31,F31,G31,L31),0),2) -> 0 | R31: =+ROUND(IF(C31=25,PRODUCT(E31,F31,G31,L31),0),2) -> 286.08
B32: Grid 1/P-Q ( C ) | C32: 20 | D32: 250 | E32: 2 | F32: 1 | G32: =+ROUND(6010/D32+1,0) -> 25 | I32: 2.65 | L32: =SUM(H32:J32)+K32 -> 2.65 | M32: =+ROUND(IF(C32=8,PRODUCT(E32,F32,G32,L32),0),2) -> 0 | N32: =+ROUND(IF(C32=10,PRODUCT(E32,F32,G32,L32),0),2) -> 0 | O32: =+ROUND(IF(C32=12,PRODUCT(E32,F32,G32,L32),0),2) -> 0 | P32: =+ROUND(IF(C32=16,PRODUCT(E32,F32,G32,L32),0),2) -> 0 | Q32: =+ROUND(IF(C32=20,PRODUCT(E32,F32,G32,L32),0),2) -> 132.5 | R32: =+ROUND(IF(C32=25,PRODUCT(E32,F32,G32,L32),0),2) -> 0
B33: Grid 1/O (A) | C33: 12 | D33: 250 | E33: 2 | F33: 1 | G33: =+ROUND(1915/D33+1,0) -> 9 | I33: 1.65 | L33: =SUM(H33:J33)+K33 -> 1.65 | M33: =+ROUND(IF(C33=8,PRODUCT(E33,F33,G33,L33),0),2) -> 0 | N33: =+ROUND(IF(C33=10,PRODUCT(E33,F33,G33,L33),0),2) -> 0 | O33: =+ROUND(IF(C33=12,PRODUCT(E33,F33,G33,L33),0),2) -> 29.7 | P33: =+ROUND(IF(C33=16,PRODUCT(E33,F33,G33,L33),0),2) -> 0 | Q33: =+ROUND(IF(C33=20,PRODUCT(E33,F33,G33,L33),0),2) -> 0 | R33: =+ROUND(IF(C33=25,PRODUCT(E33,F33,G33,L33),0),2) -> 0
C34: 12 | D34: 250 | E34: 2 | F34: 1 | G34: =+ROUND(1650/D34+1,0) -> 8 | I34: 1.915 | L34: =SUM(H34:J34)+K34 -> 1.915 | M34: =+ROUND(IF(C34=8,PRODUCT(E34,F34,G34,L34),0),2) -> 0 | N34: =+ROUND(IF(C34=10,PRODUCT(E34,F34,G34,L34),0),2) -> 0 | O34: =+ROUND(IF(C34=12,PRODUCT(E34,F34,G34,L34),0),2) -> 30.64 | P34: =+ROUND(IF(C34=16,PRODUCT(E34,F34,G34,L34),0),2) -> 0 | Q34: =+ROUND(IF(C34=20,PRODUCT(E34,F34,G34,L34),0),2) -> 0 | R34: =+ROUND(IF(C34=25,PRODUCT(E34,F34,G34,L34),0),2) -> 0
B35: Grid 1/L-M (A) | C35: 12 | D35: 250 | E35: 2 | F35: 1 | G35: =+ROUND(1915/D35+1,0) -> 9 | I35: 1.65 | L35: =SUM(H35:J35)+K35 -> 1.65 | M35: =+ROUND(IF(C35=8,PRODUCT(E35,F35,G35,L35),0),2) -> 0 | N35: =+ROUND(IF(C35=10,PRODUCT(E35,F35,G35,L35),0),2) -> 0 | O35: =+ROUND(IF(C35=12,PRODUCT(E35,F35,G35,L35),0),2) -> 29.7 | P35: =+ROUND(IF(C35=16,PRODUCT(E35,F35,G35,L35),0),2) -> 0 | Q35: =+ROUND(IF(C35=20,PRODUCT(E35,F35,G35,L35),0),2) -> 0 | R35: =+ROUND(IF(C35=25,PRODUCT(E35,F35,G35,L35),0),2) -> 0
C36: 12 | D36: 250 | E36: 2 | F36: 1 | G36: =+ROUND(1650/D36+1,0) -> 8 | I36: 1.915 | L36: =SUM(H36:J36)+K36 -> 1.915 | M36: =+ROUND(IF(C36=8,PRODUCT(E36,F36,G36,L36),0),2) -> 0 | N36: =+ROUND(IF(C36=10,PRODUCT(E36,F36,G36,L36),0),2) -> 0 | O36: =+ROUND(IF(C36=12,PRODUCT(E36,F36,G36,L36),0),2) -> 30.64 | P36: =+ROUND(IF(C36=16,PRODUCT(E36,F36,G36,L36),0),2) -> 0 | Q36: =+ROUND(IF(C36=20,PRODUCT(E36,F36,G36,L36),0),2) -> 0 | R36: =+ROUND(IF(C36=25,PRODUCT(E36,F36,G36,L36),0),2) -> 0
B37: Grid 1/F-J (D & H) | C37: 25 | D37: 250 | E37: 2 | F37: 2 | G37: =+ROUND(2650/D37+1,0) -> 12 | I37: =6.01-0.05 -> 5.96 | L37: =SUM(H37:J37)+K37 -> 5.96 | M37: =+ROUND(IF(C37=8,PRODUCT(E37,F37,G37,L37),0),2) -> 0 | N37: =+ROUND(IF(C37=10,PRODUCT(E37,F37,G37,L37),0),2) -> 0 | O37: =+ROUND(IF(C37=12,PRODUCT(E37,F37,G37,L37),0),2) -> 0 | P37: =+ROUND(IF(C37=16,PRODUCT(E37,F37,G37,L37),0),2) -> 0 | Q37: =+ROUND(IF(C37=20,PRODUCT(E37,F37,G37,L37),0),2) -> 0 | R37: =+ROUND(IF(C37=25,PRODUCT(E37,F37,G37,L37),0),2) -> 286.08
B38: Grid 1/F-J ( C ) | C38: 20 | D38: 250 | E38: 2 | F38: 1 | G38: =+ROUND(6010/D38+1,0) -> 25 | I38: 2.65 | L38: =SUM(H38:J38)+K38 -> 2.65 | M38: =+ROUND(IF(C38=8,PRODUCT(E38,F38,G38,L38),0),2) -> 0 | N38: =+ROUND(IF(C38=10,PRODUCT(E38,F38,G38,L38),0),2) -> 0 | O38: =+ROUND(IF(C38=12,PRODUCT(E38,F38,G38,L38),0),2) -> 0 | P38: =+ROUND(IF(C38=16,PRODUCT(E38,F38,G38,L38),0),2) -> 0 | Q38: =+ROUND(IF(C38=20,PRODUCT(E38,F38,G38,L38),0),2) -> 132.5 | R38: =+ROUND(IF(C38=25,PRODUCT(E38,F38,G38,L38),0),2) -> 0
B39: Grid 3/Q & F ( C) | C39: 20 | D39: 250 | E39: 2 | F39: 2 | G39: =+ROUND(2800/D39+1,0) -> 12 | I39: 2.35 | L39: =SUM(H39:J39)+K39 -> 2.35 | M39: =+ROUND(IF(C39=8,PRODUCT(E39,F39,G39,L39),0),2) -> 0 | N39: =+ROUND(IF(C39=10,PRODUCT(E39,F39,G39,L39),0),2) -> 0 | O39: =+ROUND(IF(C39=12,PRODUCT(E39,F39,G39,L39),0),2) -> 0 | P39: =+ROUND(IF(C39=16,PRODUCT(E39,F39,G39,L39),0),2) -> 0 | Q39: =+ROUND(IF(C39=20,PRODUCT(E39,F39,G39,L39),0),2) -> 112.8 | R39: =+ROUND(IF(C39=25,PRODUCT(E39,F39,G39,L39),0),2) -> 0
B40: Grid 3/Q & F( D) | C40: 25 | D40: 250 | E40: 2 | F40: 2 | G40: =+ROUND(2350/D40+1,0) -> 10 | I40: 2.8 | L40: =SUM(H40:J40)+K40 -> 2.8 | M40: =+ROUND(IF(C40=8,PRODUCT(E40,F40,G40,L40),0),2) -> 0 | N40: =+ROUND(IF(C40=10,PRODUCT(E40,F40,G40,L40),0),2) -> 0 | O40: =+ROUND(IF(C40=12,PRODUCT(E40,F40,G40,L40),0),2) -> 0 | P40: =+ROUND(IF(C40=16,PRODUCT(E40,F40,G40,L40),0),2) -> 0 | Q40: =+ROUND(IF(C40=20,PRODUCT(E40,F40,G40,L40),0),2) -> 0 | R40: =+ROUND(IF(C40=25,PRODUCT(E40,F40,G40,L40),0),2) -> 112
B41: Grid 3/P & J (D) | C41: 25 | D41: 250 | E41: 2 | F41: 2 | G41: =+ROUND(2850/D41+1,0) -> 12 | I41: 2.75 | L41: =SUM(H41:J41)+K41 -> 2.75 | M41: =+ROUND(IF(C41=8,PRODUCT(E41,F41,G41,L41),0),2) -> 0 | N41: =+ROUND(IF(C41=10,PRODUCT(E41,F41,G41,L41),0),2) -> 0 | O41: =+ROUND(IF(C41=12,PRODUCT(E41,F41,G41,L41),0),2) -> 0 | P41: =+ROUND(IF(C41=16,PRODUCT(E41,F41,G41,L41),0),2) -> 0 | Q41: =+ROUND(IF(C41=20,PRODUCT(E41,F41,G41,L41),0),2) -> 0 | R41: =+ROUND(IF(C41=25,PRODUCT(E41,F41,G41,L41),0),2) -> 132
...

Sheet Columns Steel
A1: Reinforcement
A2: Sr. No. | B2: Designation | C2: Dia | D2: C/C (mm) | E2: No | F2: No | G2: No of Bars | H2: Bar Length (mtr) | K2: Lap Length | L2: One Bar Length (MTR) | M2: Dia Wise Weight (Kg)
H3: a | I3: b | J3: c | M3: 8mm | N3: 10mm | O3: 12mm | P3: 16mm | Q3: 20MM | R3: 25mm
B5: Column From Foundation to Plinth Level (100.15-97.2)
B6: C 1 (300X600) | C6: 16 | E6: 32 | F6: 1 | G6: 8 | H6: 0.3 | I6: =100.3-97.06-0.075 -> 3.165 | K6: =40*C6/1000 -> 0.64 | L6: =SUM(H6:J6)+K6 -> 4.105 | M6: =+ROUND(IF(C6=8,PRODUCT(E6,F6,G6,L6),0),2) -> 0 | N6: =+ROUND(IF(C6=10,PRODUCT(E6,F6,G6,L6),0),2) -> 0 | O6: =+ROUND(IF(C6=12,PRODUCT(E6,F6,G6,L6),0),2) -> 0 | P6: =+ROUND(IF(C6=16,PRODUCT(E6,F6,G6,L6),0),2) -> 1050.88 | Q6: =+ROUND(IF(C6=20,PRODUCT(E6,F6,G6,L6),0),2) -> 0 | R6: =+ROUND(IF(C6=25,PRODUCT(E6,F6,G6,L6),0),2) -> 0
C7: 12 | E7: =+E6 -> 32 | F7: 1 | G7: 6 | H7: 0.3 | I7: =100.3-97.06-0.075 -> 3.165 | K7: =40*C7/1000 -> 0.48 | L7: =SUM(H7:J7)+K7 -> 3.945 | M7: =+ROUND(IF(C7=8,PRODUCT(E7,F7,G7,L7),0),2) -> 0 | N7: =+ROUND(IF(C7=10,PRODUCT(E7,F7,G7,L7),0),2) -> 0 | O7: =+ROUND(IF(C7=12,PRODUCT(E7,F7,G7,L7),0),2) -> 757.44 | P7: =+ROUND(IF(C7=16,PRODUCT(E7,F7,G7,L7),0),2) -> 0 | Q7: =+ROUND(IF(C7=20,PRODUCT(E7,F7,G7,L7),0),2) -> 0 | R7: =+ROUND(IF(C7=25,PRODUCT(E7,F7,G7,L7),0),2) -> 0
B8: Stirrups ZONE A | C8: 10 | D8: 75 | E8: =+E7 -> 32 | F8: 2 | G8: =+ROUND(600/D8,0) -> 8 | I8: =2*(0.2+0.5)+24*0.01 -> 1.64 | L8: =SUM(H8:J8)+K8 -> 1.64 | M8: =+ROUND(IF(C8=8,PRODUCT(E8,F8,G8,L8),0),2) -> 0 | N8: =+ROUND(IF(C8=10,PRODUCT(E8,F8,G8,L8),0),2) -> 839.68 | O8: =+ROUND(IF(C8=12,PRODUCT(E8,F8,G8,L8),0),2) -> 0 | P8: =+ROUND(IF(C8=16,PRODUCT(E8,F8,G8,L8),0),2) -> 0 | Q8: =+ROUND(IF(C8=20,PRODUCT(E8,F8,G8,L8),0),2) -> 0 | R8: =+ROUND(IF(C8=25,PRODUCT(E8,F8,G8,L8),0),2) -> 0
C9: 10 | D9: 75 | E9: =+E8 -> 32 | F9: 2 | G9: =+ROUND(600/D9,0) -> 8 | I9: =2*(0.2+0.115)+24*0.01 -> 0.87 | L9: =SUM(H9:J9)+K9 -> 0.87 | M9: =+ROUND(IF(C9=8,PRODUCT(E9,F9,G9,L9),0),2) -> 0 | N9: =+ROUND(IF(C9=10,PRODUCT(E9,F9,G9,L9),0),2) -> 445.44 | O9: =+ROUND(IF(C9=12,PRODUCT(E9,F9,G9,L9),0),2) -> 0 | P9: =+ROUND(IF(C9=16,PRODUCT(E9,F9,G9,L9),0),2) -> 0 | Q9: =+ROUND(IF(C9=20,PRODUCT(E9,F9,G9,L9),0),2) -> 0 | R9: =+ROUND(IF(C9=25,PRODUCT(E9,F9,G9,L9),0),2) -> 0
C10: 10 | D10: 75 | E10: =+E9 -> 32 | F10: =2*2 -> 4 | G10: =+ROUND(600/D10,0) -> 8 | I10: =+(0.168+0.168+0.2)+20*0.01 -> 0.736 | L10: =SUM(H10:J10)+K10 -> 0.736 | M10: =+ROUND(IF(C10=8,PRODUCT(E10,F10,G10,L10),0),2) -> 0 | N10: =+ROUND(IF(C10=10,PRODUCT(E10,F10,G10,L10),0),2) -> 753.66 | O10: =+ROUND(IF(C10=12,PRODUCT(E10,F10,G10,L10),0),2) -> 0 | P10: =+ROUND(IF(C10=16,PRODUCT(E10,F10,G10,L10),0),2) -> 0 | Q10: =+ROUND(IF(C10=20,PRODUCT(E10,F10,G10,L10),0),2) -> 0 | R10: =+ROUND(IF(C10=25,PRODUCT(E10,F10,G10,L10),0),2) -> 0
B11: Stirrups ZONE B | C11: 8 | D11: 150 | E11: =+E10 -> 32 | F11: 1 | G11: =+ROUND(450/D11+1,0) -> 4 | I11: =2*(0.204+0.504)+24*0.008 -> 1.608 | L11: =SUM(H11:J11)+K11 -> 1.608 | M11: =+ROUND(IF(C11=8,PRODUCT(E11,F11,G11,L11),0),2) -> 205.82 | N11: =+ROUND(IF(C11=10,PRODUCT(E11,F11,G11,L11),0),2) -> 0 | O11: =+ROUND(IF(C11=12,PRODUCT(E11,F11,G11,L11),0),2) -> 0 | P11: =+ROUND(IF(C11=16,PRODUCT(E11,F11,G11,L11),0),2) -> 0 | Q11: =+ROUND(IF(C11=20,PRODUCT(E11,F11,G11,L11),0),2) -> 0 | R11: =+ROUND(IF(C11=25,PRODUCT(E11,F11,G11,L11),0),2) -> 0
C12: 8 | D12: 150 | E12: =+E11 -> 32 | F12: 1 | G12: =+ROUND(450/D12+1,0) -> 4 | I12: =2*(0.204+0.115)+24*0.008 -> 0.83 | L12: =SUM(H12:J12)+K12 -> 0.83 | M12: =+ROUND(IF(C12=8,PRODUCT(E12,F12,G12,L12),0),2) -> 106.24 | N12: =+ROUND(IF(C12=10,PRODUCT(E12,F12,G12,L12),0),2) -> 0 | O12: =+ROUND(IF(C12=12,PRODUCT(E12,F12,G12,L12),0),2) -> 0 | P12: =+ROUND(IF(C12=16,PRODUCT(E12,F12,G12,L12),0),2) -> 0 | Q12: =+ROUND(IF(C12=20,PRODUCT(E12,F12,G12,L12),0),2) -> 0 | R12: =+ROUND(IF(C12=25,PRODUCT(E12,F12,G12,L12),0),2) -> 0
C13: 8 | D13: 150 | E13: =+E12 -> 32 | F13: 2 | G13: =+ROUND(450/D13+1,0) -> 4 | I13: =+(0.168+0.168+0.204)+20*0.008 -> 0.7 | L13: =SUM(H13:J13)+K13 -> 0.7 | M13: =+ROUND(IF(C13=8,PRODUCT(E13,F13,G13,L13),0),2) -> 179.2 | N13: =+ROUND(IF(C13=10,PRODUCT(E13,F13,G13,L13),0),2) -> 0 | O13: =+ROUND(IF(C13=12,PRODUCT(E13,F13,G13,L13),0),2) -> 0 | P13: =+ROUND(IF(C13=16,PRODUCT(E13,F13,G13,L13),0),2) -> 0 | Q13: =+ROUND(IF(C13=20,PRODUCT(E13,F13,G13,L13),0),2) -> 0 | R13: =+ROUND(IF(C13=25,PRODUCT(E13,F13,G13,L13),0),2) -> 0
B14: C 2 (300X600) | C14: 20 | E14: 22 | F14: 1 | G14: 6 | H14: 0.3 | I14: =100.3-97.06-0.075 -> 3.165 | K14: =40*C14/1000 -> 0.8 | L14: =SUM(H14:J14)+K14 -> 4.265 | M14: =+ROUND(IF(C14=8,PRODUCT(E14,F14,G14,L14),0),2) -> 0 | N14: =+ROUND(IF(C14=10,PRODUCT(E14,F14,G14,L14),0),2) -> 0 | O14: =+ROUND(IF(C14=12,PRODUCT(E14,F14,G14,L14),0),2) -> 0 | P14: =+ROUND(IF(C14=16,PRODUCT(E14,F14,G14,L14),0),2) -> 0 | Q14: =+ROUND(IF(C14=20,PRODUCT(E14,F14,G14,L14),0),2) -> 562.98 | R14: =+ROUND(IF(C14=25,PRODUCT(E14,F14,G14,L14),0),2) -> 0
C15: 16 | E15: =+E14 -> 22 | F15: 1 | G15: 8 | H15: 0.3 | I15: =100.3-97.06-0.075 -> 3.165 | K15: =40*C15/1000 -> 0.64 | L15: =SUM(H15:J15)+K15 -> 4.105 | M15: =+ROUND(IF(C15=8,PRODUCT(E15,F15,G15,L15),0),2) -> 0 | N15: =+ROUND(IF(C15=10,PRODUCT(E15,F15,G15,L15),0),2) -> 0 | O15: =+ROUND(IF(C15=12,PRODUCT(E15,F15,G15,L15),0),2) -> 0 | P15: =+ROUND(IF(C15=16,PRODUCT(E15,F15,G15,L15),0),2) -> 722.48 | Q15: =+ROUND(IF(C15=20,PRODUCT(E15,F15,G15,L15),0),2) -> 0 | R15: =+ROUND(IF(C15=25,PRODUCT(E15,F15,G15,L15),0),2) -> 0
B16: Stirrups ZONE A | C16: 10 | D16: 75 | E16: =+E15 -> 22 | F16: 2 | G16: =+ROUND(600/D16,0) -> 8 | I16: =2*(0.2+0.5)+24*0.01 -> 1.64 | L16: =SUM(H16:J16)+K16 -> 1.64 | M16: =+ROUND(IF(C16=8,PRODUCT(E16,F16,G16,L16),0),2) -> 0 | N16: =+ROUND(IF(C16=10,PRODUCT(E16,F16,G16,L16),0),2) -> 577.28 | O16: =+ROUND(IF(C16=12,PRODUCT(E16,F16,G16,L16),0),2) -> 0 | P16: =+ROUND(IF(C16=16,PRODUCT(E16,F16,G16,L16),0),2) -> 0 | Q16: =+ROUND(IF(C16=20,PRODUCT(E16,F16,G16,L16),0),2) -> 0 | R16: =+ROUND(IF(C16=25,PRODUCT(E16,F16,G16,L16),0),2) -> 0
C17: 10 | D17: 75 | E17: =+E16 -> 22 | F17: 2 | G17: =+ROUND(600/D17,0) -> 8 | I17: =2*(0.2+0.115)+24*0.01 -> 0.87 | L17: =SUM(H17:J17)+K17 -> 0.87 | M17: =+ROUND(IF(C17=8,PRODUCT(E17,F17,G17,L17),0),2) -> 0 | N17: =+ROUND(IF(C17=10,PRODUCT(E17,F17,G17,L17),0),2) -> 306.24 | O17: =+ROUND(IF(C17=12,PRODUCT(E17,F17,G17,L17),0),2) -> 0 | P17: =+ROUND(IF(C17=16,PRODUCT(E17,F17,G17,L17),0),2) -> 0 | Q17: =+ROUND(IF(C17=20,PRODUCT(E17,F17,G17,L17),0),2) -> 0 | R17: =+ROUND(IF(C17=25,PRODUCT(E17,F17,G17,L17),0),2) -> 0
C18: 10 | D18: 75 | E18: =+E17 -> 22 | F18: =2*2 -> 4 | G18: =+ROUND(600/D18,0) -> 8 | I18: =+(0.168+0.168+0.2)+20*0.01 -> 0.736 | L18: =SUM(H18:J18)+K18 -> 0.736 | M18: =+ROUND(IF(C18=8,PRODUCT(E18,F18,G18,L18),0),2) -> 0 | N18: =+ROUND(IF(C18=10,PRODUCT(E18,F18,G18,L18),0),2) -> 518.14 | O18: =+ROUND(IF(C18=12,PRODUCT(E18,F18,G18,L18),0),2) -> 0 | P18: =+ROUND(IF(C18=16,PRODUCT(E18,F18,G18,L18),0),2) -> 0 | Q18: =+ROUND(IF(C18=20,PRODUCT(E18,F18,G18,L18),0),2) -> 0 | R18: =+ROUND(IF(C18=25,PRODUCT(E18,F18,G18,L18),0),2) -> 0
B19: Stirrups ZONE B | C19: 8 | D19: 150 | E19: =+E18 -> 22 | F19: 1 | G19: =+ROUND(450/D19+1,0) -> 4 | I19: =2*(0.204+0.504)+24*0.008 -> 1.608 | L19: =SUM(H19:J19)+K19 -> 1.608 | M19: =+ROUND(IF(C19=8,PRODUCT(E19,F19,G19,L19),0),2) -> 141.5 | N19: =+ROUND(IF(C19=10,PRODUCT(E19,F19,G19,L19),0),2) -> 0 | O19: =+ROUND(IF(C19=12,PRODUCT(E19,F19,G19,L19),0),2) -> 0 | P19: =+ROUND(IF(C19=16,PRODUCT(E19,F19,G19,L19),0),2) -> 0 | Q19: =+ROUND(IF(C19=20,PRODUCT(E19,F19,G19,L19),0),2) -> 0 | R19: =+ROUND(IF(C19=25,PRODUCT(E19,F19,G19,L19),0),2) -> 0
C20: 8 | D20: 150 | E20: =+E19 -> 22 | F20: 1 | G20: =+ROUND(450/D20+1,0) -> 4 | I20: =2*(0.204+0.115)+24*0.008 -> 0.83 | L20: =SUM(H20:J20)+K20 -> 0.83 | M20: =+ROUND(IF(C20=8,PRODUCT(E20,F20,G20,L20),0),2) -> 73.04 | N20: =+ROUND(IF(C20=10,PRODUCT(E20,F20,G20,L20),0),2) -> 0 | O20: =+ROUND(IF(C20=12,PRODUCT(E20,F20,G20,L20),0),2) -> 0 | P20: =+ROUND(IF(C20=16,PRODUCT(E20,F20,G20,L20),0),2) -> 0 | Q20: =+ROUND(IF(C20=20,PRODUCT(E20,F20,G20,L20),0),2) -> 0 | R20: =+ROUND(IF(C20=25,PRODUCT(E20,F20,G20,L20),0),2) -> 0
C21: 8 | D21: 150 | E21: =+E20 -> 22 | F21: 2 | G21: =+ROUND(450/D21+1,0) -> 4 | I21: =+(0.168+0.168+0.204)+20*0.008 -> 0.7 | L21: =SUM(H21:J21)+K21 -> 0.7 | M21: =+ROUND(IF(C21=8,PRODUCT(E21,F21,G21,L21),0),2) -> 123.2 | N21: =+ROUND(IF(C21=10,PRODUCT(E21,F21,G21,L21),0),2) -> 0 | O21: =+ROUND(IF(C21=12,PRODUCT(E21,F21,G21,L21),0),2) -> 0 | P21: =+ROUND(IF(C21=16,PRODUCT(E21,F21,G21,L21),0),2) -> 0 | Q21: =+ROUND(IF(C21=20,PRODUCT(E21,F21,G21,L21),0),2) -> 0 | R21: =+ROUND(IF(C21=25,PRODUCT(E21,F21,G21,L21),0),2) -> 0
B22: C 3 (300X600) | C22: 25 | E22: 4 | F22: 1 | G22: 10 | H22: 0.3 | I22: =100.3-97.06-0.075 -> 3.165 | K22: =40*C22/1000 -> 1 | L22: =SUM(H22:J22)+K22 -> 4.465 | M22: =+ROUND(IF(C22=8,PRODUCT(E22,F22,G22,L22),0),2) -> 0 | N22: =+ROUND(IF(C22=10,PRODUCT(E22,F22,G22,L22),0),2) -> 0 | O22: =+ROUND(IF(C22=12,PRODUCT(E22,F22,G22,L22),0),2) -> 0 | P22: =+ROUND(IF(C22=16,PRODUCT(E22,F22,G22,L22),0),2) -> 0 | Q22: =+ROUND(IF(C22=20,PRODUCT(E22,F22,G22,L22),0),2) -> 0 | R22: =+ROUND(IF(C22=25,PRODUCT(E22,F22,G22,L22),0),2) -> 178.6
C23: 20 | E23: =+E22 -> 4 | F23: 1 | G23: 4 | H23: 0.3 | I23: =100.3-97.06-0.075 -> 3.165 | K23: =40*C23/1000 -> 0.8 | L23: =SUM(H23:J23)+K23 -> 4.265 | M23: =+ROUND(IF(C23=8,PRODUCT(E23,F23,G23,L23),0),2) -> 0 | N23: =+ROUND(IF(C23=10,PRODUCT(E23,F23,G23,L23),0),2) -> 0 | O23: =+ROUND(IF(C23=12,PRODUCT(E23,F23,G23,L23),0),2) -> 0 | P23: =+ROUND(IF(C23=16,PRODUCT(E23,F23,G23,L23),0),2) -> 0 | Q23: =+ROUND(IF(C23=20,PRODUCT(E23,F23,G23,L23),0),2) -> 68.24 | R23: =+ROUND(IF(C23=25,PRODUCT(E23,F23,G23,L23),0),2) -> 0
B24: Stirrups ZONE A | C24: 10 | D24: 75 | E24: =+E23 -> 4 | F24: 2 | G24: =+ROUND(600/D24,0) -> 8 | I24: =2*(0.2+0.5)+24*0.01 -> 1.64 | L24: =SUM(H24:J24)+K24 -> 1.64 | M24: =+ROUND(IF(C24=8,PRODUCT(E24,F24,G24,L24),0),2) -> 0 | N24: =+ROUND(IF(C24=10,PRODUCT(E24,F24,G24,L24),0),2) -> 104.96 | O24: =+ROUND(IF(C24=12,PRODUCT(E24,F24,G24,L24),0),2) -> 0 | P24: =+ROUND(IF(C24=16,PRODUCT(E24,F24,G24,L24),0),2) -> 0 | Q24: =+ROUND(IF(C24=20,PRODUCT(E24,F24,G24,L24),0),2) -> 0 | R24: =+ROUND(IF(C24=25,PRODUCT(E24,F24,G24,L24),0),2) -> 0
C25: 10 | D25: 75 | E25: =+E24 -> 4 | F25: 2 | G25: =+ROUND(600/D25,0) -> 8 | I25: =2*(0.2+0.115)+24*0.01 -> 0.87 | L25: =SUM(H25:J25)+K25 -> 0.87 | M25: =+ROUND(IF(C25=8,PRODUCT(E25,F25,G25,L25),0),2) -> 0 | N25: =+ROUND(IF(C25=10,PRODUCT(E25,F25,G25,L25),0),2) -> 55.68 | O25: =+ROUND(IF(C25=12,PRODUCT(E25,F25,G25,L25),0),2) -> 0 | P25: =+ROUND(IF(C25=16,PRODUCT(E25,F25,G25,L25),0),2) -> 0 | Q25: =+ROUND(IF(C25=20,PRODUCT(E25,F25,G25,L25),0),2) -> 0 | R25: =+ROUND(IF(C25=25,PRODUCT(E25,F25,G25,L25),0),2) -> 0
C26: 10 | D26: 75 | E26: =+E25 -> 4 | F26: =2*2 -> 4 | G26: =+ROUND(600/D26,0) -> 8 | I26: =+(0.168+0.168+0.2)+20*0.01 -> 0.736 | L26: =SUM(H26:J26)+K26 -> 0.736 | M26: =+ROUND(IF(C26=8,PRODUCT(E26,F26,G26,L26),0),2) -> 0 | N26: =+ROUND(IF(C26=10,PRODUCT(E26,F26,G26,L26),0),2) -> 94.21 | O26: =+ROUND(IF(C26=12,PRODUCT(E26,F26,G26,L26),0),2) -> 0 | P26: =+ROUND(IF(C26=16,PRODUCT(E26,F26,G26,L26),0),2) -> 0 | Q26: =+ROUND(IF(C26=20,PRODUCT(E26,F26,G26,L26),0),2) -> 0 | R26: =+ROUND(IF(C26=25,PRODUCT(E26,F26,G26,L26),0),2) -> 0
B27: Stirrups ZONE B | C27: 8 | D27: 150 | E27: =+E26 -> 4 | F27: 1 | G27: =+ROUND(450/D27+1,0) -> 4 | I27: =2*(0.204+0.504)+24*0.008 -> 1.608 | L27: =SUM(H27:J27)+K27 -> 1.608 | M27: =+ROUND(IF(C27=8,PRODUCT(E27,F27,G27,L27),0),2) -> 25.73 | N27: =+ROUND(IF(C27=10,PRODUCT(E27,F27,G27,L27),0),2) -> 0 | O27: =+ROUND(IF(C27=12,PRODUCT(E27,F27,G27,L27),0),2) -> 0 | P27: =+ROUND(IF(C27=16,PRODUCT(E27,F27,G27,L27),0),2) -> 0 | Q27: =+ROUND(IF(C27=20,PRODUCT(E27,F27,G27,L27),0),2) -> 0 | R27: =+ROUND(IF(C27=25,PRODUCT(E27,F27,G27,L27),0),2) -> 0
C28: 8 | D28: 150 | E28: =+E27 -> 4 | F28: 1 | G28: =+ROUND(450/D28+1,0) -> 4 | I28: =2*(0.204+0.115)+24*0.008 -> 0.83 | L28: =SUM(H28:J28)+K28 -> 0.83 | M28: =+ROUND(IF(C28=8,PRODUCT(E28,F28,G28,L28),0),2) -> 13.28 | N28: =+ROUND(IF(C28=10,PRODUCT(E28,F28,G28,L28),0),2) -> 0 | O28: =+ROUND(IF(C28=12,PRODUCT(E28,F28,G28,L28),0),2) -> 0 | P28: =+ROUND(IF(C28=16,PRODUCT(E28,F28,G28,L28),0),2) -> 0 | Q28: =+ROUND(IF(C28=20,PRODUCT(E28,F28,G28,L28),0),2) -> 0 | R28: =+ROUND(IF(C28=25,PRODUCT(E28,F28,G28,L28),0),2) -> 0
C29: 8 | D29: 150 | E29: =+E28 -> 4 | F29: 2 | G29: =+ROUND(450/D29+1,0) -> 4 | I29: =+(0.168+0.168+0.204)+20*0.008 -> 0.7 | L29: =SUM(H29:J29)+K29 -> 0.7 | M29: =+ROUND(IF(C29=8,PRODUCT(E29,F29,G29,L29),0),2) -> 22.4 | N29: =+ROUND(IF(C29=10,PRODUCT(E29,F29,G29,L29),0),2) -> 0 | O29: =+ROUND(IF(C29=12,PRODUCT(E29,F29,G29,L29),0),2) -> 0 | P29: =+ROUND(IF(C29=16,PRODUCT(E29,F29,G29,L29),0),2) -> 0 | Q29: =+ROUND(IF(C29=20,PRODUCT(E29,F29,G29,L29),0),2) -> 0 | R29: =+ROUND(IF(C29=25,PRODUCT(E29,F29,G29,L29),0),2) -> 0
B30: C 4 (300X750) | C30: 20 | E30: 16 | F30: 1 | G30: 16 | H30: 0.3 | I30: =100.3-97.06-0.075 -> 3.165 | K30: =40*C30/1000 -> 0.8 | L30: =SUM(H30:J30)+K30 -> 4.265 | M30: =+ROUND(IF(C30=8,PRODUCT(E30,F30,G30,L30),0),2) -> 0 | N30: =+ROUND(IF(C30=10,PRODUCT(E30,F30,G30,L30),0),2) -> 0 | O30: =+ROUND(IF(C30=12,PRODUCT(E30,F30,G30,L30),0),2) -> 0 | P30: =+ROUND(IF(C30=16,PRODUCT(E30,F30,G30,L30),0),2) -> 0 | Q30: =+ROUND(IF(C30=20,PRODUCT(E30,F30,G30,L30),0),2) -> 1091.84 | R30: =+ROUND(IF(C30=25,PRODUCT(E30,F30,G30,L30),0),2) -> 0
B31: Stirrups ZONE A | C31: 10 | D31: 75 | E31: =+E30 -> 16 | F31: 2 | G31: =+ROUND(750/D31,0) -> 10 | I31: =2*(0.2+0.65)+24*0.01 -> 1.94 | L31: =SUM(H31:J31)+K31 -> 1.94 | M31: =+ROUND(IF(C31=8,PRODUCT(E31,F31,G31,L31),0),2) -> 0 | N31: =+ROUND(IF(C31=10,PRODUCT(E31,F31,G31,L31),0),2) -> 620.8 | O31: =+ROUND(IF(C31=12,PRODUCT(E31,F31,G31,L31),0),2) -> 0 | P31: =+ROUND(IF(C31=16,PRODUCT(E31,F31,G31,L31),0),2) -> 0 | Q31: =+ROUND(IF(C31=20,PRODUCT(E31,F31,G31,L31),0),2) -> 0 | R31: =+ROUND(IF(C31=25,PRODUCT(E31,F31,G31,L31),0),2) -> 0
C32: 10 | D32: 75 | E32: =+E31 -> 16 | F32: 2 | G32: =+ROUND(750/D32,0) -> 10 | I32: =2*(0.2+0.23)+24*0.01 -> 1.1 | L32: =SUM(H32:J32)+K32 -> 1.1 | M32: =+ROUND(IF(C32=8,PRODUCT(E32,F32,G32,L32),0),2) -> 0 | N32: =+ROUND(IF(C32=10,PRODUCT(E32,F32,G32,L32),0),2) -> 352 | O32: =+ROUND(IF(C32=12,PRODUCT(E32,F32,G32,L32),0),2) -> 0 | P32: =+ROUND(IF(C32=16,PRODUCT(E32,F32,G32,L32),0),2) -> 0 | Q32: =+ROUND(IF(C32=20,PRODUCT(E32,F32,G32,L32),0),2) -> 0 | R32: =+ROUND(IF(C32=25,PRODUCT(E32,F32,G32,L32),0),2) -> 0
C33: 10 | D33: 75 | E33: =+E32 -> 16 | F33: =2*2 -> 4 | G33: =+ROUND(750/D33,0) -> 10 | I33: =+(0.168+0.168+0.2)+20*0.01 -> 0.736 | L33: =SUM(H33:J33)+K33 -> 0.736 | M33: =+ROUND(IF(C33=8,PRODUCT(E33,F33,G33,L33),0),2) -> 0 | N33: =+ROUND(IF(C33=10,PRODUCT(E33,F33,G33,L33),0),2) -> 471.04 | O33: =+ROUND(IF(C33=12,PRODUCT(E33,F33,G33,L33),0),2) -> 0 | P33: =+ROUND(IF(C33=16,PRODUCT(E33,F33,G33,L33),0),2) -> 0 | Q33: =+ROUND(IF(C33=20,PRODUCT(E33,F33,G33,L33),0),2) -> 0 | R33: =+ROUND(IF(C33=25,PRODUCT(E33,F33,G33,L33),0),2) -> 0
C34: 10 | D34: 75 | E34: =+E33 -> 16 | F34: 2 | G34: =+ROUND(750/D34,0) -> 10 | I34: =0.2+2*10*0.01 -> 0.4 | L34: =SUM(H34:J34)+K34 -> 0.4 | M34: =+ROUND(IF(C34=8,PRODUCT(E34,F34,G34,L34),0),2) -> 0 | N34: =+ROUND(IF(C34=10,PRODUCT(E34,F34,G34,L34),0),2) -> 128 | O34: =+ROUND(IF(C34=12,PRODUCT(E34,F34,G34,L34),0),2) -> 0 | P34: =+ROUND(IF(C34=16,PRODUCT(E34,F34,G34,L34),0),2) -> 0 | Q34: =+ROUND(IF(C34=20,PRODUCT(E34,F34,G34,L34),0),2) -> 0 | R34: =+ROUND(IF(C34=25,PRODUCT(E34,F34,G34,L34),0),2) -> 0
B35: Stirrups ZONE B | C35: 8 | D35: 150 | E35: =+E34 -> 16 | F35: 1 | G35: =+ROUND(150/D35+1,0) -> 2 | I35: =2*(0.204+0.654)+24*0.01 -> 1.956 | L35: =SUM(H35:J35)+K35 -> 1.956 | M35: =+ROUND(IF(C35=8,PRODUCT(E35,F35,G35,L35),0),2) -> 62.59 | N35: =+ROUND(IF(C35=10,PRODUCT(E35,F35,G35,L35),0),2) -> 0 | O35: =+ROUND(IF(C35=12,PRODUCT(E35,F35,G35,L35),0),2) -> 0 | P35: =+ROUND(IF(C35=16,PRODUCT(E35,F35,G35,L35),0),2) -> 0 | Q35: =+ROUND(IF(C35=20,PRODUCT(E35,F35,G35,L35),0),2) -> 0 | R35: =+ROUND(IF(C35=25,PRODUCT(E35,F35,G35,L35),0),2) -> 0
C36: 8 | D36: 150 | E36: =+E35 -> 16 | F36: 1 | G36: =+ROUND(150/D36+1,0) -> 2 | I36: =2*(0.204+0.232)+24*0.01 -> 1.112 | L36: =SUM(H36:J36)+K36 -> 1.112 | M36: =+ROUND(IF(C36=8,PRODUCT(E36,F36,G36,L36),0),2) -> 35.58 | N36: =+ROUND(IF(C36=10,PRODUCT(E36,F36,G36,L36),0),2) -> 0 | O36: =+ROUND(IF(C36=12,PRODUCT(E36,F36,G36,L36),0),2) -> 0 | P36: =+ROUND(IF(C36=16,PRODUCT(E36,F36,G36,L36),0),2) -> 0 | Q36: =+ROUND(IF(C36=20,PRODUCT(E36,F36,G36,L36),0),2) -> 0 | R36: =+ROUND(IF(C36=25,PRODUCT(E36,F36,G36,L36),0),2) -> 0
C37: 8 | D37: 150 | E37: =+E36 -> 16 | F37: 2 | G37: =+ROUND(150/D37+1,0) -> 2 | I37: =+(0.168+0.168+0.204)+20*0.01 -> 0.74 | L37: =SUM(H37:J37)+K37 -> 0.74 | M37: =+ROUND(IF(C37=8,PRODUCT(E37,F37,G37,L37),0),2) -> 47.36 | N37: =+ROUND(IF(C37=10,PRODUCT(E37,F37,G37,L37),0),2) -> 0 | O37: =+ROUND(IF(C37=12,PRODUCT(E37,F37,G37,L37),0),2) -> 0 | P37: =+ROUND(IF(C37=16,PRODUCT(E37,F37,G37,L37),0),2) -> 0 | Q37: =+ROUND(IF(C37=20,PRODUCT(E37,F37,G37,L37),0),2) -> 0 | R37: =+ROUND(IF(C37=25,PRODUCT(E37,F37,G37,L37),0),2) -> 0
C38: 8 | D38: 150 | E38: =+E37 -> 16 | F38: 1 | G38: =+ROUND(150/D38+1,0) -> 2 | I38: =0.204+2*10*0.01 -> 0.404 | L38: =SUM(H38:J38)+K38 -> 0.404 | M38: =+ROUND(IF(C38=8,PRODUCT(E38,F38,G38,L38),0),2) -> 12.93 | N38: =+ROUND(IF(C38=10,PRODUCT(E38,F38,G38,L38),0),2) -> 0 | O38: =+ROUND(IF(C38=12,PRODUCT(E38,F38,G38,L38),0),2) -> 0 | P38: =+ROUND(IF(C38=16,PRODUCT(E38,F38,G38,L38),0),2) -> 0 | Q38: =+ROUND(IF(C38=20,PRODUCT(E38,F38,G38,L38),0),2) -> 0 | R38: =+ROUND(IF(C38=25,PRODUCT(E38,F38,G38,L38),0),2) -> 0
B39: C 5 (300X750) | C39: 20 | E39: 14 | F39: 1 | G39: 4 | H39: 0.3 | I39: =100.3-97.06-0.075 -> 3.165 | K39: =40*C39/1000 -> 0.8 | L39: =SUM(H39:J39)+K39 -> 4.265 | M39: =+ROUND(IF(C39=8,PRODUCT(E39,F39,G39,L39),0),2) -> 0 | N39: =+ROUND(IF(C39=10,PRODUCT(E39,F39,G39,L39),0),2) -> 0 | O39: =+ROUND(IF(C39=12,PRODUCT(E39,F39,G39,L39),0),2) -> 0 | P39: =+ROUND(IF(C39=16,PRODUCT(E39,F39,G39,L39),0),2) -> 0 | Q39: =+ROUND(IF(C39=20,PRODUCT(E39,F39,G39,L39),0),2) -> 238.84 | R39: =+ROUND(IF(C39=25,PRODUCT(E39,F39,G39,L39),0),2) -> 0
C40: 16 | E40: =+E39 -> 14 | F40: 1 | G40: 12 | H40: 0.3 | I40: =100.3-97.06-0.075 -> 3.165 | K40: =40*C40/1000 -> 0.64 | L40: =SUM(H40:J40)+K40 -> 4.105 | M40: =+ROUND(IF(C40=8,PRODUCT(E40,F40,G40,L40),0),2) -> 0 | N40: =+ROUND(IF(C40=10,PRODUCT(E40,F40,G40,L40),0),2) -> 0 | O40: =+ROUND(IF(C40=12,PRODUCT(E40,F40,G40,L40),0),2) -> 0 | P40: =+ROUND(IF(C40=16,PRODUCT(E40,F40,G40,L40),0),2) -> 689.64 | Q40: =+ROUND(IF(C40=20,PRODUCT(E40,F40,G40,L40),0),2) -> 0 | R40: =+ROUND(IF(C40=25,PRODUCT(E40,F40,G40,L40),0),2) -> 0
B41: Stirrups ZONE A | C41: 10 | D41: 75 | E41: =+E40 -> 14 | F41: 2 | G41: =+ROUND(750/D41,0) -> 10 | I41: =2*(0.2+0.65)+24*0.01 -> 1.94 | L41: =SUM(H41:J41)+K41 -> 1.94 | M41: =+ROUND(IF(C41=8,PRODUCT(E41,F41,G41,L41),0),2) -> 0 | N41: =+ROUND(IF(C41=10,PRODUCT(E41,F41,G41,L41),0),2) -> 543.2 | O41: =+ROUND(IF(C41=12,PRODUCT(E41,F41,G41,L41),0),2) -> 0 | P41: =+ROUND(IF(C41=16,PRODUCT(E41,F41,G41,L41),0),2) -> 0 | Q41: =+ROUND(IF(C41=20,PRODUCT(E41,F41,G41,L41),0),2) -> 0 | R41: =+ROUND(IF(C41=25,PRODUCT(E41,F41,G41,L41),0),2) -> 0
...

Sheet Typical floor STEEL
A1: Reinforcement
A2: Sr. No. | B2: Designation | C2: Dia | D2: C/C (mm) | E2: No | F2: No | G2: No of Bars | H2: Bar Length (mtr) | K2: Lap Length | L2: One Bar Length (MTR) | M2: Dia Wise Weight (Kg)
H3: a | I3: b | J3: c | M3: 8mm | N3: 10mm | O3: 12mm | P3: 16mm | Q3: 20MM | R3: 25mm
B4: Typical Beam
A5: 200X500 | B5: B1 | L5: =SUM(H5:J5)+K5 -> 0 | M5: =+ROUND(IF(C5=8,PRODUCT(E5,F5,G5,L5),0),2) -> 0 | N5: =+ROUND(IF(C5=10,PRODUCT(E5,F5,G5,L5),0),2) -> 0 | O5: =+ROUND(IF(C5=12,PRODUCT(E5,F5,G5,L5),0),2) -> 0 | P5: =+ROUND(IF(C5=16,PRODUCT(E5,F5,G5,L5),0),2) -> 0 | Q5: =+ROUND(IF(C5=20,PRODUCT(E5,F5,G5,L5),0),2) -> 0 | R5: =+ROUND(IF(C5=25,PRODUCT(E5,F5,G5,L5),0),2) -> 0
B6: BOTTOM | C6: 16 | E6: 2 | F6: 1 | G6: 2 | H6: =0.58+8*$C6/1000 -> 0.708 | I6: =6.125 -> 6.125 | J6: =0.58+8*$C6/1000 -> 0.708 | L6: =SUM(H6:J6)+K6 -> 7.541 | M6: =+ROUND(IF(C6=8,PRODUCT(E6,F6,G6,L6),0),2) -> 0 | N6: =+ROUND(IF(C6=10,PRODUCT(E6,F6,G6,L6),0),2) -> 0 | O6: =+ROUND(IF(C6=12,PRODUCT(E6,F6,G6,L6),0),2) -> 0 | P6: =+ROUND(IF(C6=16,PRODUCT(E6,F6,G6,L6),0),2) -> 30.16 | Q6: =+ROUND(IF(C6=20,PRODUCT(E6,F6,G6,L6),0),2) -> 0 | R6: =+ROUND(IF(C6=25,PRODUCT(E6,F6,G6,L6),0),2) -> 0
B7: TOP | C7: 20 | E7: 2 | F7: 1 | G7: 2 | H7: =0.72+8*$C7/1000 -> 0.88 | I7: =6.125 -> 6.125 | J7: =0.72+8*$C7/1000 -> 0.88 | L7: =SUM(H7:J7)+K7 -> 7.885 | M7: =+ROUND(IF(C7=8,PRODUCT(E7,F7,G7,L7),0),2) -> 0 | N7: =+ROUND(IF(C7=10,PRODUCT(E7,F7,G7,L7),0),2) -> 0 | O7: =+ROUND(IF(C7=12,PRODUCT(E7,F7,G7,L7),0),2) -> 0 | P7: =+ROUND(IF(C7=16,PRODUCT(E7,F7,G7,L7),0),2) -> 0 | Q7: =+ROUND(IF(C7=20,PRODUCT(E7,F7,G7,L7),0),2) -> 31.54 | R7: =+ROUND(IF(C7=25,PRODUCT(E7,F7,G7,L7),0),2) -> 0
B8: TOP EXTRA | C8: 12 | E8: 2 | F8: 1 | G8: 2 | H8: =0.44+8*$C8/1000 -> 0.536 | I8: 0.85 | L8: =SUM(H8:J8)+K8 -> 1.386 | M8: =+ROUND(IF(C8=8,PRODUCT(E8,F8,G8,L8),0),2) -> 0 | N8: =+ROUND(IF(C8=10,PRODUCT(E8,F8,G8,L8),0),2) -> 0 | O8: =+ROUND(IF(C8=12,PRODUCT(E8,F8,G8,L8),0),2) -> 5.54 | P8: =+ROUND(IF(C8=16,PRODUCT(E8,F8,G8,L8),0),2) -> 0 | Q8: =+ROUND(IF(C8=20,PRODUCT(E8,F8,G8,L8),0),2) -> 0 | R8: =+ROUND(IF(C8=25,PRODUCT(E8,F8,G8,L8),0),2) -> 0
B9: STIRRUPS | C9: 8 | D9: 100 | E9: 2 | F9: 1 | G9: =+ROUND(2/0.1,0) -> 20 | I9: =2*(0.15+0.45)+16*C9/1000 -> 1.328 | L9: =SUM(H9:J9)+K9 -> 1.328 | M9: =+ROUND(IF(C9=8,PRODUCT(E9,F9,G9,L9),0),2) -> 53.12 | N9: =+ROUND(IF(C9=10,PRODUCT(E9,F9,G9,L9),0),2) -> 0 | O9: =+ROUND(IF(C9=12,PRODUCT(E9,F9,G9,L9),0),2) -> 0 | P9: =+ROUND(IF(C9=16,PRODUCT(E9,F9,G9,L9),0),2) -> 0 | Q9: =+ROUND(IF(C9=20,PRODUCT(E9,F9,G9,L9),0),2) -> 0 | R9: =+ROUND(IF(C9=25,PRODUCT(E9,F9,G9,L9),0),2) -> 0
C10: 8 | D10: 150 | E10: 2 | F10: 1 | G10: =+ROUND(1.025/0.15+1,0) -> 8 | I10: =2*(0.15+0.45)+16*C10/1000 -> 1.328 | L10: =SUM(H10:J10)+K10 -> 1.328 | M10: =+ROUND(IF(C10=8,PRODUCT(E10,F10,G10,L10),0),2) -> 21.25 | N10: =+ROUND(IF(C10=10,PRODUCT(E10,F10,G10,L10),0),2) -> 0 | O10: =+ROUND(IF(C10=12,PRODUCT(E10,F10,G10,L10),0),2) -> 0 | P10: =+ROUND(IF(C10=16,PRODUCT(E10,F10,G10,L10),0),2) -> 0 | Q10: =+ROUND(IF(C10=20,PRODUCT(E10,F10,G10,L10),0),2) -> 0 | R10: =+ROUND(IF(C10=25,PRODUCT(E10,F10,G10,L10),0),2) -> 0
B11: STIRRUPS | C11: 8 | D11: 100 | E11: 2 | F11: 1 | G11: =+ROUND(2/0.1,0) -> 20 | I11: =2*(0.15+0.45)+16*C11/1000 -> 1.328 | L11: =SUM(H11:J11)+K11 -> 1.328 | M11: =+ROUND(IF(C11=8,PRODUCT(E11,F11,G11,L11),0),2) -> 53.12 | N11: =+ROUND(IF(C11=10,PRODUCT(E11,F11,G11,L11),0),2) -> 0 | O11: =+ROUND(IF(C11=12,PRODUCT(E11,F11,G11,L11),0),2) -> 0 | P11: =+ROUND(IF(C11=16,PRODUCT(E11,F11,G11,L11),0),2) -> 0 | Q11: =+ROUND(IF(C11=20,PRODUCT(E11,F11,G11,L11),0),2) -> 0 | R11: =+ROUND(IF(C11=25,PRODUCT(E11,F11,G11,L11),0),2) -> 0
C12: 8 | D12: 150 | E12: 2 | F12: 1 | G12: =+ROUND(0.8/0.15+1,0) -> 6 | I12: =2*(0.15+0.45)+16*C12/1000 -> 1.328 | L12: =SUM(H12:J12)+K12 -> 1.328 | M12: =+ROUND(IF(C12=8,PRODUCT(E12,F12,G12,L12),0),2) -> 15.94 | N12: =+ROUND(IF(C12=10,PRODUCT(E12,F12,G12,L12),0),2) -> 0 | O12: =+ROUND(IF(C12=12,PRODUCT(E12,F12,G12,L12),0),2) -> 0 | P12: =+ROUND(IF(C12=16,PRODUCT(E12,F12,G12,L12),0),2) -> 0 | Q12: =+ROUND(IF(C12=20,PRODUCT(E12,F12,G12,L12),0),2) -> 0 | R12: =+ROUND(IF(C12=25,PRODUCT(E12,F12,G12,L12),0),2) -> 0
A13: 200X500 | B13: B2 | L13: =SUM(H13:J13)+K13 -> 0 | M13: =+ROUND(IF(C13=8,PRODUCT(E13,F13,G13,L13),0),2) -> 0 | N13: =+ROUND(IF(C13=10,PRODUCT(E13,F13,G13,L13),0),2) -> 0 | O13: =+ROUND(IF(C13=12,PRODUCT(E13,F13,G13,L13),0),2) -> 0 | P13: =+ROUND(IF(C13=16,PRODUCT(E13,F13,G13,L13),0),2) -> 0 | Q13: =+ROUND(IF(C13=20,PRODUCT(E13,F13,G13,L13),0),2) -> 0 | R13: =+ROUND(IF(C13=25,PRODUCT(E13,F13,G13,L13),0),2) -> 0
B14: BOTTOM | C14: 16 | E14: 2 | F14: 1 | G14: 2 | H14: =0.58+8*$C14/1000 -> 0.708 | I14: 3.3 | J14: =((0.79)/3)+0.1 -> 0.36333333 | L14: =SUM(H14:J14)+K14 -> 4.3713333 | M14: =+ROUND(IF(C14=8,PRODUCT(E14,F14,G14,L14),0),2) -> 0 | N14: =+ROUND(IF(C14=10,PRODUCT(E14,F14,G14,L14),0),2) -> 0 | O14: =+ROUND(IF(C14=12,PRODUCT(E14,F14,G14,L14),0),2) -> 0 | P14: =+ROUND(IF(C14=16,PRODUCT(E14,F14,G14,L14),0),2) -> 17.49 | Q14: =+ROUND(IF(C14=20,PRODUCT(E14,F14,G14,L14),0),2) -> 0 | R14: =+ROUND(IF(C14=25,PRODUCT(E14,F14,G14,L14),0),2) -> 0
B15: TOP | C15: 20 | E15: 2 | F15: 1 | G15: 2 | H15: =0.72+8*$C15/1000 -> 0.88 | I15: 3.3 | J15: =((0.98)/3)+0.1 -> 0.42666667 | L15: =SUM(H15:J15)+K15 -> 4.6066667 | M15: =+ROUND(IF(C15=8,PRODUCT(E15,F15,G15,L15),0),2) -> 0 | N15: =+ROUND(IF(C15=10,PRODUCT(E15,F15,G15,L15),0),2) -> 0 | O15: =+ROUND(IF(C15=12,PRODUCT(E15,F15,G15,L15),0),2) -> 0 | P15: =+ROUND(IF(C15=16,PRODUCT(E15,F15,G15,L15),0),2) -> 0 | Q15: =+ROUND(IF(C15=20,PRODUCT(E15,F15,G15,L15),0),2) -> 18.43 | R15: =+ROUND(IF(C15=25,PRODUCT(E15,F15,G15,L15),0),2) -> 0
B16: STIRRUPS | C16: 8 | D16: 100 | E16: 2 | F16: 1 | G16: =+ROUND(2/0.1,0) -> 20 | I16: =2*(0.15+0.45)+16*C16/1000 -> 1.328 | L16: =SUM(H16:J16)+K16 -> 1.328 | M16: =+ROUND(IF(C16=8,PRODUCT(E16,F16,G16,L16),0),2) -> 53.12 | N16: =+ROUND(IF(C16=10,PRODUCT(E16,F16,G16,L16),0),2) -> 0 | O16: =+ROUND(IF(C16=12,PRODUCT(E16,F16,G16,L16),0),2) -> 0 | P16: =+ROUND(IF(C16=16,PRODUCT(E16,F16,G16,L16),0),2) -> 0 | Q16: =+ROUND(IF(C16=20,PRODUCT(E16,F16,G16,L16),0),2) -> 0 | R16: =+ROUND(IF(C16=25,PRODUCT(E16,F16,G16,L16),0),2) -> 0
C17: 8 | D17: 150 | E17: 2 | F17: 1 | G17: =+ROUND(1.3/0.15+1,0) -> 10 | I17: =2*(0.15+0.45)+16*C17/1000 -> 1.328 | L17: =SUM(H17:J17)+K17 -> 1.328 | M17: =+ROUND(IF(C17=8,PRODUCT(E17,F17,G17,L17),0),2) -> 26.56 | N17: =+ROUND(IF(C17=10,PRODUCT(E17,F17,G17,L17),0),2) -> 0 | O17: =+ROUND(IF(C17=12,PRODUCT(E17,F17,G17,L17),0),2) -> 0 | P17: =+ROUND(IF(C17=16,PRODUCT(E17,F17,G17,L17),0),2) -> 0 | Q17: =+ROUND(IF(C17=20,PRODUCT(E17,F17,G17,L17),0),2) -> 0 | R17: =+ROUND(IF(C17=25,PRODUCT(E17,F17,G17,L17),0),2) -> 0
A18: 100X350 | B18: B3 | L18: =SUM(H18:J18)+K18 -> 0 | M18: =+ROUND(IF(C18=8,PRODUCT(E18,F18,G18,L18),0),2) -> 0 | N18: =+ROUND(IF(C18=10,PRODUCT(E18,F18,G18,L18),0),2) -> 0 | O18: =+ROUND(IF(C18=12,PRODUCT(E18,F18,G18,L18),0),2) -> 0 | P18: =+ROUND(IF(C18=16,PRODUCT(E18,F18,G18,L18),0),2) -> 0 | Q18: =+ROUND(IF(C18=20,PRODUCT(E18,F18,G18,L18),0),2) -> 0 | R18: =+ROUND(IF(C18=25,PRODUCT(E18,F18,G18,L18),0),2) -> 0
B19: BOTTOM | C19: 12 | E19: 2 | F19: 1 | G19: 2 | H19: =0.36+8*$C19/1000 -> 0.456 | I19: 1.395 | J19: =0.36+8*$C19/1000 -> 0.456 | L19: =SUM(H19:J19)+K19 -> 2.307 | M19: =+ROUND(IF(C19=8,PRODUCT(E19,F19,G19,L19),0),2) -> 0 | N19: =+ROUND(IF(C19=10,PRODUCT(E19,F19,G19,L19),0),2) -> 0 | O19: =+ROUND(IF(C19=12,PRODUCT(E19,F19,G19,L19),0),2) -> 9.23 | P19: =+ROUND(IF(C19=16,PRODUCT(E19,F19,G19,L19),0),2) -> 0 | Q19: =+ROUND(IF(C19=20,PRODUCT(E19,F19,G19,L19),0),2) -> 0 | R19: =+ROUND(IF(C19=25,PRODUCT(E19,F19,G19,L19),0),2) -> 0
B20: TOP | C20: 12 | E20: 2 | F20: 1 | G20: 2 | H20: =0.36+8*$C20/1000 -> 0.456 | I20: 1.395 | J20: =0.36+8*$C20/1000 -> 0.456 | L20: =SUM(H20:J20)+K20 -> 2.307 | M20: =+ROUND(IF(C20=8,PRODUCT(E20,F20,G20,L20),0),2) -> 0 | N20: =+ROUND(IF(C20=10,PRODUCT(E20,F20,G20,L20),0),2) -> 0 | O20: =+ROUND(IF(C20=12,PRODUCT(E20,F20,G20,L20),0),2) -> 9.23 | P20: =+ROUND(IF(C20=16,PRODUCT(E20,F20,G20,L20),0),2) -> 0 | Q20: =+ROUND(IF(C20=20,PRODUCT(E20,F20,G20,L20),0),2) -> 0 | R20: =+ROUND(IF(C20=25,PRODUCT(E20,F20,G20,L20),0),2) -> 0
B21: STIRRUPS | C21: 8 | D21: 150 | E21: 2 | F21: 1 | G21: =+ROUND(1.395/0.15+1,0) -> 10 | I21: =2*(0.05+0.3)+16*C21/1000 -> 0.828 | L21: =SUM(H21:J21)+K21 -> 0.828 | M21: =+ROUND(IF(C21=8,PRODUCT(E21,F21,G21,L21),0),2) -> 16.56 | N21: =+ROUND(IF(C21=10,PRODUCT(E21,F21,G21,L21),0),2) -> 0 | O21: =+ROUND(IF(C21=12,PRODUCT(E21,F21,G21,L21),0),2) -> 0 | P21: =+ROUND(IF(C21=16,PRODUCT(E21,F21,G21,L21),0),2) -> 0 | Q21: =+ROUND(IF(C21=20,PRODUCT(E21,F21,G21,L21),0),2) -> 0 | R21: =+ROUND(IF(C21=25,PRODUCT(E21,F21,G21,L21),0),2) -> 0
A23: 200X350 | B23: B4 | L23: =SUM(H23:J23)+K23 -> 0 | M23: =+ROUND(IF(C23=8,PRODUCT(E23,F23,G23,L23),0),2) -> 0 | N23: =+ROUND(IF(C23=10,PRODUCT(E23,F23,G23,L23),0),2) -> 0 | O23: =+ROUND(IF(C23=12,PRODUCT(E23,F23,G23,L23),0),2) -> 0 | P23: =+ROUND(IF(C23=16,PRODUCT(E23,F23,G23,L23),0),2) -> 0 | Q23: =+ROUND(IF(C23=20,PRODUCT(E23,F23,G23,L23),0),2) -> 0 | R23: =+ROUND(IF(C23=25,PRODUCT(E23,F23,G23,L23),0),2) -> 0
B24: BOTTOM | C24: 16 | E24: 4 | F24: 1 | G24: 2 | H24: =0.58+8*$C24/1000 -> 0.708 | I24: 1.395 | J24: =0.58+8*$C24/1000 -> 0.708 | L24: =SUM(H24:J24)+K24 -> 2.811 | M24: =+ROUND(IF(C24=8,PRODUCT(E24,F24,G24,L24),0),2) -> 0 | N24: =+ROUND(IF(C24=10,PRODUCT(E24,F24,G24,L24),0),2) -> 0 | O24: =+ROUND(IF(C24=12,PRODUCT(E24,F24,G24,L24),0),2) -> 0 | P24: =+ROUND(IF(C24=16,PRODUCT(E24,F24,G24,L24),0),2) -> 22.49 | Q24: =+ROUND(IF(C24=20,PRODUCT(E24,F24,G24,L24),0),2) -> 0 | R24: =+ROUND(IF(C24=25,PRODUCT(E24,F24,G24,L24),0),2) -> 0
B25: TOP | C25: 16 | E25: 4 | F25: 1 | G25: 2 | H25: =0.58+8*$C25/1000 -> 0.708 | I25: 1.395 | J25: =0.58+8*$C25/1000 -> 0.708 | L25: =SUM(H25:J25)+K25 -> 2.811 | M25: =+ROUND(IF(C25=8,PRODUCT(E25,F25,G25,L25),0),2) -> 0 | N25: =+ROUND(IF(C25=10,PRODUCT(E25,F25,G25,L25),0),2) -> 0 | O25: =+ROUND(IF(C25=12,PRODUCT(E25,F25,G25,L25),0),2) -> 0 | P25: =+ROUND(IF(C25=16,PRODUCT(E25,F25,G25,L25),0),2) -> 22.49 | Q25: =+ROUND(IF(C25=20,PRODUCT(E25,F25,G25,L25),0),2) -> 0 | R25: =+ROUND(IF(C25=25,PRODUCT(E25,F25,G25,L25),0),2) -> 0
B26: STIRRUPS | C26: 8 | D26: 100 | E26: 4 | F26: 1 | G26: =+ROUND(1.395/0.1+1,0) -> 15 | I26: =2*(0.15+0.3)+16*C26/1000 -> 1.028 | L26: =SUM(H26:J26)+K26 -> 1.028 | M26: =+ROUND(IF(C26=8,PRODUCT(E26,F26,G26,L26),0),2) -> 61.68 | N26: =+ROUND(IF(C26=10,PRODUCT(E26,F26,G26,L26),0),2) -> 0 | O26: =+ROUND(IF(C26=12,PRODUCT(E26,F26,G26,L26),0),2) -> 0 | P26: =+ROUND(IF(C26=16,PRODUCT(E26,F26,G26,L26),0),2) -> 0 | Q26: =+ROUND(IF(C26=20,PRODUCT(E26,F26,G26,L26),0),2) -> 0 | R26: =+ROUND(IF(C26=25,PRODUCT(E26,F26,G26,L26),0),2) -> 0
A27: 200X450 | B27: B5 | L27: =SUM(H27:J27)+K27 -> 0 | M27: =+ROUND(IF(C27=8,PRODUCT(E27,F27,G27,L27),0),2) -> 0 | N27: =+ROUND(IF(C27=10,PRODUCT(E27,F27,G27,L27),0),2) -> 0 | O27: =+ROUND(IF(C27=12,PRODUCT(E27,F27,G27,L27),0),2) -> 0 | P27: =+ROUND(IF(C27=16,PRODUCT(E27,F27,G27,L27),0),2) -> 0 | Q27: =+ROUND(IF(C27=20,PRODUCT(E27,F27,G27,L27),0),2) -> 0 | R27: =+ROUND(IF(C27=25,PRODUCT(E27,F27,G27,L27),0),2) -> 0
B28: BOTTOM | C28: 16 | E28: 2 | F28: 1 | G28: 2 | H28: =0.58+8*$C28/1000 -> 0.708 | I28: 6.875 | J28: =((0.79)/3)+0.1 -> 0.36333333 | L28: =SUM(H28:J28)+K28 -> 7.9463333 | M28: =+ROUND(IF(C28=8,PRODUCT(E28,F28,G28,L28),0),2) -> 0 | N28: =+ROUND(IF(C28=10,PRODUCT(E28,F28,G28,L28),0),2) -> 0 | O28: =+ROUND(IF(C28=12,PRODUCT(E28,F28,G28,L28),0),2) -> 0 | P28: =+ROUND(IF(C28=16,PRODUCT(E28,F28,G28,L28),0),2) -> 31.79 | Q28: =+ROUND(IF(C28=20,PRODUCT(E28,F28,G28,L28),0),2) -> 0 | R28: =+ROUND(IF(C28=25,PRODUCT(E28,F28,G28,L28),0),2) -> 0
B29: TOP | C29: 16 | E29: 2 | F29: 1 | G29: 2 | H29: =0.58+8*$C29/1000 -> 0.708 | I29: 6.875 | J29: =((0.79)/3)+0.1 -> 0.36333333 | L29: =SUM(H29:J29)+K29 -> 7.9463333 | M29: =+ROUND(IF(C29=8,PRODUCT(E29,F29,G29,L29),0),2) -> 0 | N29: =+ROUND(IF(C29=10,PRODUCT(E29,F29,G29,L29),0),2) -> 0 | O29: =+ROUND(IF(C29=12,PRODUCT(E29,F29,G29,L29),0),2) -> 0 | P29: =+ROUND(IF(C29=16,PRODUCT(E29,F29,G29,L29),0),2) -> 31.79 | Q29: =+ROUND(IF(C29=20,PRODUCT(E29,F29,G29,L29),0),2) -> 0 | R29: =+ROUND(IF(C29=25,PRODUCT(E29,F29,G29,L29),0),2) -> 0
B30: STIRRUPS | C30: 8 | D30: 100 | E30: 2 | F30: 1 | G30: =+ROUND(1.8/0.1,0) -> 18 | I30: =2*(0.15+0.4)+16*C30/1000 -> 1.228 | L30: =SUM(H30:J30)+K30 -> 1.228 | M30: =+ROUND(IF(C30=8,PRODUCT(E30,F30,G30,L30),0),2) -> 44.21 | N30: =+ROUND(IF(C30=10,PRODUCT(E30,F30,G30,L30),0),2) -> 0 | O30: =+ROUND(IF(C30=12,PRODUCT(E30,F30,G30,L30),0),2) -> 0 | P30: =+ROUND(IF(C30=16,PRODUCT(E30,F30,G30,L30),0),2) -> 0 | Q30: =+ROUND(IF(C30=20,PRODUCT(E30,F30,G30,L30),0),2) -> 0 | R30: =+ROUND(IF(C30=25,PRODUCT(E30,F30,G30,L30),0),2) -> 0
C31: 8 | D31: 150 | E31: 2 | F31: 1 | G31: =+ROUND(1.775/0.15+1,0) -> 13 | I31: =2*(0.15+0.4)+16*C31/1000 -> 1.228 | L31: =SUM(H31:J31)+K31 -> 1.228 | M31: =+ROUND(IF(C31=8,PRODUCT(E31,F31,G31,L31),0),2) -> 31.93 | N31: =+ROUND(IF(C31=10,PRODUCT(E31,F31,G31,L31),0),2) -> 0 | O31: =+ROUND(IF(C31=12,PRODUCT(E31,F31,G31,L31),0),2) -> 0 | P31: =+ROUND(IF(C31=16,PRODUCT(E31,F31,G31,L31),0),2) -> 0 | Q31: =+ROUND(IF(C31=20,PRODUCT(E31,F31,G31,L31),0),2) -> 0 | R31: =+ROUND(IF(C31=25,PRODUCT(E31,F31,G31,L31),0),2) -> 0
B32: STIRRUPS | C32: 8 | D32: 100 | E32: 2 | F32: 1 | G32: =+ROUND(1.8/0.1,0) -> 18 | I32: =2*(0.15+0.4)+16*C32/1000 -> 1.228 | L32: =SUM(H32:J32)+K32 -> 1.228 | M32: =+ROUND(IF(C32=8,PRODUCT(E32,F32,G32,L32),0),2) -> 44.21 | N32: =+ROUND(IF(C32=10,PRODUCT(E32,F32,G32,L32),0),2) -> 0 | O32: =+ROUND(IF(C32=12,PRODUCT(E32,F32,G32,L32),0),2) -> 0 | P32: =+ROUND(IF(C32=16,PRODUCT(E32,F32,G32,L32),0),2) -> 0 | Q32: =+ROUND(IF(C32=20,PRODUCT(E32,F32,G32,L32),0),2) -> 0 | R32: =+ROUND(IF(C32=25,PRODUCT(E32,F32,G32,L32),0),2) -> 0
C33: 8 | D33: 150 | E33: 2 | F33: 1 | G33: =+ROUND(1.3/0.15+1,0) -> 10 | I33: =2*(0.15+0.4)+16*C33/1000 -> 1.228 | L33: =SUM(H33:J33)+K33 -> 1.228 | M33: =+ROUND(IF(C33=8,PRODUCT(E33,F33,G33,L33),0),2) -> 24.56 | N33: =+ROUND(IF(C33=10,PRODUCT(E33,F33,G33,L33),0),2) -> 0 | O33: =+ROUND(IF(C33=12,PRODUCT(E33,F33,G33,L33),0),2) -> 0 | P33: =+ROUND(IF(C33=16,PRODUCT(E33,F33,G33,L33),0),2) -> 0 | Q33: =+ROUND(IF(C33=20,PRODUCT(E33,F33,G33,L33),0),2) -> 0 | R33: =+ROUND(IF(C33=25,PRODUCT(E33,F33,G33,L33),0),2) -> 0
