Workbook
Name \0: #REF!
Name \0: #REF!
Name \B: #REF!
Name \B: #REF!
Name \C: #REF!
Name \C: #REF!
Name \G: #REF!
Name \I: #REF!
Name \M: #REF!
Name \O: #REF!
Name \P: #REF!
Name \Q: #REF!
Name \R: #REF!
Name \S: #REF!
Name __aoc10: #N/A
Name __aoc11: #REF!
Name __aoc11: #REF!
Name __aoc11: #REF!
Name __aoc7: #REF!
Name __aoc7: #REF!
Name __aoc7: #REF!
Name __aoc8: #REF!
Name __aoc8: #REF!
Name __aoc9: #REF!
Name __aoc9: #REF!
Name __ERA1: #REF!
Name __ERA1: #REF!
Name __ERA10: #REF!
Name __ERA10: #REF!
Name __ERA11: #REF!
Name __ERA11: #REF!
Name __ERA2: #REF!
Name __ERA3: #REF!
Name __ERA5: #REF!
Name __ERA5: #REF!
Name __ERA9: #REF!
Name __ERA9: #REF!
Name __HED1: #REF!
Name __HED1: #REF!
Name __HED2: #REF!
Name __HED2: #REF!
Name __vut02533: #REF!
Name __vut02533: #REF!
Name __vut02533: #REF!
Name __xlnm.Print_Area: "$#REF!.$A$2:$I$161"
Name __xlnm.Print_Area_1: #REF!
Name __xlnm.Print_Area_1: #REF!
Name __xlnm.Print_Area_1: #REF!
Name __xlnm.Print_Area_10: #REF!
Name __xlnm.Print_Area_10: #REF!
Name __xlnm.Print_Area_11: #REF!
Name __xlnm.Print_Area_11: #REF!
Name __xlnm.Print_Area_12: #REF!
Name __xlnm.Print_Area_12: #REF!
Name __xlnm.Print_Area_13: #REF!
Name __xlnm.Print_Area_13: #REF!
Name __xlnm.Print_Area_14: #REF!
Name __xlnm.Print_Area_14: #REF!
Name __xlnm.Print_Area_15: #REF!
Name __xlnm.Print_Area_15: #REF!

Sheet TOP SHEET
A1: OMAXE LTD. | F1: Tracker NO | G1: Office NO
A2: NAME OF PROJECT : OMAXE ANANDA TOWER-E (Location: Tower-E STILT + 14 FLOORS) | E2: CONTRACT VALUE ; | G2: =+ABSTRACT!F109 -> 162074375
A3: NATURE OF WORK : CIVIL STRUCTURE WORK | E3: PROGRESS OF WORK: | G3: =D11/G2 -> 0.11625374
A4: NAME OF THE CONTRACTOR :- M/s MARCO-ENTERPRISES | E4: VENDOR CODE:
A5: WORK ORDER NO. & DATE : OPRL/ATE/11094106758 (14 FEB, 2025) | E5: DATE OF START: 01.MAY.2025
A6: THIS R/A BILL NO. & DATE : 8TH RA BILL, DATE 12-02-2026 | E6: COMPLETION PERIOD : Upto 31-Aug-2026 (18 Months)
A7: PERIOD OF BILL :- FROM 01-02-2026 TO 12-02-2026 | E7: GST No. : 09BLDPK5228HIZ2
A8: ERP PROJECT CODE : 127018 | E8: PAN NO. : BLDPK5228H
A9: DATE OF BILL REC. AT SITE :- | C9: DATE OF BILL RECEIVED AT H.O. :- | E9: DATE OF BILL CHECKING AT H.O. :-
A10: S.NO. | B10: PARTICULARS | C10: CLAIMED BY CONTRACTOR | D10: GROSS AMT | E10: PREVIOUS AMT. | F10: THIS BILL AMT | G10: REMARKS
A11: 1 | B11: WORK DONE(CIVIL) | D11: =ABSTRACT!M109 -> 18841753 | E11: 16826127 | F11: =+D11-E11 -> 2015626
A12: 2 | B12: WORK DONE(ELECT/ PLUMBING)
A13: 3 | B13: DIFF. OF CEMENT
A14: 4 | B14: RATE DIFF OF TILES
B15: TOTAL (A) | D15: =SUM(D11:D14) -> 18841753 | E15: =SUM(E11:E14) -> 16826127 | F15: =SUM(F11:F14) -> 2015626
A16: 5 | B16: Add GST 18% On (A) | D16: =D15*18% -> 3391515.5 | E16: =E15*18% -> 3028702.8 | F16: =F15*18% -> 362812.67
B17: TOTAL (B) | D17: =D16+D15 -> 22233268 | E17: =E16+E15 -> 19854830 | F17: =F16+F15 -> 2378438.6
B18: ADVANCES
A21: 7.1 | B21: Add Mobilization Advance | D21: =+F21+E21 -> 6000000 | E21: 6000000
A22: 7.2 | B22: Recover Mobilization Advance | D22: =-(E21*G3)/80% -> -871903.07 | E22: -778629.88 | F22: =+D22-E22 -> -93273.194
B23: TOTAL (C) | D23: =SUM(D17:D22) -> 27361365 | E23: =SUM(E17:E22) -> 25076200 | F23: =SUM(F17:F22) -> 2285165.4
B24: DEDUCTIONS
A25: 8 | B25: SECURITY @ 5 % (ON TOTAL A) | D25: =ROUND(D15*5%,0) -> 942088 | E25: =ROUND(E15*5%,0) -> 841306 | F25: =ROUND(F15*5%,0) -> 100781
A26: 9 | B26: TDS @ 1% (ON TOTAL A) | D26: =ROUND((D15+D19+D20+D21+D22)*1%,0) -> 239698 | E26: =ROUND((E15+E19+E20+E21+E22)*1%,0) -> 220475 | F26: =+D26-E26 -> 19223
B27: TOTAL DEDUCTION (C) | D27: =SUM(D25:D26) -> 1181786 | E27: =SUM(E25:E26) -> 1061781 | F27: =SUM(F25:F26) -> 120004
A28: 11 | B28: NET PAYABLE AMOUNT (D) | D28: =D23-D27 -> 26179579 | E28: =E23-E27 -> 24014419 | F28: =F23-F27 -> 2165161.4
B29: NOW PAYABLE | F29: =F28 -> 2165161.4
B30: PREPARED BY
C31: PRIYANK BARANWAL
C32: MANAGER (BILLING)
C33: 9988294677
B34: ACCOUNT (SITE) | E34: PREVIOUS RA BILL NO:-
C35: ANUP SINGH | E35: PREVIOUS RA GROSS AMOUNT:-
C36: DY. MANAGER
C37: 9315403180
B38: PROJECT INCHARGE {CPC/PC/ASST V.P./SR GM /GM}
E39: S K PANDEY
E40: G.M. - PROJECT
E41: 9711800470
B42: HO BILL MONITORING
...

Sheet ABSTRACT
A1: OMAXE PANCHAM REALCON PVT. LTD.
B2: =+'TOP SHEET'!A5 -> WORK ORDER NO. & DATE : OPRL/ATE/11094106758 (14 FEB, 2025) | J2: =+'TOP SHEET'!A8 -> ERP PROJECT CODE : 127018
B3: =+'TOP SHEET'!A6 -> THIS R/A BILL NO. & DATE : 8TH RA BILL, DATE 12-02-2026 | J3: =+'TOP SHEET'!A9 -> DATE OF BILL REC. AT SITE :-
B4: =+'TOP SHEET'!A3 -> NATURE OF WORK : CIVIL STRUCTURE WORK | J4: =+'TOP SHEET'!A7 -> PERIOD OF BILL :- FROM 01-02-2026 TO 12-02-2026
A5: ABSTRACT OF COST
A6: S.No. | B6: DESCRIPTION OF ITEM | C6: Unit | D6: AS PER W.O. (R0) | H6: Qty | K6: Amount | N6: Executed %
D7: Qty | E7: Rate | F7: Amount | G7: Part Rate | H7: Prev. Bill | I7: This Bill | J7: UpTo Date | K7: Prev. Bill | L7: This Bill | M7: UpTo Date
A8: 1 | B8: EARTH WORK
A9: 1.1. | B9: Earth work in excavation in foundation trenches, column pits, plinth beam, under grade/ raft slab etc. by mechanical and/or manual means up to a depth of 1.5 mtr in soil from existing excavated soil level, stacking/spreading the excavated material within site premises (within a stretch of 1500 M) as per direction of Project Manager including dressing of bottom, sides strutting, timbering, shoring, trimming of sides, all leads and lifts, bailing or pumping out the water from the excavated areas collected from any source including subsoil water and keeping the excavated surface dry for subsequent works incidentals, etc. complete with ramming of bottom, surface preparation as per specifications to receive the PCC. | C9: CUM | D9: 1000 | E9: 120 | F9: =$D9*E9 -> 120000 | I9: =J9-H9 -> 0 | L9: =M9-K9 -> 0 | M9: =E9*J9 -> 0 | N9: =J9/D9 -> 0
B10: Excavation shall be payable only for vertical cut up to the outer edge of foundation lean concrete as indicated in drawings for all depths. Cost of extra excavation required for working space, supporting side shuttering of foundations and retaining walls, planking, dewatering, strutting etc. and that required for making slopes for stability of excavation shall be deemed to be included in the rate quoted. This item is not for Mass Excavation. | L10: =M10-K10 -> 0 | M10: =E10*J10 -> 0
A11: 1.2. | B11: Prepare the surface for PCC by manual excavation upto 30 cm depth including dressing the surface, ramming the bottom, disposal and spreading of the surplus earth at the specified location within premises including proper levelling, watering and consolidation complete as directed by E I C. (The item shall be measured as per plan area of PCC, Working space shall not be taken into measurement, deemed to be included into rates) (This item is only applicable if excavation item is not being executed by contractor and excavation already done by client for the location) | C11: SQM | D11: 1500 | E11: 65 | F11: =$D11*E11 -> 97500 | G11: =+E11 -> 65 | H11: 1881.385 | I11: =J11-H11 -> 0 | J11: ='EARTH WORK MB'!I78 -> 1881.385 | K11: 122290.02 | L11: =M11-K11 -> 0 | M11: =G11*J11 -> 122290.02 | N11: =J11/D11 -> 1.2542566
A12: 1.3. | B12: Filling available excavated earth in trenches, plinth, sides of foundations etc. in layers not exceeding 20cm in depth: consolidating each deposited layer by ramming and watering, lead within the premises and upto any depth. (Compacted Volume shall be payable as per drawing) - Actual volume shall be paid incase excavation is done by Client. | C12: CUM | D12: 2400 | E12: 100 | F12: =$D12*E12 -> 240000 | G12: 100 | H12: 4725.3991 | I12: =J12-H12 -> 0 | J12: ='EARTH WORK MB'!I86 -> 4725.3991 | K12: 472539.91 | L12: =M12-K12 -> 0 | M12: =G12*J12 -> 472539.91 | N12: =J12/D12 -> 1.9689163
B13: Total of Earthwork | F13: =SUBTOTAL(9,F9:F12) -> 457500
A15: 2 | B15: CONCRETE WORK
B16: Rates for all cement concrete items plain and reinforced described below shall include work from Basement Level to top of last roof including roof of machine room, mumty, over head water tanks and parapets above at all floors and for all heights. The contractor should provide full time sufficient pipes with accessories and pumps based on the site requirement for pumping and laying of concrete as directed by the EIC. The rate inclusive of standard rigid pipe line and its supports, lifting, laying charges, etc., at all heights and levels. No additional payment shall be payable to the contractor on account of using or change in any size of coarse aggregate in PCC/ RCC work at any stage during currency of works. (This section covers cast in situ structural and architectural as well.)
A17: 2.1 | B17: Plain Cement Concrete: Providing and laying plain cement concrete of specified grade as bed concrete under foundation, bases for rafts, underground water tank, building machine equipments, column footing, under floor landings, below road and pathways, cill, coping, screeding at roof to required slope and other locations as called for laid, consolidated and cured etc. complete including finishing the top surface to receive the next course / layer as per specification and drawing. (Shuttering shall be paid in Item No.3.1.1) M10 Grade (Basic Rate of PCC - Rs. 4200/cum) without pump | C17: CUM | D17: 100 | E17: 5550 | F17: =$D17*E17 -> 555000 | G17: 5550 | H17: 79.466655 | I17: =J17-H17 -> 0 | J17: ='CONCRETE SUMMARY'!M6 -> 79.466655 | K17: 441039.94 | L17: =M17-K17 -> 0 | M17: =G17*J17 -> 441039.94 | N17: =J17/D17 -> 0.79466655
A18: 2.2. | B18: Providing and laying cement concrete 1:2:4 (1 cement : 2 coarse sand : 4 graded stone aggregate 20mm nominal size) for ledge wall below balcony railings, band, mullion, lintel etc. (Shuttering shall be paid separately in respective item) as per drawing and as directed by the Project Manager. | C18: CUM | D18: 50 | E18: 5750 | F18: =$D18*E18 -> 287500 | I18: =J18-H18 -> 0 | J18: ='CONCRETE SUMMARY'!M7 -> 0 | L18: =M18-K18 -> 0 | M18: =E18*J18 -> 0 | N18: =J18/D18 -> 0
A19: 2.3. | B19: Providing and laying damp proof course 40mm thick including shttering with cement concrete 1:2:4 (1 cement : 2 coarse sand : 4 graded stone aggregate 20mm nominal size) including mixing of water proofing compound @ 2% of cement content and applying two layers of bitumen @ 1.70 Kg/Sqm of grade 85/25 and as directed by the Project Manager. | C19: SQM | D19: 200 | E19: 480 | F19: =$D19*E19 -> 96000 | I19: =J19-H19 -> 0 | J19: ='CONCRETE SUMMARY'!M8 -> 0 | L19: =M19-K19 -> 0 | M19: =E19*J19 -> 0 | N19: =J19/D19 -> 0
A21: 2.4. | B21: RCC WORK
B22: Providing & Laying RMC M-25 Grade as per approved design mix concrete (strictly controlled conditions) with flyash (as per approved design mix) with automatic batching plant machine mixed and machine vibrated RCC with melamine based plasticisers etc., upto any level, including finishing the exposed surface, fixing/ removal of pockets, fixing of sleeves and inserts (sleeves provided by client), curing etc complete, as per drawing (including all size and shape like circular, semi-circular, oval etc.) and as directed for all lead and lift, excluding cost of centering, shuttering and steel reinforcement but including cost of making shear keys and provision of construction / contraction / control joints in various locations. Checking from Client should not be considered as final and any defects arising during or after casting should be borne & bear by contractor at his own cost. This is inclusive of leaving shuttering & centring for pour strip, slab in slope, RCC members in curved, etc., nothing is payable extra on this account. RMC (M-25) Basic Rate - Rs. 5200/cum without pump excluding GST
A23: 2.4.1. | B23: Foundation, column footings, raft slab, raft beams, plinth beam, lift pits, sump pits, pedestals / bases of column, column upto plinth, swimming pool, Retaining wall foundations, grade slab etc. | C23: CUM | D23: 2080 | E23: 6600 | F23: =$D23*E23 -> 13728000 | G23: =+E23 -> 6600 | H23: 1686.5471 | I23: =J23-H23 -> 0 | J23: ='CONCRETE SUMMARY'!M12 -> 1686.5471 | K23: 11131211 | L23: =M23-K23 -> 0 | M23: =G23*J23 -> 11131211 | N23: =J23/D23 -> 0.81083997
A24: 2.4.2. | B24: Suspended floors, roofs, balconies, shelves/ counters, stair waist slabs, folded plate stairs and landings, swimming pool slab, lintel and floor beams, landing beams, girders (deep beams), RCC bands, swimming pool beam, cantilever projections, coping, cills, slab of tank etc at all levels.
A25: 2.4.2.1. | B25: Stilt Floor level to 7th Floor level | C25: CUM | D25: 2200 | E25: 6550 | F25: =$D25*E25 -> 14410000 | H25: 138.41397 | I25: =J25-H25 -> 169.17264 | J25: ='CONCRETE SUMMARY'!M14 -> 307.58661 | K25: 906611.53 | L25: =M25-K25 -> 1108080.8 | M25: =E25*J25 -> 2014692.3 | N25: =J25/D25 -> 0.1398121
A26: 2.4.2.2. | B26: 7th Floor level to to Terrace Including OHT, Mumty, Machine Room, Parapet | C26: CUM | D26: 2440 | E26: 6750 | F26: =$D26*E26 -> 16470000 | I26: =J26-H26 -> 0 | J26: ='CONCRETE SUMMARY'!M15 -> 0 | L26: =M26-K26 -> 0 | M26: =E26*J26 -> 0 | N26: =J26/D26 -> 0
A27: 2.4.2.3. | B27: All type of Moulding, Bands, Elevation/Architectural Features as per drawing and as directed by EIC. at all level | C27: CUM | D27: 70 | E27: 7300 | F27: =$D27*E27 -> 511000 | I27: =J27-H27 -> 0 | J27: ='CONCRETE SUMMARY'!M16 -> 0 | L27: =M27-K27 -> 0 | M27: =E27*J27 -> 0 | N27: =J27/D27 -> 0
A29: 2.5. | B29: Columns, Wall, pillars, piers, abutments, posts and struts, offset and projection of columns, water tank walls, lift walls, Retaining Wall, swimming pool, Parapets, planters, vertical projection of pergolas, wall and ramp walls etc. at all levels.
A30: 2.5.1. | B30: Stilt Floor level to 7th Floor level | C30: CUM | D30: 860 | E30: 6850 | F30: =$D30*E30 -> 5891000 | G30: 6850 | H30: 93.874382 | I30: =J30-H30 -> 0 | J30: ='CONCRETE SUMMARY'!M19 -> 93.874382 | K30: 643039.52 | L30: =M30-K30 -> 0 | M30: =G30*J30 -> 643039.52 | N30: =J30/D30 -> 0.10915626
A31: 2.5.2. | B31: 7th Floor level to to Terrace Including OHT, Mumty, Machine Room, Parapet | C31: CUM | D31: 950 | E31: 7050 | F31: =$D31*E31 -> 6697500 | I31: =J31-H31 -> 0 | J31: ='CONCRETE SUMMARY'!M20 -> 0 | L31: =M31-K31 -> 0 | M31: =E31*J31 -> 0 | N31: =J31/D31 -> 0
A32: 2.5.3. | B32: All type of Moulding, Bands, Elevation/Architectural Features as per drawing and as directed by EIC. at all level | C32: CUM | D32: 30 | E32: 7650 | F32: =$D32*E32 -> 229500 | I32: =J32-H32 -> 0 | J32: ='CONCRETE SUMMARY'!M21 -> 0 | L32: =M32-K32 -> 0 | M32: =E32*J32 -> 0 | N32: =J32/D32 -> 0
A33: 2.5.4. | B33: Finishing vaccum dewatering continuous concrete flooring 100-150 mm thick with specified grade concrete including necessary formwork in required level, vibrating concrete both by poker vibrators / leveling vaccum processing of the concrete and planning the surface by skin powered floater trowels with broom/plain finish including groove cutting & filling etc. complete. (Concrete shall be paid in the respective items above). | C33: SQM | D33: 1625 | E33: 100 | F33: =$D33*E33 -> 162500 | J33: ='CONCRETE SUMMARY'!M22 -> 0
B35: Total of RCC Work | F35: =SUBTOTAL(9,F17:F34) -> 59038000
A37: 3 | B37: CENTRING AND SHUTTERING
B38: Providing and fixing plywood or steel plate shuttering and centring for structural concrete work in locations called for including strutting, propping, bracing, bolting, wedging, casing, striking, removal etc. complete for any size, section, thickness. Props shall consist of well designed steel pipes adequately braced (wooden ballies as props shall not be permitted). The item to include centering and shuttering at all heights and levels. Allow for forming grooves, drip course, chamfers, cut-outs, openings etc. where called for and for dressing with approved shuttering oil to prevent adhesion. Unexposed concrete surfaces subsequently left untreated (in the condition obtained on removal of form work) shall not constitute exposed concrete work and shall be measured under this item only Irregular shapes with sides (like circular, semi-circular, oval etc.) which may not be perpendicular to each other for shapes not conforming to rectangle or square, and circular shuttering shall not be paid separately. Joints of soffits of the slab shall be made clean after concreting and de-shuttering. (quoted rate to include all staging upto 3.50 mtr height). Note:- Contractor shall take necessary precautions such as watertight shuttering. This is inclusive of RCC members, leaving shuttering & centring for pour strip, slab in slope, RCC members in curved (in plan), etc., nothing is payable extra on this account.
A39: 3.1.1. | B39: Foundation, column footings, raft slab, raft beams, plinth beam, lift pits, sump pits, pedestals / bases of column, column up to plinth, swimming pool, Retaining wall foundations, grade slab etc. | C39: SQM | D39: 2150 | E39: 360 | F39: =$D39*E39 -> 774000 | G39: =+E39 -> 360 | H39: 1645.4974 | I39: =J39-H39 -> 0 | J39: ='SHUTT. WORK SUMMARY'!M5 -> 1645.4974 | K39: 592379.05 | L39: =M39-K39 -> 0 | M39: =G39*J39 -> 592379.05 | N39: =J39/D39 -> 0.7653476
A40: 3.1.2. | B40: Suspended floors, roofs, balconies, shelves/ counters, stair waist slabs, folded plate stairs and landings, swimming pool slab, lintel and floor beams, landing beams, girders (deep beams), RCC bands, swimming pool beam, cantilever projections, coping, cills, slab of tank etc at all levels.
A41: 3.1.2.1. | B41: Stilt Floor level to 7th Floor level | C41: SQM | D41: 17600 | E41: 465 | F41: =$D41*E41 -> 8184000 | H41: 1016.4427 | I41: =J41-H41 -> 1375.1872 | J41: ='SHUTT. WORK SUMMARY'!M7 -> 2391.6299 | K41: 472645.86 | L41: =M41-K41 -> 639462.04 | M41: =E41*J41 -> 1112107.9 | N41: =J41/D41 -> 0.13588806
A42: 3.1.2.2. | B42: 7th Floor level to to Terrace Including OHT, Mumty, Machine Room, Parapet | C42: SQM | D42: 18800 | E42: 485 | F42: =$D42*E42 -> 9118000 | I42: =J42-H42 -> 0 | J42: ='SHUTT. WORK SUMMARY'!M8 -> 0 | L42: =M42-K42 -> 0 | M42: =E42*J42 -> 0 | N42: =J42/D42 -> 0
A43: 3.1.2..3 | B43: All type of Moulding, Bands, Elevation/Architectural Features as per drawing and as directed by EIC. at all level | C43: SQM | D43: 400 | E43: 550 | F43: =$D43*E43 -> 220000 | I43: =J43-H43 -> 0 | J43: ='SHUTT. WORK SUMMARY'!M9 -> 0 | L43: =M43-K43 -> 0 | M43: =E43*J43 -> 0 | N43: =J43/D43 -> 0
L44: =M44-K44 -> 0 | M44: =E44*J44 -> 0
A45: 3.2. | B45: Columns, Wall, pillars, piers, abutments, posts and struts, offset and projection of columns, water tank walls, lift walls, Retaining Wall, swimming pool, Parapets, planters, vertical projection of pergolas, wall and ramp walls etc. at all levels.
...

Sheet APP. BASIC RATE
A2: TOWER-E RMC APPROVED RATE LIST
A3: S.NO. | B3: DATE | C3: RMC PLANT NAME | D3: UNIT | E3: GRADE OF CONCRTE WITH CEMENT | J3: GRADE OF CONCRTE WITHOUT CEMENT | O3: REMARKS
E4: M10 | F4: M25 | G4: M30 | H4: M35 | I4: M40 | J4: M10 | K4: M25 | L4: M30 | M4: M35 | N4: M40
A5: 1 | B5: 45796 | C5: SHUBHAM RMC | D5: CUM | E5: 4400 | F5: 5100 | G5: 5300 | H5: 5500 | J5: 3300 | K5: 3300 | L5: 3300 | M5: 3300
A6: 2 | C6: SRIJAN INFRA | D6: CUM | E6: 4600 | F6: 5300 | G6: 5550 | H6: 5700 | J6: 3450 | K6: 3450 | L6: 3400 | M6: 3400
A9: 1 | B9: 45964 | C9: SHUBHAM RMC | D9: CUM | H9: 5200 | I9: 5300
A10: 2 | C10: ULTRATECH | D10: CUM | H10: 5300 | I10: 5500
A12: 1 | B12: 45978 | C12: SHUBHAM RMC | D12: CUM | E12: 4400 | F12: 4950
A13: 2 | C13: ULTRATECH | D13: CUM | E13: 4500 | F13: 5100

Sheet RMC BASIC RATE DIFF
A1: M/s. MARCO ENTERPRISES : RMC BASIC RATE DIFF. AT OMAXE ANANDA TOWER-E -PRAYAGRAJ
A2: SN | B2: DATE | C2: RMC SUPPLIER | D2: MATERIAL GRADE | E2: UNIT | F2: QTY | G2: BASIC RATE | H2: APPROVED RATE | I2: DIFF. IN RATE | J2: DIFF. AMOUNT | K2: REMARKS
A3: 1 | B3: 45791 | C3: ELSA | D3: M10 | E3: CUM | F3: 3.3 | G3: 4200 | H3: 4400 | I3: =H3-G3 -> 200 | J3: =F3*I3 -> 660
A4: 2 | B4: 45797 | C4: ELSA | D4: M10 | E4: CUM | F4: 5.4 | G4: 4200 | H4: 4400 | I4: =H4-G4 -> 200 | J4: =F4*I4 -> 1080
A5: 3 | B5: 45786 | C5: SHUBHAM | D5: M10 | E5: CUM | F5: 40 | G5: 4200 | H5: 4400 | I5: =H5-G5 -> 200 | J5: =F5*I5 -> 8000
A6: 4 | B6: 45789 | C6: SHUBHAM | D6: M10 | E6: CUM | F6: 17.5 | G6: 4200 | H6: 4400 | I6: =H6-G6 -> 200 | J6: =F6*I6 -> 3500
A7: 5 | B7: 45802 | C7: SHUBHAM | D7: M10 | E7: CUM | F7: 7.2 | G7: 4200 | H7: 4400 | I7: =H7-G7 -> 200 | J7: =F7*I7 -> 1440
A8: 6 | B8: 45803 | C8: SHUBHAM | D8: M10 | E8: CUM | F8: 10 | G8: 4200 | H8: 4400 | I8: =H8-G8 -> 200 | J8: =F8*I8 -> 2000
A9: 7 | B9: 45806 | C9: SHUBHAM | D9: M25 | E9: CUM | F9: 35 | G9: 5200 | H9: 5100 | I9: =H9-G9 -> -100 | J9: =F9*I9 -> -3500
A10: 8 | B10: 45806 | C10: ULTRATECH | D10: M25 | E10: CUM | F10: 35 | G10: 5200 | H10: 5300 | I10: =H10-G10 -> 100 | J10: =F10*I10 -> 3500
A11: 9 | B11: 45806 | C11: SHUBHAM | D11: M25 | E11: CUM | F11: 273 | G11: 5200 | H11: 5100 | I11: =H11-G11 -> -100 | J11: =F11*I11 -> -27300
A12: 10 | B12: 45807 | C12: ULTRATECH | D12: M25 | E12: CUM | F12: 56 | G12: 5200 | H12: 5300 | I12: =H12-G12 -> 100 | J12: =F12*I12 -> 5600
A13: 11 | B13: 45808 | C13: SHUBHAM | D13: M25 | E13: CUM | F13: 182 | G13: 5200 | H13: 5100 | I13: =H13-G13 -> -100 | J13: =F13*I13 -> -18200
A14: 12 | B14: 45808 | C14: ULTRATECH | D14: M25 | E14: CUM | F14: 182 | G14: 5200 | H14: 5300 | I14: =H14-G14 -> 100 | J14: =F14*I14 -> 18200
... A74: 72 | B74: 46009 | C74: ELSA | D74: M25 | E74: CUM | F74: 1 | G74: 5200 | H74: 4950 | I74: =H74-G74 -> -250 | J74: =F74*I74 -> -250
A75: 73 | B75: 18.12.2025 | C75: SHUBHAM | D75: M40 | E75: CUM | F75: 2 | G75: 5200 | H75: 5300 | I75: =H75-G75 -> 100 | J75: =F75*I75 -> 200
A76: 74 | B76: 19.12.2025 | C76: SHUBHAM | D76: M40 | E76: CUM | F76: 3 | G76: 5200 | H76: 5300 | I76: =H76-G76 -> 100 | J76: =F76*I76 -> 300
A77: 75 | B77: 20.12.2025 | C77: SHUBHAM | D77: M40 | E77: CUM | F77: 3 | G77: 5200 | H77: 5300 | I77: =H77-G77 -> 100 | J77: =F77*I77 -> 300
A78: 76 | B78: 20.12.2025 | C78: SHUBHAM | D78: M40 | E78: CUM | F78: 3.5 | G78: 5200 | H78: 5300 | I78: =H78-G78 -> 100 | J78: =F78*I78 -> 350
A79: 77 | B79: 21.12.2025 | C79: SHUBHAM | D79: M40 | E79: CUM | F79: 3 | G79: 5200 | H79: 5300 | I79: =H79-G79 -> 100 | J79: =F79*I79 -> 300
A80: 78 | B80: 21.12.2025 | C80: SHUBHAM | D80: M40 | E80: CUM | F80: 3 | G80: 5200 | H80: 5300 | I80: =H80-G80 -> 100 | J80: =F80*I80 -> 300
A81: 79 | B81: 23.12.2025 | C81: SHUBHAM | D81: M40 | E81: CUM | F81: 3 | G81: 5200 | H81: 5300 | I81: =H81-G81 -> 100 | J81: =F81*I81 -> 300
A82: 80 | B82: 25.12.2025 | C82: SHUBHAM | D82: M40 | E82: CUM | F82: 3 | G82: 5200 | H82: 5300 | I82: =H82-G82 -> 100 | J82: =F82*I82 -> 300
A83: 81 | B83: 25.12.2025 | C83: SHUBHAM | D83: M40 | E83: CUM | F83: 2.5 | G83: 5200 | H83: 5300 | I83: =H83-G83 -> 100 | J83: =F83*I83 -> 250
A84: 82 | B84: 26.12.2025 | C84: SHUBHAM | D84: M40 | E84: CUM | F84: 3 | G84: 5200 | H84: 5300 | I84: =H84-G84 -> 100 | J84: =F84*I84 -> 300
A85: 83 | B85: 29.12.2025 | C85: SHUBHAM | D85: M40 | E85: CUM | F85: 3 | G85: 5200 | H85: 5300 | I85: =H85-G85 -> 100 | J85: =F85*I85 -> 300
A86: 84 | B86: 31.12.2025 | C86: SHUBHAM | D86: M40 | E86: CUM | F86: 3.5 | G86: 5200 | H86: 5300 | I86: =H86-G86 -> 100 | J86: =F86*I86 -> 350
... A99: 97 | B99: 31.01.2026 | C99: SHUBHAM | D99: M25 | E99: CUM | F99: 28 | G99: 5200 | H99: 4950 | I99: =H99-G99 -> -250 | J99: =F99*I99 -> -7000
B102: Total Qty upto date | F102: =SUM(F3:F101) -> 2113.46 | J102: =SUM(J3:J101) -> 340

Sheet EARTH WORK MB
A1: COMPANY- OMAXE PANCHAM REALCON PVT LTD
A2: PROJECT- TOWER-E
A3: LOCATION- NAINI, PRAYAGRAJ
A4: MB SHEET- SOIL SURFACE DRESSING BELOW PLINTH BEAM
B5: & SOIL BACK FILLING WORK
A6: S.NO. | B6: DESCRIPTION | C6: UNIT | D6: NOS | E6: NOS | F6: MEASUREMENT | I6: QTY. | J6: REMARKS
F7: L | G7: B | H7: H/T
B8: SOIL DRESSING FOR RAFT PCC
A9: 1 | B9: GRID (22'-43'/A-Q') | C9: SQM | D9: 1 | E9: 1 | F9: =31.935+0.115+0.115+0.1+0.1 -> 32.365 | G9: =36.895+0.115+0.1+0.115+0.1 -> 37.325 | I9: =PRODUCT(D9:H9) -> 1208.0236 | J9: 3RD RA
A10: 2 | C10: SQM | D10: 1 | E10: 1 | F10: =8.78+0.115+0.115+0.1+0.1 -> 9.21 | G10: 0.515 | I10: =PRODUCT(D10:H10) -> 4.74315
A11: 3 | B11: GRID (22'-26'/M'-Q') | C11: SQM | D11: -1 | E11: 1 | F11: 11.005 | G11: 12.415 | I11: =PRODUCT(D11:H11) -> -136.62707
A12: 4 | B12: GRID (38'-43'/A-E') | C12: SQM | D12: -1 | E12: 1 | F12: 11.09 | G12: 10.285 | I12: =PRODUCT(D12:H12) -> -114.06065
A13: 5 | B13: GRID (22'-30'/A-B') | C13: SQM | D13: -1 | E13: 1 | F13: 11.285 | G13: =1.405+0.815+1.5 -> 3.72 | I13: =PRODUCT(D13:H13) -> -41.9802
A14: 6 | C14: SQM | D14: -1 | E14: 1 | F14: 1.695 | G14: =0.815+1.5 -> 2.315 | I14: =PRODUCT(D14:H14) -> -3.923925
A15: 7 | C15: SQM | D15: -1 | E15: 1 | F15: 3.95 | G15: 1.5 | I15: =PRODUCT(D15:H15) -> -5.925
A16: 8 | C16: SQM | D16: -1 | E16: 1 | F16: 15.8 | G16: =0.115+0.1 -> 0.215 | I16: =PRODUCT(D16:H16) -> -3.397
A17: 1 | B17: GRID (1-22'/A-Q') | C17: SQM | D17: 1 | E17: 1 | F17: =31.935+0.115+0.115+0.1+0.1 -> 32.365 | G17: =40.165+0.9+0.115+0.1+0.115+0.1 -> 41.495 | I17: =PRODUCT(D17:H17) -> 1342.9857 | J17: 4TH RA
A18: 2 | C18: SQM | D18: 1 | E18: 1 | F18: =8.78+0.115+0.115+0.1+0.1 -> 9.21 | G18: 0.515 | I18: =PRODUCT(D18:H18) -> 4.74315
A19: 3 | B19: GRID (17'-22'/M'-Q') | C19: SQM | D19: -1 | E19: 1 | F19: =14.275+0.9 -> 15.175 | G19: 12.415 | I19: =PRODUCT(D19:H19) -> -188.39763
A20: 4 | B20: GRID (1-5'/A-E') | C20: SQM | D20: -1 | E20: 1 | F20: 11.09 | G20: 10.285 | I20: =PRODUCT(D20:H20) -> -114.06065
A21: 5 | B21: GRID (14'-22'/A-B') | C21: SQM | D21: -1 | E21: 1 | F21: =14.555+0.9 -> 15.455 | G21: =1.405+0.815+1.5 -> 3.72 | I21: =PRODUCT(D21:H21) -> -57.4926
A22: 6 | C22: SQM | D22: -1 | E22: 1 | F22: 1.695 | G22: =0.815+1.5 -> 2.315 | I22: =PRODUCT(D22:H22) -> -3.923925
A23: 7 | C23: SQM | D23: -1 | E23: 1 | F23: 3.95 | G23: 1.5 | I23: =PRODUCT(D23:H23) -> -5.925
A24: 8 | C24: SQM | D24: -1 | E24: 1 | F24: 15.8 | G24: =0.115+0.1 -> 0.215 | I24: =PRODUCT(D24:H24) -> -3.397
B25: FLAT AREA SOIL DRESSING WORK GRID (22-43/A-Q)
J26: 7TH RA
B27: 1 | C27: SQM | D27: 1 | E27: 1 | F27: 5.15 | G27: =3.035+0.115 -> 3.15
B28: 2,3 | C28: SQM | D28: 1 | E28: 2 | F28: 3.17 | G28: 2.41
B29: 2' | C29: SQM | D29: 1 | E29: 1 | F29: 3.55 | G29: 3.17
B30: 4,10 | C30: SQM | D30: 1 | E30: 1 | F30: 5.49 | G30: 3.25
B31: 5,9 | C31: SQM | D31: 1 | E31: 1 | F31: 2.925 | G31: 1.7
B32: 6 | C32: SQM | D32: 1 | E32: 1 | F32: 3.385 | G32: 1.425
B33: 7 | C33: SQM | D33: 1 | E33: 1 | F33: 1.455 | G33: 1.425
B34: 8 | C34: SQM | D34: 1 | E34: 1 | F34: 1.7 | G34: 1.425
B35: 11 | C35: SQM | D35: 1 | E35: 1 | F35: 3.33 | G35: 1.83
C36: SQM | D36: 1 | E36: 1 | F36: 4.27 | G36: 1.93
C37: SQM | D37: 1 | E37: 1 | F37: 7.665 | G37: 3.14
B38: 12 | C38: SQM | D38: 1 | E38: 1 | F38: 4.27 | G38: 1.7
B39: 13 | C39: SQM | D39: 1 | E39: 1 | F39: 1.6 | G39: 1.44
B40: 14 | C40: SQM | D40: 1 | E40: 1 | F40: 1.69 | G40: 1.6
...

Sheet CONCRETE SUMMARY
A2: TOWER-E CONCRETE WORK SUMMARY
D3: QTY | M3: TOTAL
A4: 2 | B4: CONCRETE WORK | D4: 3rd RA | E4: 4th RA | F4: 5th RA | G4: 6th RA | H4: 7th RA | I4: 8th RA | J4: 9th RA
B5: Rates for all cement concrete items plain and reinforced described below shall include work from Basement Level to top of last roof including roof of machine room, mumty, over head water tanks and parapets above at all floors and for all heights. The contractor should provide full time sufficient pipes with accessories and pumps based on the site requirement for pumping and laying of concrete as directed by the EIC. The rate inclusive of standard rigid pipe line and its supports, lifting, laying charges, etc., at all heights and levels. No additional payment shall be payable to the contractor on account of using or change in any size of coarse aggregate in PCC/ RCC work at any stage during currency of works. (This section covers cast in situ structural and architectural as well.)
A6: 2.1 | B6: Plain Cement Concrete: Providing and laying plain cement concrete of specified grade as bed concrete under foundation, bases for rafts, underground water tank, building machine equipments, column footing, under floor landings, below road and pathways, cill, coping, screeding at roof to required slope and other locations as called for laid, consolidated and cured etc. complete including finishing the top surface to receive the next course / layer as per specification and drawing. (Shuttering shall be paid in Item No.3.1.1) M10 Grade (Basic Rate of PCC - Rs. 4200/cum) without pump | C6: CUM | D6: 56.798193 | E6: 22.668463 | M6: =SUM(D6:L6) -> 79.466655
A7: 2.2. | B7: Providing and laying cement concrete 1:2:4 (1 cement : 2 coarse sand : 4 graded stone aggregate 20mm nominal size) for ledge wall below balcony railings, band, mullion, lintel etc. (Shuttering shall be paid separately in respective item) as per drawing and as directed by the Project Manager. | C7: CUM | M7: =SUM(D7:L7) -> 0
A8: 2.3. | B8: Providing and laying damp proof course 40mm thick including shttering with cement concrete 1:2:4 (1 cement : 2 coarse sand : 4 graded stone aggregate 20mm nominal size) including mixing of water proofing compound @ 2% of cement content and applying two layers of bitumen @ 1.70 Kg/Sqm of grade 85/25 and as directed by the Project Manager. | C8: SQM | M8: =SUM(D8:L8) -> 0
A10: 2.4. | B10: RCC WORK
B11: Providing & Laying RMC M-25 Grade as per approved design mix concrete (strictly controlled conditions) with flyash (as per approved design mix) with automatic batching plant machine mixed and machine vibrated RCC with melamine based plasticisers etc., upto any level, including finishing the exposed surface, fixing/ removal of pockets, fixing of sleeves and inserts (sleeves provided by client), curing etc complete, as per drawing (including all size and shape like circular, semi-circular, oval etc.) and as directed for all lead and lift, excluding cost of centering, shuttering and steel reinforcement but including cost of making shear keys and provision of construction / contraction / control joints in various locations. Checking from Client should not be considered as final and any defects arising during or after casting should be borne & bear by contractor at his own cost. This is inclusive of leaving shuttering & centring for pour strip, slab in slope, RCC members in curved, etc., nothing is payable extra on this account. RMC (M-25) Basic Rate - Rs. 5200/cum without pump excluding GST
A12: 2.4.1. | B12: Foundation, column footings, raft slab, raft beams, plinth beam, lift pits, sump pits, pedestals / bases of column, column upto plinth, swimming pool, Retaining wall foundations, grade slab etc. | C12: CUM | D12: 748.20967 | E12: 792.12577 | F12: 76.112912 | H12: 70.098772 | M12: =SUM(D12:L12) -> 1686.5471
A13: 2.4.2. | B13: Suspended floors, roofs, balconies, shelves/ counters, stair waist slabs, folded plate stairs and landings, swimming pool slab, lintel and floor beams, landing beams, girders (deep beams), RCC bands, swimming pool beam, cantilever projections, coping, cills, slab of tank etc at all levels.
A14: 2.4.2.1. | B14: Stilt Floor level to 7th Floor level | C14: CUM | I14: =+'CONCRETE WORK MB'!I478 -> 153.7933 | J14: ='CONCRETE WORK MB'!I698 -> 153.7933 | M14: =SUM(D14:L14) -> 307.58661
A15: 2.4.2.2. | B15: 7th Floor level to to Terrace Including OHT, Mumty, Machine Room, Parapet | C15: CUM | M15: =SUM(D15:L15) -> 0
A16: 2.4.2.3. | B16: All type of Moulding, Bands, Elevation/Architectural Features as per drawing and as directed by EIC. at all level | C16: CUM | M16: =SUM(D16:L16) -> 0
A18: 2.5. | B18: Columns, Wall, pillars, piers, abutments, posts and struts, offset and projection of columns, water tank walls, lift walls, Retaining Wall, swimming pool, Parapets, planters, vertical projection of pergolas, wall and ramp walls etc. at all levels.
A19: 2.5.1. | B19: Stilt Floor level to 7th Floor level | C19: CUM | H19: 48.0455 | I19: =+'CONCRETE WORK MB'!I260*0.9+'CONCRETE WORK MB'!I243*0.9 -> 45.828882 | M19: =SUM(D19:L19) -> 93.874382
A20: 2.5.2. | B20: 7th Floor level to to Terrace Including OHT, Mumty, Machine Room, Parapet | C20: CUM | M20: =SUM(D20:L20) -> 0
A21: 2.5.3. | B21: All type of Moulding, Bands, Elevation/Architectural Features as per drawing and as directed by EIC. at all level | C21: CUM | M21: =SUM(D21:L21) -> 0
A22: 2.5.4. | B22: Finishing vaccum dewatering continuous concrete flooring 100-150 mm thick with specified grade concrete including necessary formwork in required level, vibrating concrete both by poker vibrators / leveling vaccum processing of the concrete and planning the surface by skin powered floater trowels with broom/plain finish including groove cutting & filling etc. complete. (Concrete shall be paid in the respective items above). | C22: SQM | M22: =SUM(D22:L22) -> 0
D24: =SUM(D5:D23) -> 805.00787 | E24: =SUM(E5:E23) -> 814.79424 | F24: =SUM(F5:F23) -> 76.112912 | G24: =SUM(G5:G23) -> 0 | H24: =SUM(H5:H23) -> 118.14427 | I24: =SUM(I5:I23) -> 199.62219 | J24: =SUM(J5:J23) -> 153.7933 | K24: =SUM(K5:K23) -> 0 | L24: TOTAL | M24: =SUM(M5:M23) -> 2167.4748

Sheet CONCRETE RECO.
B1: RCC SUMMARY : OMAXE TOWER-E
B2: M/s. MARCO ENTERPRISES
A3: S.No. | B3: Item Discription | C3: Grade | D3: Floor Name | E3: NO | F3: Unit Qty. | G3: Quantity | H3: Unit | I3: M10 | J3: M25 | K3: M30 | L3: M35 | M3: M40
B4: TOWER-E
A6: 1 | B6: RAFT PCC GRID (A-Q/23-43) | C6: M10 | D6: AS SUB-STRUCTURE | E6: 1 | F6: ='CONCRETE WORK MB'!I22 -> 56.798193 | G6: =E6*F6 -> 56.798193 | H6: Cum | I6: =IF(I$3=$C6,$G6,"-") -> 56.798193 | J6: =IF(J$3=$C6,$G6,"-") -> - | K6: =IF(K$3=$C6,$G6,"-") -> - | L6: =IF(L$3=$C6,$G6,"-") -> - | M6: =IF(M$3=$C6,$G6,"-") -> -
A7: 2 | B7: RAFT RCC GRID (A-Q/23-43) | C7: M25 | D7: AS SUB-STRUCTURE | E7: =E6 -> 1 | F7: ='CONCRETE WORK MB'!I47 -> 748.20967 | G7: =E7*F7 -> 748.20967 | H7: Cum | I7: =IF(I$3=$C7,$G7,"-") -> - | J7: =IF(J$3=$C7,$G7,"-") -> 748.20967 | K7: =IF(K$3=$C7,$G7,"-") -> - | L7: =IF(L$3=$C7,$G7,"-") -> - | M7: =IF(M$3=$C7,$G7,"-") -> -
A8: 3 | B8: RAFT PCC GRID (A-Q/1-23) | C8: M10 | D8: AS SUB-STRUCTURE | E8: 1 | F8: ='CONCRETE WORK MB'!I34 -> 22.668463 | G8: =E8*F8 -> 22.668463 | H8: Cum | I8: =IF(I$3=$C8,$G8,"-") -> 22.668463 | J8: =IF(J$3=$C8,$G8,"-") -> - | K8: =IF(K$3=$C8,$G8,"-") -> - | L8: =IF(L$3=$C8,$G8,"-") -> - | M8: =IF(M$3=$C8,$G8,"-") -> -
A9: 4 | B9: RAFT RCC GRID (A-Q/1-43) | C9: M25 | D9: AS SUB-STRUCTURE | E9: =E8 -> 1 | F9: ='CONCRETE WORK MB'!I56 -> 792.12577 | G9: =E9*F9 -> 792.12577 | H9: Cum | I9: =IF(I$3=$C9,$G9,"-") -> - | J9: =IF(J$3=$C9,$G9,"-") -> 792.12577 | K9: =IF(K$3=$C9,$G9,"-") -> - | L9: =IF(L$3=$C9,$G9,"-") -> - | M9: =IF(M$3=$C9,$G9,"-") -> -
A10: 5 | B10: COMPENSATORY STRIP (22-23/B'-L') | C10: M25 | D10: AS SUB-STRUCTURE | E10: =E9 -> 1 | F10: ='CONCRETE WORK MB'!I60 -> 12.087 | G10: =E10*F10 -> 12.087 | H10: Cum | I10: =IF(I$3=$C10,$G10,"-") -> - | J10: =IF(J$3=$C10,$G10,"-") -> 12.087 | K10: =IF(K$3=$C10,$G10,"-") -> - | L10: =IF(L$3=$C10,$G10,"-") -> - | M10: =IF(M$3=$C10,$G10,"-") -> -
A11: 6 | B11: PADESTIAL & LIFT (1-43/A-Q) | C11: M35 | D11: AS SUB-STRUCTURE | E11: =E10 -> 1 | F11: ='CONCRETE WORK MB'!I93 -> 64.025912 | G11: =E11*F11 -> 64.025912 | H11: Cum | I11: =IF(I$3=$C11,$G11,"-") -> - | J11: =IF(J$3=$C11,$G11,"-") -> - | K11: =IF(K$3=$C11,$G11,"-") -> - | L11: =IF(L$3=$C11,$G11,"-") -> 64.025912 | M11: =IF(M$3=$C11,$G11,"-") -> -
A12: 7 | B12: PLINTH BEAM (1-43/A-Q) | C12: M25 | D12: AS SUB-STRUCTURE | E12: =E11 -> 1 | F12: ='CONCRETE WORK MB'!I168 -> 51.601792 | G12: =E12*F12 -> 51.601792 | H12: Cum | I12: =IF(I$3=$C12,$G12,"-") -> - | J12: =IF(J$3=$C12,$G12,"-") -> 51.601792 | K12: =IF(K$3=$C12,$G12,"-") -> - | L12: =IF(L$3=$C12,$G12,"-") -> - | M12: =IF(M$3=$C12,$G12,"-") -> -
A13: 8 | B13: COLUMN JUNCTION AT PLINTH BEAM LVL (1-43/A-Q) | C13: M35 | D13: AS SUB-STRUCTURE | E13: =E12 -> 1 | F13: 14 | G13: =E13*F13 -> 14 | H13: Cum | I13: =IF(I$3=$C13,$G13,"-") -> - | J13: =IF(J$3=$C13,$G13,"-") -> - | K13: =IF(K$3=$C13,$G13,"-") -> - | L13: =IF(L$3=$C13,$G13,"-") -> 14 | M13: =IF(M$3=$C13,$G13,"-") -> -
A14: 9 | B14: COLUMN JUNCTION AT PLINTH BEAM LVL (1-43/A-Q) | C14: M40 | D14: AS SUB-STRUCTURE | E14: =E13 -> 1 | F14: ='CONCRETE WORK MB'!I193-F13 -> 4.49698 | G14: =E14*F14 -> 4.49698 | H14: Cum | I14: =IF(I$3=$C14,$G14,"-") -> - | J14: =IF(J$3=$C14,$G14,"-") -> - | K14: =IF(K$3=$C14,$G14,"-") -> - | L14: =IF(L$3=$C14,$G14,"-") -> - | M14: =IF(M$3=$C14,$G14,"-") -> 4.49698
A15: 10 | B15: COLUMN FROM PLINTH BEAM LVL TO 1ST FLOOR LVL (22-43/A-Q) | C15: M40 | D15: AS SUPER-STRUCTURE | E15: =E13 -> 1 | F15: ='CONCRETE WORK MB'!I217 -> 48.0455 | G15: =E15*F15 -> 48.0455 | H15: Cum | I15: =IF(I$3=$C15,$G15,"-") -> - | J15: =IF(J$3=$C15,$G15,"-") -> - | K15: =IF(K$3=$C15,$G15,"-") -> - | L15: =IF(L$3=$C15,$G15,"-") -> - | M15: =IF(M$3=$C15,$G15,"-") -> 48.0455
A16: 11 | B16: COLUMN FROM PLINTH BEAM LVL TO 1ST FLOOR LVL (1-22/A-Q) | C16: M40 | D16: AS SUPER-STRUCTURE | E16: =E14 -> 1 | F16: ='CONCRETE WORK MB'!I243 -> 45.9755 | G16: =E16*F16 -> 45.9755 | H16: Cum | I16: =IF(I$3=$C16,$G16,"-") -> - | J16: =IF(J$3=$C16,$G16,"-") -> - | K16: =IF(K$3=$C16,$G16,"-") -> - | L16: =IF(L$3=$C16,$G16,"-") -> - | M16: =IF(M$3=$C16,$G16,"-") -> 45.9755
A17: 12 | B17: EXTRA HEIGHT COLUMN FROM PLINTH BEAM LVL TO 1ST FLOOR LVL (1-43/A-Q) | C17: M40 | D17: AS SUPER-STRUCTURE | E17: =E15 -> 1 | F17: ='CONCRETE WORK MB'!I260 -> 4.94548 | G17: =E17*F17 -> 4.94548 | H17: Cum | I17: =IF(I$3=$C17,$G17,"-") -> - | J17: =IF(J$3=$C17,$G17,"-") -> - | K17: =IF(K$3=$C17,$G17,"-") -> - | L17: =IF(L$3=$C17,$G17,"-") -> - | M17: =IF(M$3=$C17,$G17,"-") -> 4.94548
A18: 13 | B18: SLAB AT GROUND FLOOR LVL (22-43/A-Q) | C18: M40 | D18: AS SUPER-STRUCTURE | E18: =E15 -> 1 | F18: 24 | G18: =E18*F18 -> 24 | H18: Cum | I18: =IF(I$3=$C18,$G18,"-") -> - | J18: =IF(J$3=$C18,$G18,"-") -> - | K18: =IF(K$3=$C18,$G18,"-") -> - | L18: =IF(L$3=$C18,$G18,"-") -> - | M18: =IF(M$3=$C18,$G18,"-") -> 24
A19: 14 | B19: SLAB AT GROUND FLOOR LVL (22-43/A-Q) | C19: M25 | D19: AS SUPER-STRUCTURE | E19: =E16 -> 1 | F19: ='CONCRETE WORK MB'!I478-F18 -> 129.7933 | G19: =E19*F19 -> 129.7933 | H19: Cum | I19: =IF(I$3=$C19,$G19,"-") -> - | J19: =IF(J$3=$C19,$G19,"-") -> 129.7933 | K19: =IF(K$3=$C19,$G19,"-") -> - | L19: =IF(L$3=$C19,$G19,"-") -> - | M19: =IF(M$3=$C19,$G19,"-") -> -
A20: 14 | B20: SLAB AT GROUND FLOOR LVL (1-22/A-Q) | C20: M40 | D20: AS SUPER-STRUCTURE | E20: =E17 -> 1 | F20: 15 | G20: =E20*F20 -> 15 | H20: Cum | I20: =IF(I$3=$C20,$G20,"-") -> - | J20: =IF(J$3=$C20,$G20,"-") -> - | K20: =IF(K$3=$C20,$G20,"-") -> - | L20: =IF(L$3=$C20,$G20,"-") -> - | M20: =IF(M$3=$C20,$G20,"-") -> 15
A21: 15 | B21: SLAB AT GROUND FLOOR LVL (1-22/A-Q) | C21: M25 | D21: AS SUPER-STRUCTURE | E21: =E17 -> 1 | F21: ='CONCRETE WORK MB'!I698-F20 -> 138.7933 | G21: =E21*F21 -> 138.7933 | H21: Cum | I21: =IF(I$3=$C21,$G21,"-") -> - | J21: =IF(J$3=$C21,$G21,"-") -> 138.7933 | K21: =IF(K$3=$C21,$G21,"-") -> - | L21: =IF(L$3=$C21,$G21,"-") -> - | M21: =IF(M$3=$C21,$G21,"-") -> -
B23: TOTAL RCC QTY (THEORITICAL) | G23: =SUM(G4:G22) -> 2172.5669 | H23: Cum | I23: =SUM(I4:I22) -> 79.466655 | J23: =SUM(J4:J22) -> 1872.6108 | K23: =SUM(K4:K22) -> 0 | L23: =SUM(L4:L22) -> 78.025912 | M23: =SUM(M4:M22) -> 142.46346
B24: TOTAL RCC QTY (CASTING) | G24: ='PCC & RCC REC.'!T96 -> 2232.46 | H24: Cum | I24: ='PCC & RCC REC.'!D98+'PCC & RCC REC.'!I98+'PCC & RCC REC.'!N98 -> 83.4 | J24: ='PCC & RCC REC.'!E98+'PCC & RCC REC.'!J98+'PCC & RCC REC.'!O98 -> 1910.06 | K24: ='PCC & RCC REC.'!F98+'PCC & RCC REC.'!K98+'PCC & RCC REC.'!P98 -> 0 | L24: ='PCC & RCC REC.'!G98+'PCC & RCC REC.'!L98+'PCC & RCC REC.'!Q98 -> 82 | M24: ='PCC & RCC REC.'!H98+'PCC & RCC REC.'!M98+'PCC & RCC REC.'!R98 -> 157
B25: DIFFERENCE (WASTAGE) | G25: =G23-G24 -> -59.893124 | H25: Cum | I25: =I23-I24 -> -3.933345 | J25: =J23-J24 -> -37.449151 | K25: =K23-K24 -> 0 | L25: =L23-L24 -> -3.974088 | M25: =M23-M24 -> -14.53654
B26: WASTAGE % | G26: =G25/G23 -> -0.027567908 | I26: =I25/I23 -> -0.049496798 | J26: =J25/J23 -> -0.019998363 | K26: =K25/K23 -> #DIV/0! | L26: =L25/L23 -> -0.050932926 | M26: =M25/M23 -> -0.10203697
B28: PREV. BILL RCC QTY (THEORITICAL) | G28: =+I28+J28+K28+L28+M28 -> 1814.0567 | H28: Cum | I28: 79.466655 | J28: 1604.02 | K28: 0 | L28: 78.03 | M28: 52.54
B29: PREV. BILL RCC QTY (CASTING-ACTUAL) | G29: =+I29+J29+K29+L29+M29 -> 1857.98 | H29: Cum | I29: 83.4 | J29: 1636.58 | K29: 0 | L29: 82 | M29: 56
B30: DIFFERENCE (WASTAGE) | G30: =G28-G29 -> -43.923345 | H30: Cum | I30: =I28-I29 -> -3.933345 | J30: =J28-J29 -> -32.56 | K30: =K28-K29 -> 0 | L30: =L28-L29 -> -3.97 | M30: =M28-M29 -> -3.46
B31: WASTAGE % | G31: =G30/G28 -> -0.024212775 | I31: =I30/I28 -> -0.049496798 | J31: =J30/J28 -> -0.020298999 | K31: =K30/K28 -> #DIV/0! | L31: =L30/L28 -> -0.050877867 | M31: =M30/M28 -> -0.065854587
B33: THIS BILL RCC QTY (THEORITICAL) | G33: =G23-G28 -> 358.51022 | H33: Cum | I33: =I23-I28 -> 0 | J33: =J23-J28 -> 268.59085 | K33: =K23-K28 -> 0 | L33: =L23-L28 -> -0.004088 | M33: =M23-M28 -> 89.92346
B34: THIS BILL RCC QTY (CASTING-ACTUAL) | G34: =G24-G29 -> 374.48 | H34: Cum | I34: =I24-I29 -> 0 | J34: =J24-J29 -> 273.48 | K34: =K24-K29 -> 0 | L34: =L24-L29 -> 0 | M34: =M24-M29 -> 101
B35: DIFFERENCE (WASTAGE) | G35: =G33-G34 -> -15.969779 | H35: Cum | I35: =I33-I34 -> 0 | J35: =J33-J34 -> -4.8891512 | K35: =K33-K34 -> 0 | L35: =L33-L34 -> -0.004088 | M35: =M33-M34 -> -11.07654
B36: WASTAGE % | G36: =G35/G33 -> -0.044544837 | I36: =I35/I33 -> #DIV/0! | J36: =J35/J33 -> -0.01820297 | K36: =K35/K33 -> #DIV/0! | L36: =L35/L33 -> 1 | M36: =M35/M33 -> -0.12317742

Sheet PCC & RCC REC.
A1: S.NO. | B1: MONTH | C1: DATE | D1: RMC | I1: ELSA | N1: MANUAL | S1: WORK IN PROGRSS | T1: TOTAL | U1: REMARK
D2: GRADE | I2: GRADE | N2: GRADE
D3: M10 | E3: M25 | F3: M30 | G3: M35 | H3: M40 | I3: M10 | J3: M25 | K3: M30 | L3: M35 | M3: M40 | N3: M10 | O3: M25 | P3: M30 | Q3: M35 | R3: M40
A4: 1 | B4: 45778 | C4: 45791 | I4: 3.3 | U4: TOWER-E RAFT PCC
A5: 2 | C5: 45797 | I5: 5.4 | U5: TOWER-E RAFT PCC
A6: 3 | C6: 45786 | D6: 40 | U6: TOWER-E RAFT PCC
A7: 4 | C7: 45789 | D7: 17.5 | U7: TOWER-E RAFT PCC
A8: 5 | C8: 45802 | I8: 7.2 | U8: TOWER-E RAFT PCC
A9: 6 | C9: 45803 | I9: 10 | U9: TOWER-E RAFT PCC
A10: 7 | C10: 45806 | E10: 70 | U10: TOWER-E RAFT RCC (23-43)
A11: 8 | C11: 45807 | E11: 329 | U11: TOWER-E RAFT RCC (23-43)
A12: 9 | C12: 45808 | E12: =357+7 -> 364 | U12: TOWER-E RAFT RCC (23-43)
A13: 10 | B13: 45809 | C13: 45818 | E13: 147 | U13: TOWER-E RAFT RCC (1-23)
A14: 11 | C14: 45819 | E14: 2 | U14: TOWER-E RAFT RCC (1-23)
A15: 12 | C15: 45820 | E15: 154 | U15: TOWER-E RAFT RCC (1-23)
A16: 13 | C16: 45821 | E16: 431 | U16: TOWER-E RAFT RCC (1-23)
A17: 14 | C17: 45822 | E17: 73 | U17: TOWER-E RAFT RCC (1-23)
A18: 15 | C18: 45830 | G18: 3 | U18: TOWER-E PADESTIAL (1-42/A-Q)
A19: 16 | C19: 45831 | G19: 4 | U19: TOWER-E PADESTIAL (1-42/A-Q)
A20: 17 | C20: 45832 | G20: 5 | U20: TOWER-E PADESTIAL (1-42/A-Q)
A21: 18 | C21: 45833 | G21: 5 | U21: TOWER-E PADESTIAL (1-42/A-Q)
A22: 19 | C22: 45834 | G22: 6 | U22: TOWER-E PADESTIAL (1-42/A-Q)
A23: 20 | C23: 45835 | G23: 4 | U23: TOWER-E PADESTIAL (1-42/A-Q)
A24: 21 | C24: 45837 | G24: 3 | U24: TOWER-E PADESTIAL (1-42/A-Q)
A25: 22 | B25: 45839 | C25: 45839 | G25: 8 | U25: TOWER-E PADESTIAL (1-42/A-Q)
A26: 23 | C26: 45840 | G26: 4.5 | U26: TOWER-E PADESTIAL (1-42/A-Q)
A27: 24 | C27: 45842 | G27: 3.5 | U27: TOWER-E PADESTIAL (1-42/A-Q)
A28: 25 | C28: 45843 | G28: 8 | U28: TOWER-E PADESTIAL (1-42/A-Q)
A29: 26 | C29: 45845 | G29: 3 | U29: TOWER-E PADESTIAL (1-42/A-Q)
A30: 27 | C30: 45846 | G30: 4 | U30: TOWER-E PADESTIAL (1-42/A-Q)
A31: 28 | C31: 45846 | E31: 14 | U31: TOWER-E RAFT COMPENSATORY STRIP (22-23/B'-L')
A32: 29 | C32: 45847 | G32: 3.5 | U32: TOWER-E PADESTIAL (1-42/A-Q)
A33: 30 | C33: 45848 | G33: 3.5 | U33: TOWER-E PADESTIAL (1-42/A-Q)
A34: 31 | B34: 45901 | C34: 45925 | G34: 3 | U34: COLUMN JUNCTION AT PLINTH BEAM
A35: 32 | C35: 45925 | E35: 4 | U35: PLINTH BEAM
A36: 33 | C36: 45925 | E36: 4.5 | U36: PLINTH BEAM
A37: 34 | B37: 45931 | C37: 45931 | G37: 3 | U37: COLUMN JUNCTION AT PLINTH BEAM
A38: 35 | C38: 45931 | E38: 4 | U38: PLINTH BEAM
A39: 36 | C39: 45931 | E39: 3.5 | U39: PLINTH BEAM
A40: 37 | C40: 45937 | G40: 3 | U40: COLUMN JUNCTION AT PLINTH BEAM
...

Sheet RMC RECEIVING
A1: M/s. MARCO ENTERPRISES : RMC RECEIVING AT OMAXE ANANDA TOWER-E -PRAYAGRAJ
A2: SN | B2: DATE | C2: VEHICLE NO | D2: CHALLAN NO/INVOICE NO. | E2: MATERIAL GRADE | F2: UNIT | G2: RMC PLANT QTY (M 10) | H2: RMC PLANT QTY (M 25) | I2: RMC PLANT QTY (M 30) | J2: RMC PLANT QTY (M 35) | K2: RMC PLANT QTY (M 40) | L2: ACTUAL CEMENT WEIGHT BY DESIGN MIX | M2: CEMENT WEIGHT BY RMC PLANT | N2: CEMENT DIFF (IN KG) | O2: IN TIME | P2: OUT TIME | Q2: TOWER NO | R2: TYPE OF WORK | S2: RMC SUPPLIER | T2: REMARKS
A3: 1 | B3: 45786 | C3: UP32VN6145 | D3: 449 | E3: RMC10 | F3: CUM | G3: 7 | L3: =G3*220 -> 1540 | M3: 1540 | N3: =M3-L3 -> 0 | O3: 0.45138889 | P3: 0.51041667 | Q3: TOWER-E RAFT PCC | R3: RAFT PCC | S3: SHUBHAM
A4: 2 | B4: 45786 | C4: UP32WN8332 | D4: 450 | E4: RMC10 | F4: CUM | G4: 7 | L4: =G4*220 -> 1540 | M4: 1540 | N4: =M4-L4 -> 0 | O4: 0.52083333 | P4: 0.56944444 | Q4: TOWER-E RAFT PCC | R4: RAFT PCC | S4: SHUBHAM
A5: 3 | B5: 45786 | C5: UP53HT5034 | D5: 451 | E5: RMC10 | F5: CUM | G5: 7 | L5: =G5*220 -> 1540 | M5: 1540 | N5: =M5-L5 -> 0 | O5: 0.57777778 | P5: 0.61111111 | Q5: TOWER-E RAFT PCC | R5: RAFT PCC | S5: SHUBHAM
A6: 4 | B6: 45786 | C6: UP32VN6145 | D6: 453 | E6: RMC10 | F6: CUM | G6: 7 | L6: =G6*220 -> 1540 | M6: 1540 | N6: =M6-L6 -> 0 | O6: 0.61805556 | P6: 0.66666667 | Q6: TOWER-E RAFT PCC | R6: RAFT PCC | S6: SHUBHAM
A7: 5 | B7: 45786 | C7: UP32WN8334 | D7: 454 | E7: RMC10 | F7: CUM | G7: 6 | L7: =G7*220 -> 1320 | M7: 1320 | N7: =M7-L7 -> 0 | O7: 0.6875 | P7: 0.73958333 | Q7: TOWER-E RAFT PCC | R7: RAFT PCC | S7: SHUBHAM
A8: 6 | B8: 45786 | C8: UP53HT5034 | D8: 457 | E8: RMC10 | F8: CUM | G8: 6 | L8: =G8*220 -> 1320 | M8: 1320 | N8: =M8-L8 -> 0 | O8: 0.77430556 | P8: 0.8125 | Q8: TOWER-E RAFT PCC | R8: RAFT PCC | S8: SHUBHAM
A9: 7 | B9: 45789 | C9: UP32WN8334 | D9: 487 | E9: RMC10 | F9: CUM | G9: 5 | L9: =G9*220 -> 1100 | M9: 1096 | N9: =M9-L9 -> -4 | O9: 0.77430556 | P9: 0.8125 | Q9: TOWER-E RAFT PCC | R9: RAFT PCC | S9: SHUBHAM
A10: 8 | B10: 45789 | C10: UP32WN8334 | D10: 488 | E10: RMC10 | F10: CUM | G10: 5 | L10: =G10*220 -> 1100 | M10: 1096 | N10: =M10-L10 -> -4 | O10: 0.77430556 | P10: 0.8125 | Q10: TOWER-E RAFT PCC | R10: RAFT PCC | S10: SHUBHAM
A11: 9 | B11: 45789 | C11: UP32VN6144 | D11: 490 | E11: RMC10 | F11: CUM | G11: 5.5 | L11: =G11*220 -> 1210 | M11: 1210 | N11: =M11-L11 -> 0 | O11: 0.77430556 | P11: 0.8125 | Q11: TOWER-E RAFT PCC | R11: RAFT PCC | S11: SHUBHAM
A12: 10 | B12: 45789 | C12: UP32VN6144 | D12: 494 | E12: RMC10 | F12: CUM | G12: 2 | L12: =G12*220 -> 440 | M12: 440 | N12: =M12-L12 -> 0 | O12: 0.77430556 | P12: 0.8125 | Q12: TOWER-E RAFT PCC | R12: RAFT PCC | S12: SHUBHAM
A13: 11 | B13: 29.05.2025 | C13: UP32VN6145 | D13: 721 | E13: RMC 25 | F13: CUM | H13: 7 | L13: =H13*365 -> 2555 | M13: 2563 | N13: =M13-L13 -> 8 | O13: 0.9375 | P13: 0.96388889 | Q13: TOWER-E (23-43) | R13: RAFT | S13: SHUBHAM
A14: 12 | B14: 29.05.2025 | C14: UP32WN8334 | D14: 722 | E14: RMC 25 | F14: CUM | H14: 7 | L14: =H14*365 -> 2555 | M14: 2558 | N14: =M14-L14 -> 3 | O14: 0.96666667 | P14: 0.98125 | Q14: TOWER-E (23-43) | R14: RAFT | S14: SHUBHAM
A15: 13 | B15: 29.05.2025 | C15: UP32WN8333 | D15: 723 | E15: RMC 25 | F15: CUM | H15: 7 | L15: =H15*365 -> 2555 | M15: 2564 | N15: =M15-L15 -> 9 | O15: 0.98541667 | P15: 12:02PM | Q15: TOWER-E (23-43) | R15: RAFT | S15: SHUBHAM
A16: 14 | B16: 29.05.2025 | C16: UP32HT5032 | D16: 724 | E16: RMC 25 | F16: CUM | H16: 7 | L16: =H16*365 -> 2555 | M16: 2574 | N16: =M16-L16 -> 19 | O16: 0.50347222 | P16: 0.013194444 | Q16: TOWER-E (23-43) | R16: RAFT | S16: SHUBHAM
A17: 15 | B17: 29.05.2025 | C17: UP32HT5034 | D17: 725 | E17: RMC 25 | F17: CUM | H17: 5.5 | L17: =H17*365 -> 2007.5 | M17: 2018 | N17: =M17-L17 -> 10.5 | O17: 0.015972222 | P17: 0.029166667 | Q17: TOWER-E (23-43) | R17: RAFT | S17: SHUBHAM
B18: 29.05.2025 | C18: UP32HT5034 | D18: 726 | E18: RMC 25 | F18: CUM | H18: 1.5 | L18: =H18*365 -> 547.5 | M18: 548 | N18: =M18-L18 -> 0.5 | O18: 0.015972222 | P18: 0.029166667 | Q18: TOWER-E (23-43) | R18: RAFT | S18: SHUBHAM
A19: 16 | B19: 29.05.2025 | C19: UP70QT2013 | D19: 905350012 | E19: RMC 25 | F19: CUM | H19: 7 | L19: =H19*365 -> 2555 | M19: 2555 | N19: =M19-L19 -> 0 | O19: 0.9375 | P19: 0.96319444 | Q19: TOWER-E (23-43) | R19: RAFT | S19: ULTRATECH
A20: 17 | B20: 29.05.2025 | C20: UP70QT2341 | D20: 905350013 | E20: RMC 25 | F20: CUM | H20: 7 | L20: =H20*365 -> 2555 | M20: 2555 | N20: =M20-L20 -> 0 | O20: 0.96736111 | P20: 0.98680556 | Q20: TOWER-E (23-43) | R20: RAFT | S20: ULTRATECH
A21: 18 | B21: 29.05.2025 | C21: UP70QT2015 | D21: 905350014 | E21: RMC 25 | F21: CUM | H21: 7 | L21: =H21*365 -> 2555 | M21: 2555 | N21: =M21-L21 -> 0 | O21: 0.98680556 | P21: 1.0083333 | Q21: TOWER-E (23-43) | R21: RAFT | S21: ULTRATECH
A22: 19 | B22: 29.05.2025 | C22: UP70QT2342 | D22: 905350015 | E22: RMC 25 | F22: CUM | H22: 7 | L22: =H22*365 -> 2555 | M22: 2556 | N22: =M22-L22 -> 1 | O22: 0.052777778 | P22: 0.071527778 | Q22: TOWER-E (23-43) | R22: RAFT | S22: ULTRATECH
A23: 20 | B23: 29.05.2025 | C23: UP70QT2014 | D23: 905350016 | E23: RMC 25 | F23: CUM | H23: 7 | L23: =H23*365 -> 2555 | M23: 2555 | N23: =M23-L23 -> 0 | O23: 0.075694444 | P23: 0.086805556 | Q23: TOWER-E (23-43) | R23: RAFT | S23: ULTRATECH
A24: 21 | B24: 30.05.2025 | C24: UP32VN6145 | D24: 727 | E24: RMC 25 | F24: CUM | H24: 7 | L24: =H24*365 -> 2555 | M24: 2561 | N24: =M24-L24 -> 6 | O24: 0.043055556 | P24: 0.076388889 | Q24: TOWER-E (23-43) | R24: RAFT | S24: SHUBHAM
A25: 22 | B25: 30.05.2025 | C25: UP32WN8334 | D25: 728 | E25: RMC 25 | F25: CUM | H25: 7 | L25: =H25*365 -> 2555 | M25: 2551 | N25: =M25-L25 -> -4 | O25: 0.077777778 | P25: 0.09375 | Q25: TOWER-E (23-43) | R25: RAFT | S25: SHUBHAM
A26: 23 | B26: 30.05.2025 | C26: UP32WN8332 | D26: 729 | E26: RMC 25 | F26: CUM | H26: 7 | L26: =H26*365 -> 2555 | M26: 2557 | N26: =M26-L26 -> 2 | O26: 0.096527778 | P26: 0.10625 | Q26: TOWER-E (23-43) | R26: RAFT | S26: SHUBHAM
A27: 24 | B27: 30.05.2025 | C27: UP32WN8333 | D27: 730 | E27: RMC 25 | F27: CUM | H27: 7 | L27: =H27*365 -> 2555 | M27: 2557 | N27: =M27-L27 -> 2 | O27: 0.10763889 | P27: 0.12708333 | Q27: TOWER-E (23-43) | R27: RAFT | S27: SHUBHAM
A28: 25 | B28: 30.05.2025 | C28: UP32VN6144 | D28: 731 | E28: RMC 25 | F28: CUM | H28: 7 | L28: =H28*365 -> 2555 | M28: 2561 | N28: =M28-L28 -> 6 | O28: 0.12708333 | P28: 0.14097222 | Q28: TOWER-E (23-43) | R28: RAFT | S28: SHUBHAM
A29: 26 | B29: 30.05.2025 | C29: UP53HT5032 | D29: 732 | E29: RMC 25 | F29: CUM | H29: 7 | L29: =H29*365 -> 2555 | M29: 2560 | N29: =M29-L29 -> 5 | O29: 0.14305556 | P29: 0.15833333 | Q29: TOWER-E (23-43) | R29: RAFT | S29: SHUBHAM
A30: 27 | B30: 30.05.2025 | C30: UP32VN6145 | D30: 733 | E30: RMC 25 | F30: CUM | H30: 7 | L30: =H30*365 -> 2555 | M30: 2570 | N30: =M30-L30 -> 15 | O30: 0.16180556 | P30: 0.17083333 | Q30: TOWER-E (23-43) | R30: RAFT | S30: SHUBHAM
... A238: 235 | B238: 14.06.2025 | C238: UP70QT2013 | D238: 905350139 | E238: RMC 25 | F238: CUM | H238: 7 | L238: =H238*365 -> 2555 | M238: 2555 | N238: =M238-L238 -> 0 | O238: 0.72222222 | P238: 0.75694444 | Q238: TOWER-E (1-23) | R238: RAFT | S238: ULTRATECH
A239: 236 | B239: 45830 | C239: UP70QT2341 | D239: 905350161 | E239: RMC 35 | F239: CUM | J239: 3 | L239: =J239*415 -> 1245 | M239: =L239 -> 1245 | N239: =M239-L239 -> 0 | Q239: TOWER-E (1-43) | R239: PADESTIAL | S239: ULTRATECH
A240: 237 | B240: 45831 | C240: UP70QT2013 | D240: 905350165 | E240: RMC 35 | F240: CUM | J240: 4 | L240: =J240*415 -> 1660 | M240: =L240 -> 1660 | N240: =M240-L240 -> 0 | Q240: TOWER-E (1-43) | R240: PADESTIAL | S240: ULTRATECH
A241: 238 | B241: 45832 | C241: UP70QT2342 | D241: 905350166 | E241: RMC 35 | F241: CUM | J241: 5 | L241: =J241*415 -> 2075 | M241: =L241 -> 2075 | N241: =M241-L241 -> 0 | Q241: TOWER-E (1-43) | R241: PADESTIAL | S241: ULTRATECH
A242: 239 | B242: 45833 | C242: UP70QT2342 | D242: 905350167 | E242: RMC 35 | F242: CUM | J242: 5 | L242: =J242*415 -> 2075 | M242: =L242 -> 2075 | N242: =M242-L242 -> 0 | Q242: TOWER-E (1-43) | R242: PADESTIAL | S242: ULTRATECH
A243: 240 | B243: 45834 | C243: UP70QT2014 | D243: 905350168 | E243: RMC 35 | F243: CUM | J243: 6 | L243: =J243*415 -> 2490 | M243: =L243 -> 2490 | N243: =M243-L243 -> 0 | Q243: TOWER-E (1-43) | R243: PADESTIAL | S243: ULTRATECH
A244: 241 | B244: 45835 | C244: UP70QT2342 | D244: 905350171 | E244: RMC 35 | F244: CUM | J244: 4 | L244: =J244*415 -> 1660 | M244: =L244 -> 1660 | N244: =M244-L244 -> 0 | Q244: TOWER-E (1-43) | R244: PADESTIAL | S244: ULTRATECH
A245: 242 | B245: 45837 | C245: UP70QT2014 | D245: 905350190 | E245: RMC 35 | F245: CUM | J245: 3 | L245: =J245*415 -> 1245 | M245: =L245 -> 1245 | N245: =M245-L245 -> 0 | Q245: TOWER-E (1-43) | R245: PADESTIAL | S245: ULTRATECH
A246: 243 | B246: 45839 | C246: 9655 | D246: 563 | E246: RMC 35 | F246: CUM | J246: 4 | L246: =J246*415 -> 1660 | M246: =L246 -> 1660 | N246: =M246-L246 -> 0 | Q246: TOWER-E (1-43) | R246: PADESTIAL | S246: SRIJAN
A247: 244 | B247: 45839 | C247: UP70NT8336 | D247: 564 | E247: RMC 35 | F247: CUM | J247: 4 | L247: =J247*415 -> 1660 | M247: =L247 -> 1660 | N247: =M247-L247 -> 0 | Q247: TOWER-E (1-43) | R247: PADESTIAL | S247: SRIJAN
...

Sheet CONCRETE WORK MB
A1: COMPANY- OMAXE PANCHAM REALCON PVT LTD
A2: PROJECT- TOWER-E
A3: LOCATION- NAINI, PRAYAGRAJ
A4: MB SHEET- CONCRETE WORK
A6: S.NO. | B6: DESCRIPTION | C6: UNIT | D6: NOS | E6: NOS | F6: MEASUREMENT | I6: QTY. | J6: REMARKS
F7: L | G7: B | H7: H/T
B8: RAFT PCC- M10 BELOW PLINTH BEAM
A9: 1 | B9: GRID (22'-43'/A-Q') | C9: CUM | D9: 1 | E9: 1 | F9: =31.935+0.115+0.115 -> 32.165 | G9: =36.895+0.115+0.115 -> 37.125 | H9: 0.1 | I9: =PRODUCT(D9:H9) -> 119.41256 | J9: 3rd RA
A10: 2 | C10: CUM | D10: 1 | E10: 1 | F10: =8.78+0.115+0.115 -> 9.01 | G10: 0.515 | H10: 0.1 | I10: =PRODUCT(D10:H10) -> 0.464015
A11: 3 | B11: GRID (22'-26'/M'-Q') | C11: CUM | D11: -1 | E11: 1 | F11: 11.005 | G11: 12.415 | H11: 0.1 | I11: =PRODUCT(D11:H11) -> -13.662707
A12: 4 | B12: GRID (38'-43'/A-E') | C12: CUM | D12: -1 | E12: 1 | F12: 11.09 | G12: 10.285 | H12: 0.1 | I12: =PRODUCT(D12:H12) -> -11.406065
A13: 5 | B13: GRID (22'-30'/A-B') | C13: CUM | D13: -1 | E13: 1 | F13: 11.285 | G13: 3.72 | H13: 0.1 | I13: =PRODUCT(D13:H13) -> -4.19802
A14: 6 | C14: CUM | D14: -1 | E14: 1 | F14: 1.695 | G14: 2.315 | H14: 0.1 | I14: =PRODUCT(D14:H14) -> -0.3923925
A15: 7 | C15: CUM | D15: -1 | E15: 1 | F15: 3.95 | G15: 1.5 | H15: 0.1 | I15: =PRODUCT(D15:H15) -> -0.5925
D16: -1 | E16: 1 | F16: 15.8 | G16: =0.115 -> 0.115 | H16: 0.1 | I16: =PRODUCT(D16:H16) -> -0.1817
A17: 8 | B17: EXISTING RAFT (DETAILS IN JMR) | C17: CUM | D17: -1 | E17: 1 | F17: 9 | G17: =5.8+0.115 -> 5.915 | H17: 0.1 | I17: =PRODUCT(D17:H17) -> -5.3235
A18: 9 | C18: CUM | D18: -1 | E18: 1 | F18: 19.05 | G18: 10 | H18: 0.1 | I18: =PRODUCT(D18:H18) -> -19.05
A19: 10 | C19: CUM | D19: -1 | E19: 1 | F19: 6.2 | G19: 6.2 | H19: 0.1 | I19: =PRODUCT(D19:H19) -> -3.844
A20: 11 | C20: CUM | D20: -1 | E20: 1 | F20: =11.7-6.2 -> 5.5 | G20: 8.05 | H20: 0.1 | I20: =PRODUCT(D20:H20) -> -4.4275
H22: TOTAL | I22: =SUM(I8:I21) -> 56.798193
A23: 1 | B23: GRID (5'-20/A-C') (DETAILS IN JMR) | C23: CUM | D23: 1 | E23: 1 | F23: 3 | G23: 1.5 | H23: 0.1 | I23: =PRODUCT(D23:H23) -> 0.45 | J23: 4th RA
A24: 2 | C24: CUM | D24: 1 | E24: 1 | F24: 5.875 | G24: 1.5 | H24: 0.1 | I24: =PRODUCT(D24:H24) -> 0.88125
A25: 3 | C25: CUM | D25: 1 | E25: 1 | F25: 9.825 | G25: 0.815 | H25: 0.1 | I25: =PRODUCT(D25:H25) -> 0.8007375
A26: 4 | C26: CUM | D26: 1 | E26: 1 | F26: 11.52 | G26: 1.405 | H26: 0.1 | I26: =PRODUCT(D26:H26) -> 1.61856
A27: 5 | C27: CUM | D27: 1 | E27: 1 | F27: 16.5 | G27: 1 | H27: 0.1 | I27: =PRODUCT(D27:H27) -> 1.65
A28: 6 | B28: GRID (1-18/M'-Q') (DETAILS IN JMR) | C28: CUM | D28: 1 | E28: 1 | F28: 11.03 | G28: 8.67 | H28: 0.1 | I28: =PRODUCT(D28:H28) -> 9.56301
A29: 7 | C29: CUM | D29: 1 | E29: 1 | F29: 11.545 | G29: 2.715 | H29: 0.1 | I29: =PRODUCT(D29:H29) -> 3.1344675
A30: 8 | C30: CUM | D30: 1 | E30: 1 | F30: 6.065 | G30: 2.515 | H30: 0.1 | I30: =PRODUCT(D30:H30) -> 1.5253475
A31: 9 | C31: CUM | D31: 1 | E31: 1 | F31: 1.05 | G31: 2 | H31: 0.1 | I31: =PRODUCT(D31:H31) -> 0.21
A32: 10 | C32: CUM | D32: 1 | E32: 1 | F32: 8.67 | G32: 3.27 | H32: 0.1 | I32: =PRODUCT(D32:H32) -> 2.83509
H34: TOTAL | I34: =SUM(I23:I33) -> 22.668463
A36: S.NO. | B36: DESCRIPTION | C36: UNIT | D36: NOS | E36: NOS | F36: MEASUREMENT | I36: QTY. | J36: REMARKS
F37: L | G37: B | H37: H/T
B38: RAFT RCC- M25 BELOW PLINTH BEAM
A39: 1 | B39: GRID (22'-43'/A-Q') | C39: CUM | D39: 1 | E39: 1 | F39: =31.935 -> 31.935 | G39: =36.895 -> 36.895 | H39: 0.85 | I39: =PRODUCT(D39:H39) -> 1001.5056 | J39: 3rd RA
A40: 2 | C40: CUM | D40: 1 | E40: 1 | F40: =8.78 -> 8.78 | G40: 0.515 | H40: 0.85 | I40: =PRODUCT(D40:H40) -> 3.843445
A41: 3 | B41: GRID (22'-26'/M'-Q') | C41: CUM | D41: -1 | E41: 1 | F41: 11.005 | G41: 12.415 | H41: 0.85 | I41: =PRODUCT(D41:H41) -> -116.13301
A42: 4 | B42: GRID (38'-43'/A-E') | C42: CUM | D42: -1 | E42: 1 | F42: 11.09 | G42: 10.285 | H42: 0.85 | I42: =PRODUCT(D42:H42) -> -96.951552
A43: 5 | B43: GRID (22'-30'/A-B') | C43: CUM | D43: -1 | E43: 1 | F43: 11.285 | G43: 3.72 | H43: 0.85 | I43: =PRODUCT(D43:H43) -> -35.68317
A44: 6 | C44: CUM | D44: -1 | E44: 1 | F44: 1.695 | G44: 2.315 | H44: 0.85 | I44: =PRODUCT(D44:H44) -> -3.3353363
...

Sheet SHUTT. WORK SUMMARY
A1: TOWER-E CENTERING & SHUTTERING WORK SUMMARY
D2: QTY | M2: TOTAL
A3: 3 | B3: CENTRING AND SHUTTERING | D3: 3rd RA | E3: 4th RA | F3: 5th RA | G3: 6th RA | H3: 7th RA | I3: 8th RA | J3: 9th RA
B4: Providing and fixing plywood or steel plate shuttering and centring for structural concrete work in locations called for including strutting, propping, bracing, bolting, wedging, casing, striking, removal etc. complete for any size, section, thickness. Props shall consist of well designed steel pipes adequately braced (wooden ballies as props shall not be permitted). The item to include centering and shuttering at all heights and levels. Allow for forming grooves, drip course, chamfers, cut-outs, openings etc. where called for and for dressing with approved shuttering oil to prevent adhesion. Unexposed concrete surfaces subsequently left untreated (in the condition obtained on removal of form work) shall not constitute exposed concrete work and shall be measured under this item only Irregular shapes with sides (like circular, semi-circular, oval etc.) which may not be perpendicular to each other for shapes not conforming to rectangle or square, and circular shuttering shall not be paid separately. Joints of soffits of the slab shall be made clean after concreting and de-shuttering. (quoted rate to include all staging upto 3.50 mtr height). Note:- Contractor shall take necessary precautions such as watertight shuttering. This is inclusive of RCC members, leaving shuttering & centring for pour strip, slab in slope, RCC members in curved (in plan), etc., nothing is payable extra on this account.
A5: 3.1.1. | B5: Foundation, column footings, raft slab, raft beams, plinth beam, lift pits, sump pits, pedestals / bases of column, column up to plinth, swimming pool, Retaining wall foundations, grade slab etc. | C5: SQM | D5: 93.6125 | E5: 82.707 | F5: 619.2036 | H5: 849.97425 | M5: =SUM(D5:L5) -> 1645.4974
A6: 3.1.2. | B6: Suspended floors, roofs, balconies, shelves/ counters, stair waist slabs, folded plate stairs and landings, swimming pool slab, lintel and floor beams, landing beams, girders (deep beams), RCC bands, swimming pool beam, cantilever projections, coping, cills, slab of tank etc at all levels.
A7: 3.1.2.1. | B7: Stilt Floor level to 7th Floor level | C7: SQM | I7: =+'SHUTTERING WORK MB'!I802 -> 1195.8149 | J7: ='SHUTTERING WORK MB'!I1243 -> 1195.8149 | M7: =SUM(D7:L7) -> 2391.6299
