Workbook
Name \0: #REF!
Name \0: #REF!
Name \B: #REF!
Name \B: #REF!
Name \C: #REF!
Name \C: #REF!
Name \G: #REF!
Name \I: #REF!
Name \M: #REF!
Name \O: #REF!
Name \P: #REF!
Name \Q: #REF!
Name \R: #REF!
Name \S: #REF!
Name __aoc10: #N/A
Name __aoc11: #REF!
Name __aoc11: #REF!
Name __aoc11: #REF!
Name __aoc7: #REF!
Name __aoc7: #REF!
Name __aoc7: #REF!
Name __aoc8: #REF!
Name __aoc8: #REF!
Name __aoc9: #REF!
Name __aoc9: #REF!
Name __ERA1: #REF!
Name __ERA1: #REF!
Name __ERA10: #REF!
Name __ERA10: #REF!
Name __ERA11: #REF!
Name __ERA11: #REF!
Name __ERA2: #REF!
Name __ERA3: #REF!
Name __ERA5: #REF!
Name __ERA5: #REF!
Name __ERA9: #REF!
Name __ERA9: #REF!
Name __HED1: #REF!
Name __HED1: #REF!
Name __HED2: #REF!
Name __HED2: #REF!
Name __vut02533: #REF!
Name __vut02533: #REF!
Name __vut02533: #REF!
Name __xlnm.Print_Area: "$#REF!.$A$2:$I$161"
Name __xlnm.Print_Area_1: #REF!
Name __xlnm.Print_Area_1: #REF!
Name __xlnm.Print_Area_1: #REF!
Name __xlnm.Print_Area_10: #REF!
Name __xlnm.Print_Area_10: #REF!
Name __xlnm.Print_Area_11: #REF!
Name __xlnm.Print_Area_11: #REF!
Name __xlnm.Print_Area_12: #REF!
Name __xlnm.Print_Area_12: #REF!
Name __xlnm.Print_Area_13: #REF!
Name __xlnm.Print_Area_13: #REF!
Name __xlnm.Print_Area_14: #REF!
Name __xlnm.Print_Area_14: #REF!
Name __xlnm.Print_Area_15: #REF!
Name __xlnm.Print_Area_15: #REF!

Sheet TOP SHEET
A1: OMAXE LTD. | F1: Tracker NO | G1: Office NO
A2: NAME OF PROJECT : OMAXE ANANDA TOWER-E (Location: Tower-E STILT + 14 FLOORS) | E2: CONTRACT VALUE ; | G2: =+ABSTRACT!F108 -> 162074375
A3: NATURE OF WORK : CIVIL STRUCTURE WORK | E3: PROGRESS OF WORK: | G3: =D11/G2 -> 0.035935252
A4: NAME OF THE CONTRACTOR :- M/s MARCO-ENTERPRISES | E4: VENDOR CODE:
A5: WORK ORDER NO. & DATE : OPRL/ATE/11094106758 (14 FEB, 2025) | E5: DATE OF START: 01.MAY.2025
A6: THIS R/A BILL NO. & DATE : 3RD RA BILL, DATE 07-06-2025 | E6: COMPLETION PERIOD : Upto 31-Aug-2026 (18 Months)
A7: PERIOD OF BILL :- FROM 01-05-2025 TO 31-05-2025 | E7: GST No. : 09BLDPK5228HIZ2
A8: ERP PROJECT CODE : 127018 | E8: PAN NO. : BLDPK5228H
A9: DATE OF BILL REC. AT SITE :- | C9: DATE OF BILL RECEIVED AT H.O. :- | E9: DATE OF BILL CHECKING AT H.O. :-
A10: S.NO. | B10: PARTICULARS | C10: CLAIMED BY CONTRACTOR | D10: GROSS AMT | E10: PREVIOUS AMT. | F10: THIS BILL AMT | G10: REMARKS
A11: 1 | B11: WORK DONE(CIVIL) | D11: =ABSTRACT!M108 -> 5824183.5 | E11: =ABSTRACT!K108 -> 0 | F11: =+D11-E11 -> 5824183.5 | I11: 5824183.5
A12: 2 | B12: WORK DONE(ELECT/ PLUMBING)
A13: 3 | B13: DIFF. OF CEMENT
A14: 4 | B14: RATE DIFF OF TILES
B15: TOTAL (A) | D15: =SUM(D11:D14) -> 5824183.5 | E15: =SUM(E11:E14) -> 0 | F15: =SUM(F11:F14) -> 5824183.5
A16: 5 | B16: Add GST 18% On (A) | D16: =D15*18% -> 1048353 | E16: =E15*18% -> 0 | F16: =F15*18% -> 1048353
B17: TOTAL (B) | D17: =D16+D15 -> 6872536.5 | E17: =E16+E15 -> 0 | F17: =F16+F15 -> 6872536.5
B18: ADVANCES
A21: 7.1 | B21: Add Mobilization Advance | D21: =+F21+E21 -> 400000 | E21: 400000 | F21: 0
A22: 7.2 | B22: Recover Mobilization Advance | F22: =+D22-E22 -> 0
B23: TOTAL (C) | D23: =SUM(D17:D22) -> 7272536.5 | E23: =SUM(E17:E22) -> 400000 | F23: =SUM(F17:F22) -> 6872536.5
B24: DEDUCTIONS
A25: 8 | B25: SECURITY @ 5 % (ON TOTAL A) | D25: =ROUND(D15*5%,0) -> 291209 | E25: =ROUND(E15*5%,0) -> 0 | F25: =ROUND(F15*5%,0) -> 291209
A26: 9 | B26: TDS @ 1% (ON TOTAL A) | D26: =ROUND((D15+D19+D20+D21)*1%,0) -> 62242 | E26: =ROUND((E15+E19+E20+E21)*1%,0) -> 4000 | F26: =ROUND((F15+F19+F20+F21)*1%,0) -> 58242
B28: TOTAL DEDUCTION (C) | D28: =SUM(D25:D27) -> 353451 | E28: =SUM(E25:E27) -> 4000 | F28: =SUM(F25:F27) -> 349451
A29: 11 | B29: NET PAYABLE AMOUNT (D) | D29: =D23-D28 -> 6919085.5 | E29: =E23-E28 -> 396000 | F29: =F23-F28 -> 6523085.5 | G29: =+G30*0.7 -> 3832312.8
B30: NOW PAYABLE | F30: =F29 -> 6523085.5 | G30: =+F30-F16 -> 5474732.5
B31: PREPARED BY
C32: PRIYANK BARANWAL
C33: MANAGER (BILLING)
C34: 9988294677
B35: ACCOUNT (SITE) | E35: PREVIOUS RA BILL NO:-
C36: ANUP SINGH | E36: PREVIOUS RA GROSS AMOUNT:-
C37: DY. MANAGER
C38: 9315403180
B39: PROJECT INCHARGE {CPC/PC/ASST V.P./SR GM /GM}
E40: S K PANDEY
E41: G.M. - PROJECT
E42: 9711800470
B43: HO BILL MONITORING
...

Sheet ABSTRACT
A1: OMAXE PANCHAM REALCON PVT. LTD.
B2: =+'TOP SHEET'!A5 -> WORK ORDER NO. & DATE : OPRL/ATE/11094106758 (14 FEB, 2025) | J2: =+'TOP SHEET'!A8 -> ERP PROJECT CODE : 127018
B3: =+'TOP SHEET'!A6 -> THIS R/A BILL NO. & DATE : 3RD RA BILL, DATE 07-06-2025 | J3: =+'TOP SHEET'!A9 -> DATE OF BILL REC. AT SITE :-
B4: =+'TOP SHEET'!A3 -> NATURE OF WORK : CIVIL STRUCTURE WORK | J4: =+'TOP SHEET'!A7 -> PERIOD OF BILL :- FROM 01-05-2025 TO 31-05-2025
A5: ABSTRACT OF COST
A6: S.No. | B6: DESCRIPTION OF ITEM | C6: Unit | D6: AS PER W.O. (R0) | H6: Qty | K6: Amount | N6: Executed %
D7: Qty | E7: Rate | F7: Amount | G7: Part Rate | H7: Prev. Bill | I7: This Bill | J7: UpTo Date | K7: Prev. Bill | L7: This Bill | M7: UpTo Date
A8: 1 | B8: EARTH WORK
A9: 1.1. | B9: Earth work in excavation in foundation trenches, column pits, plinth beam, under grade/ raft slab etc. by mechanical and/or manual means up to a depth of 1.5 mtr in soil from existing excavated soil level, stacking/spreading the excavated material within site premises (within a stretch of 1500 M) as per direction of Project Manager including dressing of bottom, sides strutting, timbering, shoring, trimming of sides, all leads and lifts, bailing or pumping out the water from the excavated areas collected from any source including subsoil water and keeping the excavated surface dry for subsequent works incidentals, etc. complete with ramming of bottom, surface preparation as per specifications to receive the PCC. | C9: CUM | D9: 1000 | E9: 120 | F9: =$D9*E9 -> 120000 | I9: =J9-H9 -> 0 | L9: =M9-K9 -> 0 | M9: =E9*J9 -> 0 | N9: =J9/D9 -> 0
B10: Excavation shall be payable only for vertical cut up to the outer edge of foundation lean concrete as indicated in drawings for all depths. Cost of extra excavation required for working space, supporting side shuttering of foundations and retaining walls, planking, dewatering, strutting etc. and that required for making slopes for stability of excavation shall be deemed to be included in the rate quoted. This item is not for Mass Excavation. | L10: =M10-K10 -> 0 | M10: =E10*J10 -> 0
A11: 1.2. | B11: Prepare the surface for PCC by manual excavation upto 30 cm depth including dressing the surface, ramming the bottom, disposal and spreading of the surplus earth at the specified location within premises including proper levelling, watering and consolidation complete as directed by E I C. (The item shall be measured as per plan area of PCC, Working space shall not be taken into measurement, deemed to be included into rates) (This item is only applicable if excavation item is not being executed by contractor and excavation already done by client for the location) | C11: SQM | D11: 1500 | E11: 65 | F11: =$D11*E11 -> 97500 | G11: =+E11 -> 65 | I11: =J11-H11 -> 906.85293 | J11: ='EARTH WORK MB'!I18 -> 906.85293 | L11: =M11-K11 -> 58945.44 | M11: =G11*J11 -> 58945.44 | N11: =J11/D11 -> 0.60456862
A12: 1.3. | B12: Filling available excavated earth in trenches, plinth, sides of foundations etc. in layers not exceeding 20cm in depth: consolidating each deposited layer by ramming and watering, lead within the premises and upto any depth. (Compacted Volume shall be payable as per drawing) - Actual volume shall be paid incase excavation is done by Client. | C12: CUM | D12: 2400 | E12: 100 | F12: =$D12*E12 -> 240000 | I12: =J12-H12 -> 0 | L12: =M12-K12 -> 0 | M12: =E12*J12 -> 0 | N12: =J12/D12 -> 0
B13: Total of Earthwork | F13: =SUBTOTAL(9,F9:F12) -> 457500
A15: 2 | B15: CONCRETE WORK
B16: Rates for all cement concrete items plain and reinforced described below shall include work from Basement Level to top of last roof including roof of machine room, mumty, over head water tanks and parapets above at all floors and for all heights. The contractor should provide full time sufficient pipes with accessories and pumps based on the site requirement for pumping and laying of concrete as directed by the EIC. The rate inclusive of standard rigid pipe line and its supports, lifting, laying charges, etc., at all heights and levels. No additional payment shall be payable to the contractor on account of using or change in any size of coarse aggregate in PCC/ RCC work at any stage during currency of works. (This section covers cast in situ structural and architectural as well.)
A17: 2.1 | B17: Plain Cement Concrete: Providing and laying plain cement concrete of specified grade as bed concrete under foundation, bases for rafts, underground water tank, building machine equipments, column footing, under floor landings, below road and pathways, cill, coping, screeding at roof to required slope and other locations as called for laid, consolidated and cured etc. complete including finishing the top surface to receive the next course / layer as per specification and drawing. (Shuttering shall be paid in Item No.3.1.1) M10 Grade (Basic Rate of PCC - Rs. 4200/cum) without pump | C17: CUM | D17: 100 | E17: 5550 | F17: =$D17*E17 -> 555000 | G17: 5550 | I17: =J17-H17 -> 56.798193 | J17: ='CONCRETE SUMMARY'!J6 -> 56.798193 | L17: =M17-K17 -> 315229.97 | M17: =G17*J17 -> 315229.97 | N17: =J17/D17 -> 0.56798193
A18: 2.2. | B18: Providing and laying cement concrete 1:2:4 (1 cement : 2 coarse sand : 4 graded stone aggregate 20mm nominal size) for ledge wall below balcony railings, band, mullion, lintel etc. (Shuttering shall be paid separately in respective item) as per drawing and as directed by the Project Manager. | C18: CUM | D18: 50 | E18: 5750 | F18: =$D18*E18 -> 287500 | I18: =J18-H18 -> 0 | J18: ='CONCRETE SUMMARY'!J7 -> 0 | L18: =M18-K18 -> 0 | M18: =E18*J18 -> 0 | N18: =J18/D18 -> 0
A19: 2.3. | B19: Providing and laying damp proof course 40mm thick including shttering with cement concrete 1:2:4 (1 cement : 2 coarse sand : 4 graded stone aggregate 20mm nominal size) including mixing of water proofing compound @ 2% of cement content and applying two layers of bitumen @ 1.70 Kg/Sqm of grade 85/25 and as directed by the Project Manager. | C19: SQM | D19: 200 | E19: 480 | F19: =$D19*E19 -> 96000 | I19: =J19-H19 -> 0 | J19: ='CONCRETE SUMMARY'!J8 -> 0 | L19: =M19-K19 -> 0 | M19: =E19*J19 -> 0 | N19: =J19/D19 -> 0
A21: 2.4. | B21: RCC WORK
B22: Providing & Laying RMC M-25 Grade as per approved design mix concrete (strictly controlled conditions) with flyash (as per approved design mix) with automatic batching plant machine mixed and machine vibrated RCC with melamine based plasticisers etc., upto any level, including finishing the exposed surface, fixing/ removal of pockets, fixing of sleeves and inserts (sleeves provided by client), curing etc complete, as per drawing (including all size and shape like circular, semi-circular, oval etc.) and as directed for all lead and lift, excluding cost of centering, shuttering and steel reinforcement but including cost of making shear keys and provision of construction / contraction / control joints in various locations. Checking from Client should not be considered as final and any defects arising during or after casting should be borne & bear by contractor at his own cost. This is inclusive of leaving shuttering & centring for pour strip, slab in slope, RCC members in curved, etc., nothing is payable extra on this account. RMC (M-25) Basic Rate - Rs. 5200/cum without pump excluding GST
A23: 2.4.1. | B23: Foundation, column footings, raft slab, raft beams, plinth beam, lift pits, sump pits, pedestals / bases of column, column upto plinth, swimming pool, Retaining wall foundations, grade slab etc. | C23: CUM | D23: 2080 | E23: 6600 | F23: =$D23*E23 -> 13728000 | G23: 6600 | I23: =J23-H23 -> 748.20967 | J23: ='CONCRETE SUMMARY'!J12 -> 748.20967 | L23: =M23-K23 -> 4938183.8 | M23: =G23*J23 -> 4938183.8 | N23: =J23/D23 -> 0.35971619
A24: 2.4.2. | B24: Suspended floors, roofs, balconies, shelves/ counters, stair waist slabs, folded plate stairs and landings, swimming pool slab, lintel and floor beams, landing beams, girders (deep beams), RCC bands, swimming pool beam, cantilever projections, coping, cills, slab of tank etc at all levels.
A25: 2.4.2.1. | B25: Stilt Floor level to 7th Floor level | C25: CUM | D25: 2200 | E25: 6550 | F25: =$D25*E25 -> 14410000 | I25: =J25-H25 -> 0 | J25: ='CONCRETE SUMMARY'!J14 -> 0 | L25: =M25-K25 -> 0 | M25: =E25*J25 -> 0 | N25: =J25/D25 -> 0
A26: 2.4.2.2. | B26: 7th Floor level to to Terrace Including OHT, Mumty, Machine Room, Parapet | C26: CUM | D26: 2440 | E26: 6750 | F26: =$D26*E26 -> 16470000 | I26: =J26-H26 -> 0 | J26: ='CONCRETE SUMMARY'!J15 -> 0 | L26: =M26-K26 -> 0 | M26: =E26*J26 -> 0 | N26: =J26/D26 -> 0
A27: 2.4.2.3. | B27: All type of Moulding, Bands, Elevation/Architectural Features as per drawing and as directed by EIC. at all level | C27: CUM | D27: 70 | E27: 7300 | F27: =$D27*E27 -> 511000 | I27: =J27-H27 -> 0 | J27: ='CONCRETE SUMMARY'!J16 -> 0 | L27: =M27-K27 -> 0 | M27: =E27*J27 -> 0 | N27: =J27/D27 -> 0
A29: 2.5. | B29: Columns, Wall, pillars, piers, abutments, posts and struts, offset and projection of columns, water tank walls, lift walls, Retaining Wall, swimming pool, Parapets, planters, vertical projection of pergolas, wall and ramp walls etc. at all levels.
A30: 2.5.1. | B30: Stilt Floor level to 7th Floor level | C30: CUM | D30: 860 | E30: 6850 | F30: =$D30*E30 -> 5891000 | I30: =J30-H30 -> 0 | J30: ='CONCRETE SUMMARY'!J19 -> 0 | L30: =M30-K30 -> 0 | M30: =E30*J30 -> 0 | N30: =J30/D30 -> 0
A31: 2.5.2. | B31: 7th Floor level to to Terrace Including OHT, Mumty, Machine Room, Parapet | C31: CUM | D31: 950 | E31: 7050 | F31: =$D31*E31 -> 6697500 | I31: =J31-H31 -> 0 | J31: ='CONCRETE SUMMARY'!J20 -> 0 | L31: =M31-K31 -> 0 | M31: =E31*J31 -> 0 | N31: =J31/D31 -> 0
A32: 2.5.3. | B32: All type of Moulding, Bands, Elevation/Architectural Features as per drawing and as directed by EIC. at all level | C32: CUM | D32: 30 | E32: 7650 | F32: =$D32*E32 -> 229500 | I32: =J32-H32 -> 0 | J32: ='CONCRETE SUMMARY'!J21 -> 0 | L32: =M32-K32 -> 0 | M32: =E32*J32 -> 0 | N32: =J32/D32 -> 0
A33: 2.5.4. | B33: Finishing vaccum dewatering continuous concrete flooring 100-150 mm thick with specified grade concrete including necessary formwork in required level, vibrating concrete both by poker vibrators / leveling vaccum processing of the concrete and planning the surface by skin powered floater trowels with broom/plain finish including groove cutting & filling etc. complete. (Concrete shall be paid in the respective items above). | C33: SQM | D33: 1625 | E33: 100 | F33: =$D33*E33 -> 162500 | J33: ='CONCRETE SUMMARY'!J22 -> 0
B35: Total of RCC Work | F35: =SUBTOTAL(9,F17:F34) -> 59038000
A37: 3 | B37: CENTRING AND SHUTTERING
B38: Providing and fixing plywood or steel plate shuttering and centring for structural concrete work in locations called for including strutting, propping, bracing, bolting, wedging, casing, striking, removal etc. complete for any size, section, thickness. Props shall consist of well designed steel pipes adequately braced (wooden ballies as props shall not be permitted). The item to include centering and shuttering at all heights and levels. Allow for forming grooves, drip course, chamfers, cut-outs, openings etc. where called for and for dressing with approved shuttering oil to prevent adhesion. Unexposed concrete surfaces subsequently left untreated (in the condition obtained on removal of form work) shall not constitute exposed concrete work and shall be measured under this item only Irregular shapes with sides (like circular, semi-circular, oval etc.) which may not be perpendicular to each other for shapes not conforming to rectangle or square, and circular shuttering shall not be paid separately. Joints of soffits of the slab shall be made clean after concreting and de-shuttering. (quoted rate to include all staging upto 3.50 mtr height). Note:- Contractor shall take necessary precautions such as watertight shuttering. This is inclusive of RCC members, leaving shuttering & centring for pour strip, slab in slope, RCC members in curved (in plan), etc., nothing is payable extra on this account.
A39: 3.1.1. | B39: Foundation, column footings, raft slab, raft beams, plinth beam, lift pits, sump pits, pedestals / bases of column, column up to plinth, swimming pool, Retaining wall foundations, grade slab etc. | C39: SQM | D39: 2150 | E39: 360 | F39: =$D39*E39 -> 774000 | G39: =+E39 -> 360 | I39: =J39-H39 -> 90.1365 | J39: ='SHUTT. WORK SUMMARY'!J5 -> 90.1365 | L39: =M39-K39 -> 32449.14 | M39: =G39*J39 -> 32449.14 | N39: =J39/D39 -> 0.041923953
A40: 3.1.2. | B40: Suspended floors, roofs, balconies, shelves/ counters, stair waist slabs, folded plate stairs and landings, swimming pool slab, lintel and floor beams, landing beams, girders (deep beams), RCC bands, swimming pool beam, cantilever projections, coping, cills, slab of tank etc at all levels.
A41: 3.1.2.1. | B41: Stilt Floor level to 7th Floor level | C41: SQM | D41: 17600 | E41: 465 | F41: =$D41*E41 -> 8184000 | I41: =J41-H41 -> 0 | J41: ='SHUTT. WORK SUMMARY'!J7 -> 0 | L41: =M41-K41 -> 0 | M41: =E41*J41 -> 0 | N41: =J41/D41 -> 0
A42: 3.1.2.2. | B42: 7th Floor level to to Terrace Including OHT, Mumty, Machine Room, Parapet | C42: SQM | D42: 18800 | E42: 485 | F42: =$D42*E42 -> 9118000 | I42: =J42-H42 -> 0 | J42: ='SHUTT. WORK SUMMARY'!J8 -> 0 | L42: =M42-K42 -> 0 | M42: =E42*J42 -> 0 | N42: =J42/D42 -> 0
A43: 3.1.2..3 | B43: All type of Moulding, Bands, Elevation/Architectural Features as per drawing and as directed by EIC. at all level | C43: SQM | D43: 400 | E43: 550 | F43: =$D43*E43 -> 220000 | I43: =J43-H43 -> 0 | J43: ='SHUTT. WORK SUMMARY'!J9 -> 0 | L43: =M43-K43 -> 0 | M43: =E43*J43 -> 0 | N43: =J43/D43 -> 0
L44: =M44-K44 -> 0 | M44: =E44*J44 -> 0
A45: 3.2. | B45: Columns, Wall, pillars, piers, abutments, posts and struts, offset and projection of columns, water tank walls, lift walls, Retaining Wall, swimming pool, Parapets, planters, vertical projection of pergolas, wall and ramp walls etc. at all levels.
...

Sheet EARTH WORK MB
A1: COMPANY- OMAXE PANCHAM REALCON PVT LTD
A2: PROJECT- TOWER-E
A3: LOCATION- NAINI, PRAYAGRAJ
A4: MB SHEET- SOIL SURFACE DRESSING BELOW PLINTH BEAM
A6: S.NO. | B6: DESCRIPTION | C6: UNIT | D6: NOS | E6: NOS | F6: MEASUREMENT | I6: QTY. | J6: REMARKS
F7: L | G7: B | H7: H/T
B8: SOIL DRESSING FOR RAFT PCC
A9: 1 | B9: GRID (22'-43'/A-Q') | C9: SQM | D9: 1 | E9: 1 | F9: =31.935+0.115+0.115+0.1+0.1 -> 32.365 | G9: =36.895+0.115+0.1+0.115+0.1 -> 37.325 | I9: =PRODUCT(D9:H9) -> 1208.0236
A10: 2 | C10: SQM | D10: 1 | E10: 1 | F10: =8.78+0.115+0.115+0.1+0.1 -> 9.21 | G10: 0.515 | I10: =PRODUCT(D10:H10) -> 4.74315
A11: 3 | B11: GRID (22'-26'/M'-Q') | C11: SQM | D11: -1 | E11: 1 | F11: 11.005 | G11: 12.415 | I11: =PRODUCT(D11:H11) -> -136.62707
A12: 4 | B12: GRID (38'-43'/A-E') | C12: SQM | D12: -1 | E12: 1 | F12: 11.09 | G12: 10.285 | I12: =PRODUCT(D12:H12) -> -114.06065
A13: 5 | B13: GRID (22'-30'/A-B') | C13: SQM | D13: -1 | E13: 1 | F13: 11.285 | G13: =1.405+0.815+1.5 -> 3.72 | I13: =PRODUCT(D13:H13) -> -41.9802
A14: 6 | C14: SQM | D14: -1 | E14: 1 | F14: 1.695 | G14: =0.815+1.5 -> 2.315 | I14: =PRODUCT(D14:H14) -> -3.923925
A15: 7 | C15: SQM | D15: -1 | E15: 1 | F15: 3.95 | G15: 1.5 | I15: =PRODUCT(D15:H15) -> -5.925
A16: 8 | C16: SQM | D16: -1 | E16: 1 | F16: 15.8 | G16: =0.115+0.1 -> 0.215 | I16: =PRODUCT(D16:H16) -> -3.397
H18: TOTAL | I18: =SUM(I8:I17) -> 906.85293

Sheet CONCRETE SUMMARY
A2: TOWER-E CONCRETE WORK SUMMARY
D3: QTY | J3: TOTAL
A4: 2 | B4: CONCRETE WORK | D4: 1ST RA | E4: 2ND RA | F4: 3rd RA | G4: 4th RA | H4: 5th RA | I4: 6th RA
B5: Rates for all cement concrete items plain and reinforced described below shall include work from Basement Level to top of last roof including roof of machine room, mumty, over head water tanks and parapets above at all floors and for all heights. The contractor should provide full time sufficient pipes with accessories and pumps based on the site requirement for pumping and laying of concrete as directed by the EIC. The rate inclusive of standard rigid pipe line and its supports, lifting, laying charges, etc., at all heights and levels. No additional payment shall be payable to the contractor on account of using or change in any size of coarse aggregate in PCC/ RCC work at any stage during currency of works. (This section covers cast in situ structural and architectural as well.)
A6: 2.1 | B6: Plain Cement Concrete: Providing and laying plain cement concrete of specified grade as bed concrete under foundation, bases for rafts, underground water tank, building machine equipments, column footing, under floor landings, below road and pathways, cill, coping, screeding at roof to required slope and other locations as called for laid, consolidated and cured etc. complete including finishing the top surface to receive the next course / layer as per specification and drawing. (Shuttering shall be paid in Item No.3.1.1) M10 Grade (Basic Rate of PCC - Rs. 4200/cum) without pump | C6: CUM | D6: ='CONCRETE WORK MB'!I23 -> 56.798193 | J6: =SUM(D6:I6) -> 56.798193
A7: 2.2. | B7: Providing and laying cement concrete 1:2:4 (1 cement : 2 coarse sand : 4 graded stone aggregate 20mm nominal size) for ledge wall below balcony railings, band, mullion, lintel etc. (Shuttering shall be paid separately in respective item) as per drawing and as directed by the Project Manager. | C7: CUM | J7: =SUM(D7:I7) -> 0
A8: 2.3. | B8: Providing and laying damp proof course 40mm thick including shttering with cement concrete 1:2:4 (1 cement : 2 coarse sand : 4 graded stone aggregate 20mm nominal size) including mixing of water proofing compound @ 2% of cement content and applying two layers of bitumen @ 1.70 Kg/Sqm of grade 85/25 and as directed by the Project Manager. | C8: SQM | J8: =SUM(D8:I8) -> 0
A10: 2.4. | B10: RCC WORK
B11: Providing & Laying RMC M-25 Grade as per approved design mix concrete (strictly controlled conditions) with flyash (as per approved design mix) with automatic batching plant machine mixed and machine vibrated RCC with melamine based plasticisers etc., upto any level, including finishing the exposed surface, fixing/ removal of pockets, fixing of sleeves and inserts (sleeves provided by client), curing etc complete, as per drawing (including all size and shape like circular, semi-circular, oval etc.) and as directed for all lead and lift, excluding cost of centering, shuttering and steel reinforcement but including cost of making shear keys and provision of construction / contraction / control joints in various locations. Checking from Client should not be considered as final and any defects arising during or after casting should be borne & bear by contractor at his own cost. This is inclusive of leaving shuttering & centring for pour strip, slab in slope, RCC members in curved, etc., nothing is payable extra on this account. RMC (M-25) Basic Rate - Rs. 5200/cum without pump excluding GST
A12: 2.4.1. | B12: Foundation, column footings, raft slab, raft beams, plinth beam, lift pits, sump pits, pedestals / bases of column, column upto plinth, swimming pool, Retaining wall foundations, grade slab etc. | C12: CUM | D12: ='CONCRETE WORK MB'!I37 -> 748.20967 | J12: =SUM(D12:I12) -> 748.20967
A13: 2.4.2. | B13: Suspended floors, roofs, balconies, shelves/ counters, stair waist slabs, folded plate stairs and landings, swimming pool slab, lintel and floor beams, landing beams, girders (deep beams), RCC bands, swimming pool beam, cantilever projections, coping, cills, slab of tank etc at all levels.
A14: 2.4.2.1. | B14: Stilt Floor level to 7th Floor level | C14: CUM | J14: =SUM(D14:I14) -> 0
A15: 2.4.2.2. | B15: 7th Floor level to to Terrace Including OHT, Mumty, Machine Room, Parapet | C15: CUM | J15: =SUM(D15:I15) -> 0
A16: 2.4.2.3. | B16: All type of Moulding, Bands, Elevation/Architectural Features as per drawing and as directed by EIC. at all level | C16: CUM | J16: =SUM(D16:I16) -> 0
A18: 2.5. | B18: Columns, Wall, pillars, piers, abutments, posts and struts, offset and projection of columns, water tank walls, lift walls, Retaining Wall, swimming pool, Parapets, planters, vertical projection of pergolas, wall and ramp walls etc. at all levels.
A19: 2.5.1. | B19: Stilt Floor level to 7th Floor level | C19: CUM | J19: =SUM(D19:I19) -> 0
A20: 2.5.2. | B20: 7th Floor level to to Terrace Including OHT, Mumty, Machine Room, Parapet | C20: CUM | J20: =SUM(D20:I20) -> 0
A21: 2.5.3. | B21: All type of Moulding, Bands, Elevation/Architectural Features as per drawing and as directed by EIC. at all level | C21: CUM | J21: =SUM(D21:I21) -> 0
A22: 2.5.4. | B22: Finishing vaccum dewatering continuous concrete flooring 100-150 mm thick with specified grade concrete including necessary formwork in required level, vibrating concrete both by poker vibrators / leveling vaccum processing of the concrete and planning the surface by skin powered floater trowels with broom/plain finish including groove cutting & filling etc. complete. (Concrete shall be paid in the respective items above). | C22: SQM | J22: =SUM(D22:I22) -> 0
I24: TOTAL | J24: =SUM(J5:J23) -> 805.00787

Sheet CONCRETE RECO.
B1: RCC SUMMARY : OMAXE TOWER-E
B2: M/s. MARCO ENTERPRISES
A3: S.No. | B3: Item Discription | C3: Grade | D3: Floor Name | E3: NO | F3: Unit Qty. | G3: Quantity | H3: Unit | I3: M10 | J3: M25 | K3: M30 | L3: M35
B4: TOWER-E
A6: 1 | B6: RAFT PCC GRID (A-Q/23-43) | C6: M10 | D6: AS SUB-STRUCTURE | E6: 1 | F6: ='CONCRETE WORK MB'!I23 -> 56.798193 | G6: =E6*F6 -> 56.798193 | H6: Cum | I6: =IF(I$3=$C6,$G6,"-") -> 56.798193 | J6: =IF(J$3=$C6,$G6,"-") -> - | K6: =IF(K$3=$C6,$G6,"-") -> - | L6: =IF(L$3=$C6,$G6,"-") -> -
A7: 2 | B7: RAFT RCC GRID (A-Q/23-43) | C7: M25 | D7: AS SUB-STRUCTURE | E7: =E6 -> 1 | F7: ='CONCRETE WORK MB'!I37 -> 748.20967 | G7: =E7*F7 -> 748.20967 | H7: Cum | I7: =IF(I$3=$C7,$G7,"-") -> - | J7: =IF(J$3=$C7,$G7,"-") -> 748.20967 | K7: =IF(K$3=$C7,$G7,"-") -> - | L7: =IF(L$3=$C7,$G7,"-") -> -
I8: =IF(I$3=$C8,$G8,"-") -> -
B12: TOTAL RCC QTY (THEORITICAL) | G12: =SUM(G4:G11) -> 805.00787 | H12: Cum | I12: =SUM(I4:I11) -> 56.798193 | J12: =SUM(J4:J11) -> 748.20967 | K12: =SUM(K4:K11) -> 0 | L12: =SUM(L4:L11) -> 0
B13: TOTAL RCC QTY (CASTING) | G13: ='PCC & RCC REC.'!Q16 -> 829.2 | H13: Cum | I13: ='PCC & RCC REC.'!D18+'PCC & RCC REC.'!H18+'PCC & RCC REC.'!L18 -> 66.2 | J13: ='PCC & RCC REC.'!E18+'PCC & RCC REC.'!I18+'PCC & RCC REC.'!M18 -> 763 | K13: ='PCC & RCC REC.'!F18+'PCC & RCC REC.'!J18+'PCC & RCC REC.'!N18 -> 0 | L13: ='PCC & RCC REC.'!G18+'PCC & RCC REC.'!K18+'PCC & RCC REC.'!O18 -> 0
B14: DIFFERENCE (WASTAGE) | G14: =G12-G13 -> -24.192134 | H14: Cum | I14: =I12-I13 -> -9.4018075 | J14: =J12-J13 -> -14.790326 | K14: =K12-K13 -> 0 | L14: =L13-L12 -> 0
B15: WASTAGE % | G15: =G14/G12 -> -0.030052046 | I15: =I14/I12 -> -0.16553005 | J15: =J14/J12 -> -0.019767622 | K15: =K14/K12 -> #DIV/0! | L15: =L14/L12 -> #DIV/0!
B17: PREV. BILL RCC QTY (THEORITICAL) | G17: 0 | H17: Cum | J17: 0 | K17: 0 | L17: 0
B18: PREV. BILL RCC QTY (CASTING-ACTUAL) | G18: 0 | H18: Cum | J18: 0 | K18: 0 | L18: 0
B19: DIFFERENCE (WASTAGE) | G19: =G17-G18 -> 0 | H19: Cum | J19: =J17-J18 -> 0 | K19: =K17-K18 -> 0 | L19: =L18-L17 -> 0
B20: WASTAGE % | G20: =G19/G17 -> #DIV/0! | I20: =I19/I17 -> #DIV/0! | J20: =J19/J17 -> #DIV/0! | K20: =K19/K17 -> #DIV/0! | L20: =L19/L17 -> #DIV/0!
B22: THIS BILL RCC QTY (THEORITICAL) | G22: =G12-G17 -> 805.00787 | H22: Cum | I22: =I12-I17 -> 56.798193 | J22: =J12-J17 -> 748.20967 | K22: =K12-K17 -> 0 | L22: =L12-L17 -> 0
B23: THIS BILL RCC QTY (CASTING-ACTUAL) | G23: =G13-G18 -> 829.2 | H23: Cum | I23: =I13-I18 -> 66.2 | J23: =J13-J18 -> 763 | K23: =K13-K18 -> 0 | L23: =L13-L18 -> 0
B24: DIFFERENCE (WASTAGE) | G24: =G22-G23 -> -24.192134 | H24: Cum | I24: =I22-I23 -> -9.4018075 | J24: =J22-J23 -> -14.790326 | K24: =K22-K23 -> 0 | L24: =L23-L22 -> 0
B25: WASTAGE % | G25: =G24/G22 -> -0.030052046 | I25: =I24/I22 -> -0.16553005 | J25: =J24/J22 -> -0.019767622 | K25: =K24/K22 -> #DIV/0! | L25: =L24/L22 -> #DIV/0!

Sheet PCC & RCC REC.
A1: S.NO. | B1: MONTH | C1: DATE | D1: RMC | H1: ELSA | L1: MANUAL | P1: WORK IN PROGRSS | Q1: TOTAL | R1: REMARK
D2: GRADE | H2: GRADE | L2: GRADE
D3: M10 | E3: M25 | F3: M30 | G3: M35 | H3: M10 | I3: M25 | J3: M30 | K3: M35 | L3: M10 | M3: M25 | N3: M30 | O3: M35
A5: 1 | B5: 45778 | C5: 45791 | H5: 3.3 | R5: TOWER-E FOUNDATION PCC CASTING WORK
A6: 2 | C6: 45797 | H6: 5.4 | R6: TOWER-E FOUNDATION PCC CASTING WORK
A7: 3 | C7: 45786 | D7: 40 | R7: TOWER-E RAFT PCC
A8: 4 | C8: 45789 | D8: 17.5 | R8: TOWER-E RAFT PCC
A9: 5 | C9: 45806 | E9: 70 | R9: TOWER-E RAFT RCC
A10: 6 | C10: 45807 | E10: 329 | R10: TOWER-E RAFT RCC
A11: 7 | C11: 45808 | E11: =357+7 -> 364 | R11: TOWER-E RAFT RCC
B16: TOTAL | D16: =SUM(D4:D15) -> 57.5 | E16: =SUM(E4:E15) -> 763 | F16: =SUM(F4:F15) -> 0 | G16: =SUM(G4:G15) -> 0 | H16: =SUM(H4:H15) -> 8.7 | I16: =SUM(I4:I15) -> 0 | J16: =SUM(J4:J15) -> 0 | K16: =SUM(K4:K15) -> 0 | ... P16: =SUM(P4:P15) -> 0 | Q16: =SUM(D16:P16) -> 829.2
B18: GRAND TOTAL | D18: =D16 -> 57.5 | E18: =E16 -> 763 | G18: =G16 -> 0 | H18: =H16 -> 8.7 | I18: =I16 -> 0 | K18: =K16 -> 0 | L18: =L16 -> 0 | M18: =M16 -> 0 | O18: =O16 -> 0 | P18: =P16 -> 0 | Q18: =Q16 -> 829.2
B19: TOTAL RCC BY RMC/ELSA /MANUAL | D19: =D18+E18+G18 -> 820.5 | H19: =H18+I18+K18 -> 8.7 | L19: =L18+M18+O18 -> 0 | P19: =P18 -> 0 | Q19: =D19+H19+P19+L19 -> 829.2
B20: RCC BY RMC + ELSA | D20: =SUM(D19:O19) -> 829.2

Sheet RMC RECEIVING
A1: M/s. MARCO ENTERPRISES : RMC RECEIVING AT OMAXE ANANDA TOWER-E -PRAYAGRAJ
A2: SN | B2: DATE | C2: VEHICLE NO | D2: CHALLAN NO/INVOICE NO. | E2: MATERIAL GRADE | F2: UNIT | G2: RMC PLANT QTY (M 10) | H2: RMC PLANT QTY (M 25) | I2: RMC PLANT QTY (M 30) | J2: RMC PLANT QTY (M 35) | K2: ACTUAL CEMENT WEIGHT BY DESIGN MIX | L2: CEMENT WEIGHT BY RMC PLANT | M2: CEMENT DIFF (IN KG) | N2: IN TIME | O2: OUT TIME | P2: TOWER NO | Q2: TYPE OF WORK | R2: RMC SUPPLIER | S2: REMARKS
A3: 1 | B3: 45786 | C3: UP32VN6145 | D3: 449 | E3: RMC10 | F3: CUM | G3: 7 | K3: =G3*220 -> 1540 | L3: 1096 | M3: =L3-K3 -> -444 | N3: 0.45138889 | O3: 0.51041667 | P3: TOWER-E RAFT PCC | Q3: RAFT PCC | R3: SHUBHAM
A4: 2 | B4: 45786 | C4: UP32WN8332 | D4: 450 | E4: RMC10 | F4: CUM | G4: 7 | K4: =G4*220 -> 1540 | L4: 1096 | M4: =L4-K4 -> -444 | N4: 0.52083333 | O4: 0.56944444 | P4: TOWER-E RAFT PCC | Q4: RAFT PCC | R4: SHUBHAM
A5: 3 | B5: 45786 | C5: UP53HT5034 | D5: 451 | E5: RMC10 | F5: CUM | G5: 7 | K5: =G5*220 -> 1540 | L5: 1096 | M5: =L5-K5 -> -444 | N5: 0.57777778 | O5: 0.61111111 | P5: TOWER-E RAFT PCC | Q5: RAFT PCC | R5: SHUBHAM
A6: 4 | B6: 45786 | C6: UP32VN6145 | D6: 453 | E6: RMC10 | F6: CUM | G6: 7 | K6: =G6*220 -> 1540 | L6: 1096 | M6: =L6-K6 -> -444 | N6: 0.61805556 | O6: 0.66666667 | P6: TOWER-E RAFT PCC | Q6: RAFT PCC | R6: SHUBHAM
A7: 5 | B7: 45786 | C7: UP32WN8334 | D7: 454 | E7: RMC10 | F7: CUM | G7: 6 | K7: =G7*220 -> 1320 | L7: 1096 | M7: =L7-K7 -> -224 | N7: 0.6875 | O7: 0.73958333 | P7: TOWER-E RAFT PCC | Q7: RAFT PCC | R7: SHUBHAM
A8: 6 | B8: 45786 | C8: UP53HT5034 | D8: 457 | E8: RMC10 | F8: CUM | G8: 6 | K8: =G8*220 -> 1320 | L8: 1096 | M8: =L8-K8 -> -224 | N8: 0.77430556 | O8: 0.8125 | P8: TOWER-E RAFT PCC | Q8: RAFT PCC | R8: SHUBHAM
A9: 7 | B9: 45789 | C9: UP32WN8334 | D9: 487 | E9: RMC10 | F9: CUM | G9: 5 | K9: =G9*220 -> 1100 | L9: 1096 | M9: =L9-K9 -> -4 | N9: 0.77430556 | O9: 0.8125 | P9: TOWER-E RAFT PCC | Q9: RAFT PCC | R9: SHUBHAM
A10: 8 | B10: 45789 | C10: UP32WN8334 | D10: 488 | E10: RMC10 | F10: CUM | G10: 5 | K10: =G10*220 -> 1100 | L10: 1096 | M10: =L10-K10 -> -4 | N10: 0.77430556 | O10: 0.8125 | P10: TOWER-E RAFT PCC | Q10: RAFT PCC | R10: SHUBHAM
A11: 9 | B11: 45789 | C11: UP32VN6144 | D11: 490 | E11: RMC10 | F11: CUM | G11: 5.5 | K11: =G11*220 -> 1210 | L11: 1096 | M11: =L11-K11 -> -114 | N11: 0.77430556 | O11: 0.8125 | P11: TOWER-E RAFT PCC | Q11: RAFT PCC | R11: SHUBHAM
A12: 10 | B12: 45789 | C12: UP32VN6144 | D12: 494 | E12: RMC10 | F12: CUM | G12: 2 | K12: =G12*220 -> 440 | L12: 1096 | M12: =L12-K12 -> 656 | N12: 0.77430556 | O12: 0.8125 | P12: TOWER-E RAFT PCC | Q12: RAFT PCC | R12: SHUBHAM
A13: 11 | B13: 29.05.2025 | C13: UP32VN6145 | D13: 721 | E13: RMC 25 | F13: CUM | H13: 7 | K13: =H13*365 -> 2555 | L13: 2563 | M13: =L13-K13 -> 8 | N13: 0.9375 | O13: 0.96388889 | P13: TOWER-E (23-43) | Q13: RAFT | R13: SHUBHAM
A14: 12 | B14: 29.05.2025 | C14: UP32WN8334 | D14: 722 | E14: RMC 25 | F14: CUM | H14: 7 | K14: =H14*365 -> 2555 | L14: 2558 | M14: =L14-K14 -> 3 | N14: 0.96666667 | O14: 0.98125 | P14: TOWER-E (23-43) | Q14: RAFT | R14: SHUBHAM
A15: 13 | B15: 29.05.2025 | C15: UP32WN8333 | D15: 723 | E15: RMC 25 | F15: CUM | H15: 7 | K15: =H15*365 -> 2555 | L15: 2564 | M15: =L15-K15 -> 9 | N15: 0.98541667 | O15: 12:02PM | P15: TOWER-E (23-43) | Q15: RAFT | R15: SHUBHAM
A16: 14 | B16: 29.05.2025 | C16: UP32HT5032 | D16: 724 | E16: RMC 25 | F16: CUM | H16: 7 | K16: =H16*365 -> 2555 | L16: 2574 | M16: =L16-K16 -> 19 | N16: 0.50347222 | O16: 0.013194444 | P16: TOWER-E (23-43) | Q16: RAFT | R16: SHUBHAM
A17: 15 | B17: 29.05.2025 | C17: UP32HT5034 | D17: 725 | E17: RMC 25 | F17: CUM | H17: 5.5 | K17: =H17*365 -> 2007.5 | L17: 2018 | M17: =L17-K17 -> 10.5 | N17: 0.015972222 | O17: 0.029166667 | P17: TOWER-E (23-43) | Q17: RAFT | R17: SHUBHAM
B18: 29.05.2025 | C18: UP32HT5034 | D18: 726 | E18: RMC 25 | F18: CUM | H18: 1.5 | K18: =H18*365 -> 547.5 | L18: 548 | M18: =L18-K18 -> 0.5 | N18: 0.015972222 | O18: 0.029166667 | P18: TOWER-E (23-43) | Q18: RAFT | R18: SHUBHAM
A19: 16 | B19: 29.05.2025 | C19: UP70QT2013 | D19: 905350012 | E19: RMC 25 | F19: CUM | H19: 7 | K19: =H19*365 -> 2555 | L19: 2555 | M19: =L19-K19 -> 0 | N19: 0.9375 | O19: 0.96319444 | P19: TOWER-E (23-43) | Q19: RAFT | R19: ULTRATECH
A20: 17 | B20: 29.05.2025 | C20: UP70QT2341 | D20: 905350013 | E20: RMC 25 | F20: CUM | H20: 7 | K20: =H20*365 -> 2555 | L20: 2555 | M20: =L20-K20 -> 0 | N20: 0.96736111 | O20: 0.98680556 | P20: TOWER-E (23-43) | Q20: RAFT | R20: ULTRATECH
A21: 18 | B21: 29.05.2025 | C21: UP70QT2015 | D21: 905350014 | E21: RMC 25 | F21: CUM | H21: 7 | K21: =H21*365 -> 2555 | L21: 2555 | M21: =L21-K21 -> 0 | N21: 0.98680556 | O21: 1.0083333 | P21: TOWER-E (23-43) | Q21: RAFT | R21: ULTRATECH
A22: 19 | B22: 29.05.2025 | C22: UP70QT2342 | D22: 905350015 | E22: RMC 25 | F22: CUM | H22: 7 | K22: =H22*365 -> 2555 | L22: 2556 | M22: =L22-K22 -> 1 | N22: 0.052777778 | O22: 0.071527778 | P22: TOWER-E (23-43) | Q22: RAFT | R22: ULTRATECH
A23: 20 | B23: 29.05.2025 | C23: UP70QT2014 | D23: 905350016 | E23: RMC 25 | F23: CUM | H23: 7 | K23: =H23*365 -> 2555 | L23: 2555 | M23: =L23-K23 -> 0 | N23: 0.075694444 | O23: 0.086805556 | P23: TOWER-E (23-43) | Q23: RAFT | R23: ULTRATECH
A24: 21 | B24: 30.05.2025 | C24: UP32VN6145 | D24: 727 | E24: RMC 25 | F24: CUM | H24: 7 | K24: =H24*365 -> 2555 | L24: 2561 | M24: =L24-K24 -> 6 | N24: 0.043055556 | O24: 0.076388889 | P24: TOWER-E (23-43) | Q24: RAFT | R24: SHUBHAM
A25: 22 | B25: 30.05.2025 | C25: UP32WN8334 | D25: 728 | E25: RMC 25 | F25: CUM | H25: 7 | K25: =H25*365 -> 2555 | L25: 2551 | M25: =L25-K25 -> -4 | N25: 0.077777778 | O25: 0.09375 | P25: TOWER-E (23-43) | Q25: RAFT | R25: SHUBHAM
A26: 23 | B26: 30.05.2025 | C26: UP32WN8332 | D26: 729 | E26: RMC 25 | F26: CUM | H26: 7 | K26: =H26*365 -> 2555 | L26: 2557 | M26: =L26-K26 -> 2 | N26: 0.096527778 | O26: 0.10625 | P26: TOWER-E (23-43) | Q26: RAFT | R26: SHUBHAM
A27: 24 | B27: 30.05.2025 | C27: UP32WN8333 | D27: 730 | E27: RMC 25 | F27: CUM | H27: 7 | K27: =H27*365 -> 2555 | L27: 2557 | M27: =L27-K27 -> 2 | N27: 0.10763889 | O27: 0.12708333 | P27: TOWER-E (23-43) | Q27: RAFT | R27: SHUBHAM
A28: 25 | B28: 30.05.2025 | C28: UP32VN6144 | D28: 731 | E28: RMC 25 | F28: CUM | H28: 7 | K28: =H28*365 -> 2555 | L28: 2561 | M28: =L28-K28 -> 6 | N28: 0.12708333 | O28: 0.14097222 | P28: TOWER-E (23-43) | Q28: RAFT | R28: SHUBHAM
A29: 26 | B29: 30.05.2025 | C29: UP53HT5032 | D29: 732 | E29: RMC 25 | F29: CUM | H29: 7 | K29: =H29*365 -> 2555 | L29: 2560 | M29: =L29-K29 -> 5 | N29: 0.14305556 | O29: 0.15833333 | P29: TOWER-E (23-43) | Q29: RAFT | R29: SHUBHAM
A30: 27 | B30: 30.05.2025 | C30: UP32VN6145 | D30: 733 | E30: RMC 25 | F30: CUM | H30: 7 | K30: =H30*365 -> 2555 | L30: 2570 | M30: =L30-K30 -> 15 | N30: 0.16180556 | O30: 0.17083333 | P30: TOWER-E (23-43) | Q30: RAFT | R30: SHUBHAM
... A122: 118 | B122: 31.05.2025 | C122: UP70QT2014 | D122: 905350052 | E122: RMC 25 | F122: CUM | H122: 7 | K122: =H122*365 -> 2555 | L122: 2554 | M122: =L122-K122 -> -1 | N122: 0.083333333 | O122: 0.097222222 | P122: TOWER-E (23-43) | Q122: RAFT | R122: ULTRATECH
B124: Total Qty upto date | G124: =SUM(G3:G123) -> 57.5 | H124: =SUM(H3:H123) -> 763 | I124: =SUM(I3:I123) -> 0 | J124: =SUM(J3:J123) -> 0 | K124: =SUM(K3:K123) -> 291145 | L124: =SUM(L3:L123) -> 289936 | M124: =SUM(M3:M123) -> -1209
G125: =SUM(G124:J124) -> 820.5 | K125: =K124/50 -> 5822.9 | L125: =L124/50 -> 5798.72 | M125: BAGS

Sheet CONCRETE WORK MB
A1: COMPANY- OMAXE PANCHAM REALCON PVT LTD
A2: PROJECT- TOWER-E
A3: LOCATION- NAINI, PRAYAGRAJ
A4: MB SHEET- CONCRETE WORK
A6: S.NO. | B6: DESCRIPTION | C6: UNIT | D6: NOS | E6: NOS | F6: MEASUREMENT | I6: QTY. | J6: REMARKS
F7: L | G7: B | H7: H/T
B8: RAFT PCC- M10
A9: 1 | B9: GRID (22'-43'/A-Q') | C9: CUM | D9: 1 | E9: 1 | F9: =31.935+0.115+0.115 -> 32.165 | G9: =36.895+0.115+0.115 -> 37.125 | H9: 0.1 | I9: =PRODUCT(D9:H9) -> 119.41256
A10: 2 | C10: CUM | D10: 1 | E10: 1 | F10: =8.78+0.115+0.115 -> 9.01 | G10: 0.515 | H10: 0.1 | I10: =PRODUCT(D10:H10) -> 0.464015
A11: 3 | B11: GRID (22'-26'/M'-Q') | C11: CUM | D11: -1 | E11: 1 | F11: 11.005 | G11: 12.415 | H11: 0.1 | I11: =PRODUCT(D11:H11) -> -13.662707
A12: 4 | B12: GRID (38'-43'/A-E') | C12: CUM | D12: -1 | E12: 1 | F12: 11.09 | G12: 10.285 | H12: 0.1 | I12: =PRODUCT(D12:H12) -> -11.406065
A13: 5 | B13: GRID (22'-30'/A-B') | C13: CUM | D13: -1 | E13: 1 | F13: 11.285 | G13: 3.72 | H13: 0.1 | I13: =PRODUCT(D13:H13) -> -4.19802
A14: 6 | C14: CUM | D14: -1 | E14: 1 | F14: 1.695 | G14: 2.315 | H14: 0.1 | I14: =PRODUCT(D14:H14) -> -0.3923925
A15: 7 | C15: CUM | D15: -1 | E15: 1 | F15: 3.95 | G15: 1.5 | H15: 0.1 | I15: =PRODUCT(D15:H15) -> -0.5925
D16: -1 | E16: 1 | F16: 15.8 | G16: =0.115 -> 0.115 | H16: 0.1 | I16: =PRODUCT(D16:H16) -> -0.1817
A17: 8 | B17: EXISTING RAFT (DETAILS IN JMR) | C17: CUM | D17: -1 | E17: 1 | F17: 9 | G17: =5.8+0.115 -> 5.915 | H17: 0.1 | I17: =PRODUCT(D17:H17) -> -5.3235
A18: 9 | C18: CUM | D18: -1 | E18: 1 | F18: 19.05 | G18: 10 | H18: 0.1 | I18: =PRODUCT(D18:H18) -> -19.05
A19: 10 | C19: CUM | D19: -1 | E19: 1 | F19: 6.2 | G19: 6.2 | H19: 0.1 | I19: =PRODUCT(D19:H19) -> -3.844
A20: 11 | C20: CUM | D20: -1 | E20: 1 | F20: =11.7-6.2 -> 5.5 | G20: 8.05 | H20: 0.1 | I20: =PRODUCT(D20:H20) -> -4.4275
H23: TOTAL | I23: =SUM(I8:I22) -> 56.798193
A25: S.NO. | B25: DESCRIPTION | C25: UNIT | D25: NOS | E25: NOS | F25: MEASUREMENT | I25: QTY. | J25: REMARKS
F26: L | G26: B | H26: H/T
B27: RAFT RCC- M25
A28: 1 | B28: GRID (22'-43'/A-Q') | C28: CUM | D28: 1 | E28: 1 | F28: =31.935 -> 31.935 | G28: =36.895 -> 36.895 | H28: 0.85 | I28: =PRODUCT(D28:H28) -> 1001.5056
A29: 2 | C29: CUM | D29: 1 | E29: 1 | F29: =8.78 -> 8.78 | G29: 0.515 | H29: 0.85 | I29: =PRODUCT(D29:H29) -> 3.843445
A30: 3 | B30: GRID (22'-26'/M'-Q') | C30: CUM | D30: -1 | E30: 1 | F30: 11.005 | G30: 12.415 | H30: 0.85 | I30: =PRODUCT(D30:H30) -> -116.13301
A31: 4 | B31: GRID (38'-43'/A-E') | C31: CUM | D31: -1 | E31: 1 | F31: 11.09 | G31: 10.285 | H31: 0.85 | I31: =PRODUCT(D31:H31) -> -96.951552
A32: 5 | B32: GRID (22'-30'/A-B') | C32: CUM | D32: -1 | E32: 1 | F32: 11.285 | G32: 3.72 | H32: 0.85 | I32: =PRODUCT(D32:H32) -> -35.68317
A33: 6 | C33: CUM | D33: -1 | E33: 1 | F33: 1.695 | G33: 2.315 | H33: 0.85 | I33: =PRODUCT(D33:H33) -> -3.3353363
A34: 7 | C34: CUM | D34: -1 | E34: 1 | F34: 3.95 | G34: 1.5 | H34: 0.85 | I34: =PRODUCT(D34:H34) -> -5.03625
H37: TOTAL | I37: =SUM(I27:I36) -> 748.20967

Sheet SHUTT. WORK SUMMARY
A1: TOWER-E CENTERING & SHUTTERING WORK SUMMARY
D2: QTY | J2: TOTAL
A3: 3 | B3: CENTRING AND SHUTTERING | D3: 1ST RA | E3: 2ND RA | F3: 3rd RA | G3: 4th RA | H3: 5th RA | I3: 6th RA
B4: Providing and fixing plywood or steel plate shuttering and centring for structural concrete work in locations called for including strutting, propping, bracing, bolting, wedging, casing, striking, removal etc. complete for any size, section, thickness. Props shall consist of well designed steel pipes adequately braced (wooden ballies as props shall not be permitted). The item to include centering and shuttering at all heights and levels. Allow for forming grooves, drip course, chamfers, cut-outs, openings etc. where called for and for dressing with approved shuttering oil to prevent adhesion. Unexposed concrete surfaces subsequently left untreated (in the condition obtained on removal of form work) shall not constitute exposed concrete work and shall be measured under this item only Irregular shapes with sides (like circular, semi-circular, oval etc.) which may not be perpendicular to each other for shapes not conforming to rectangle or square, and circular shuttering shall not be paid separately. Joints of soffits of the slab shall be made clean after concreting and de-shuttering. (quoted rate to include all staging upto 3.50 mtr height). Note:- Contractor shall take necessary precautions such as watertight shuttering. This is inclusive of RCC members, leaving shuttering & centring for pour strip, slab in slope, RCC members in curved (in plan), etc., nothing is payable extra on this account.
A5: 3.1.1. | B5: Foundation, column footings, raft slab, raft beams, plinth beam, lift pits, sump pits, pedestals / bases of column, column up to plinth, swimming pool, Retaining wall foundations, grade slab etc. | C5: SQM | D5: ='SHUTTERING WORK MB'!I37 -> 90.1365 | J5: =SUM(D5:I5) -> 90.1365
A6: 3.1.2. | B6: Suspended floors, roofs, balconies, shelves/ counters, stair waist slabs, folded plate stairs and landings, swimming pool slab, lintel and floor beams, landing beams, girders (deep beams), RCC bands, swimming pool beam, cantilever projections, coping, cills, slab of tank etc at all levels.
A7: 3.1.2.1. | B7: Stilt Floor level to 7th Floor level | C7: SQM | J7: =SUM(D7:I7) -> 0
A8: 3.1.2.2. | B8: 7th Floor level to to Terrace Including OHT, Mumty, Machine Room, Parapet | C8: SQM | J8: =SUM(D8:I8) -> 0
A9: 3.1.2..3 | B9: All type of Moulding, Bands, Elevation/Architectural Features as per drawing and as directed by EIC. at all level | C9: SQM | J9: =SUM(D9:I9) -> 0
A11: 3.2. | B11: Columns, Wall, pillars, piers, abutments, posts and struts, offset and projection of columns, water tank walls, lift walls, Retaining Wall, swimming pool, Parapets, planters, vertical projection of pergolas, wall and ramp walls etc. at all levels.
A12: 3.2.1. | B12: Stilt Floor level to 7th Floor level | C12: SQM | J12: =SUM(D12:I12) -> 0
A13: 3.2.2. | B13: 7th Floor level to to Terrace Including OHT, Mumty, Machine Room, Parapet | C13: SQM | J13: =SUM(D13:I13) -> 0
A14: 3.2.3. | B14: All type of Moulding, Bands, Elevation/Architectural Features as per drawing and as directed by EIC. at all level | C14: SQM | J14: =SUM(D14:I14) -> 0
A16: 3.3. | B16: Extra for additional height in centring, shuttering where ever required with adequate bracing, propping etc. including cost of de-shuttering and decentring at all levels, over and above height of 3.50 mtr (Plan area to be measured and shall be paid proportionately on actual height) – for every 1.0 mtr. height | C16: SQM | J16: =SUM(D16:I16) -> 0
I18: TOTAL | J18: =SUM(J4:J17) -> 90.1365

Sheet SHUTTERING WORK MB
A1: COMPANY- OMAXE PANCHAM REALCON PVT LTD
A2: PROJECT- TOWER-E
A3: LOCATION- NAINI, PRAYAGRAJ
A4: MB SHEET- SHUTTERING BELOW PLINTH BEAM
A6: S.NO. | B6: DESCRIPTION | C6: UNIT | D6: NOS | E6: NOS | F6: MEASUREMENT | I6: QTY. | J6: REMARKS
F7: L | G7: B | H7: H/T
B8: PCC SHUTTERING
A9: 1 | B9: GRID (26'/Q') | C9: SQM | D9: 1 | E9: 1 | F9: 0.7 | H9: 0.1 | I9: =PRODUCT(D9:H9) -> 0.07
A10: 2 | B10: GRID (26'-43'/Q') | C10: SQM | D10: 1 | E10: 1 | F10: =25.89+0.515+0.515 -> 26.92 | H10: 0.1 | I10: =PRODUCT(D10:H10) -> 2.692
A11: 3 | B11: GRID (43'/E'-Q') | C11: SQM | D11: 1 | E11: 1 | F11: 21.65 | H11: 0.1 | I11: =PRODUCT(D11:H11) -> 2.165
A12: 4 | B12: GRID (38'-43'/E') | C12: SQM | D12: 1 | E12: 1 | F12: 11.09 | H12: 0.1 | I12: =PRODUCT(D12:H12) -> 1.109
A13: 5 | B13: GRID (38'/A-E') | C13: SQM | D13: 1 | E13: 1 | F13: 10.285 | H13: 0.1 | I13: =PRODUCT(D13:H13) -> 1.0285
A14: 6 | B14: GRID (30-38'/A) | C14: SQM | D14: 1 | E14: 1 | F14: 8.875 | H14: 0.1 | I14: =PRODUCT(D14:H14) -> 0.8875
A15: 7 | B15: GRID (30/A-A') | C15: SQM | D15: 1 | E15: 1 | F15: 1.5 | H15: 0.1 | I15: =PRODUCT(D15:H15) -> 0.15
A16: 8 | B16: GRID (27'-30/A') | C16: SQM | D16: 1 | E16: 1 | F16: 3.95 | H16: 0.1 | I16: =PRODUCT(D16:H16) -> 0.395
A17: 9 | B17: GRID (27'/A'-B) | C17: SQM | D17: 1 | E17: 1 | F17: 0.815 | H17: 0.1 | I17: =PRODUCT(D17:H17) -> 0.0815
A18: 10 | B18: GRID (26'-27'/B) | C18: SQM | D18: 1 | E18: 1 | F18: 1.695 | H18: 0.1 | I18: =PRODUCT(D18:H18) -> 0.1695
A19: 11 | B19: GRID (26'/B-B') | C19: SQM | D19: 1 | E19: 1 | F19: 1.405 | H19: 0.1 | I19: =PRODUCT(D19:H19) -> 0.1405
A20: 12 | B20: GRID (22'-26'/B') | C20: SQM | D20: 1 | E20: 1 | F20: =11.285-9 -> 2.285 | H20: 0.1 | I20: =PRODUCT(D20:H20) -> 0.2285 | J20: -9mtr as per JMR
B21: RAFT SHUTTERING
A22: 1 | B22: GRID (22'-26'/M') | C22: SQM | D22: 1 | E22: 1 | F22: 11.005 | H22: =0.85-0.3 -> 0.55 | I22: =PRODUCT(D22:H22) -> 6.05275
A23: =+A22+1 -> 2 | B23: GRID (26/M'-Q) | C23: SQM | D23: 1 | E23: 1 | F23: 12.415 | H23: =0.85-0.3 -> 0.55 | I23: =PRODUCT(D23:H23) -> 6.82825
A24: =+A23+1 -> 3 | B24: GRID (26'-43'/Q') | C24: SQM | D24: 1 | E24: 1 | F24: =25.89+0.515+0.515 -> 26.92 | H24: =0.85-0.3 -> 0.55 | I24: =PRODUCT(D24:H24) -> 14.806
A25: =+A24+1 -> 4 | B25: GRID (43'/E'-Q') | C25: SQM | D25: 1 | E25: 1 | F25: 21.65 | H25: =0.85-0.3 -> 0.55 | I25: =PRODUCT(D25:H25) -> 11.9075
A26: =+A25+1 -> 5 | B26: GRID (38'-43'/E') | C26: SQM | D26: 1 | E26: 1 | F26: 11.09 | H26: =0.85-0.3 -> 0.55 | I26: =PRODUCT(D26:H26) -> 6.0995
A27: =+A26+1 -> 6 | B27: GRID (38'/A-E') | C27: SQM | D27: 1 | E27: 1 | F27: 10.285 | H27: =0.85-0.3 -> 0.55 | I27: =PRODUCT(D27:H27) -> 5.65675
A28: =+A27+1 -> 7 | B28: GRID (30-38'/A) | C28: SQM | D28: 1 | E28: 1 | F28: 8.875 | H28: =0.85-0.3 -> 0.55 | I28: =PRODUCT(D28:H28) -> 4.88125
A29: =+A28+1 -> 8 | B29: GRID (30/A-A') | C29: SQM | D29: 1 | E29: 1 | F29: 1.5 | H29: =0.85-0.3 -> 0.55 | I29: =PRODUCT(D29:H29) -> 0.825
A30: =+A29+1 -> 9 | B30: GRID (27'-30/A') | C30: SQM | D30: 1 | E30: 1 | F30: 3.95 | H30: =0.85-0.3 -> 0.55 | I30: =PRODUCT(D30:H30) -> 2.1725
A31: =+A30+1 -> 10 | B31: GRID (27'/A'-B) | C31: SQM | D31: 1 | E31: 1 | F31: 0.815 | H31: =0.85-0.3 -> 0.55 | I31: =PRODUCT(D31:H31) -> 0.44825
A32: =+A31+1 -> 11 | B32: GRID (26'-27'/B) | C32: SQM | D32: 1 | E32: 1 | F32: 1.695 | H32: =0.85-0.3 -> 0.55 | I32: =PRODUCT(D32:H32) -> 0.93225
A33: =+A32+1 -> 12 | B33: GRID (26'/B-B') | C33: SQM | D33: 1 | E33: 1 | F33: 1.405 | H33: =0.85-0.3 -> 0.55 | I33: =PRODUCT(D33:H33) -> 0.77275
A34: =+A33+1 -> 13 | B34: GRID (22'-26'/B') | C34: SQM | D34: 1 | E34: 1 | F34: 11.285 | H34: =0.85-0.3 -> 0.55 | I34: =PRODUCT(D34:H34) -> 6.20675
A35: =+A34+1 -> 14 | B35: GRID (22'-26'/B') | C35: SQM | D35: 1 | E35: 1 | F35: =15.8 -> 15.8 | H35: 0.85 | I35: =PRODUCT(D35:H35) -> 13.43
H37: TOTAL | I37: =SUM(I8:I36) -> 90.1365

Sheet BRICK WORK SUMMARY
A2: TOWER-E BRICK WORK SUMMARY
D3: QTY | J3: TOTAL
A4: 5 | B4: MASONARY WORK | D4: 1ST RA | E4: 2ND RA | F4: 3rd RA | G4: 4th RA | H4: 5th RA | I4: 6th RA
B5: (Quoted Rates are for all heights, all depths, all levels, including basement to roof (mumty) & all leads and lifts, including curved or circular including elevation masonary work) (Basic Rate of Brick @ Rs. 7/No. FOR at site without GST)
A6: 5.1. | B6: Brick work in Sub Structure (Up to Stilt Floor level):
B7: Providing and laying 230mm thick brick masonry using 1st quality burnt clay FPS bricks in Sub-Structure laid in cement mortar 1:6 (1 cement : 6 coarse sand) mix, joints finished, flush/ raked to 6mm depth including scaffolding, curing complete as per specification and drawing or as directed by Project Manager. | C7: CUM | J7: =SUM(D7:I7) -> 0
A8: 5.2. | B8: Brick work in Sub Structure (Up to Stilt Floor level):
B9: Providing and laying of 115 mm thick brick work with 1st quality burnt clay FPS bricks in sub-superstructure laid in cement mortar 1:4 (1 cement : 4 coarse sand) mix, joints finished, including placing hoop iron as per specification at every third course, scaffolding, curing complete in all respect as per direction of EIC. (Hoop iron shall be provided by client free of cost) (Items of RCC bands like shuttering, concrete and reinforcement to be paid in respective items). | C9: SQM | D9: ='BRICK WORK MB'!I24 -> 36.867 | J9: =SUM(D9:I9) -> 36.867
A10: 5.3. | B10: Brick work in Super Structure (Above Stilt FLoor level)
A11: 5.3.1 | B11: Providing and laying 230mm thick brick masonry using 1st quality burnt clay FPS bricks in Super-Structure laid in cement mortar 1:6 (1 cement : 6 coarse sand) mix, joints finished, flush/ raked to 6mm depth including scaffolding, curing complete as per specification and drawing or as directed by Project Manager.
A12: (a) | B12: Stilt Floor level to 7th Floor level | C12: CUM | J12: =SUM(D12:I12) -> 0
A13: (b) | B13: 7th Floor level to to Terrace Including OHT, Mumty, Machine Room, Parapet | C13: CUM | J13: =SUM(D13:I13) -> 0
A14: 5.4. | B14: Brick work in Super Structure (Above Stilt FLoor level)
A15: 5.4.1 | B15: Providing and laying of 115 mm thick brick work with 1st quality burnt clay FPS bricks in Super-Superstructure laid in cement mortar 1:4 (1 cement : 4 coarse sand) mix, joints finished, including placing hoop iron as per specification at every third course, scaffolding, curing complete in all respect as per direction of EIC. (Hoop iron shall be provided by client free of cost) (Items of RCC bands like shuttering, concrete and reinforcement to be paid in respective items).
A16: (a) | B16: Stilt Floor level to 7th Floor level | C16: SQM | J16: =SUM(D16:I16) -> 0
A17: (b) | B17: 7th Floor level to to Terrace Including OHT, Mumty, Machine Room, Parapet | C17: SQM | J17: =SUM(D17:I17) -> 0
A18: 5.8. | B18: Brick work in staircase steps:
B19: Providing and laying and constructing brickwork in staircase steps using 1st quality burnt clay FPS bricks in cement mortar 1:3 (1 cement : 3 coarse sand) at all heights and levels including cutting, chamfering scaffolding, curing, complete as per specification. | C19: CUM | J19: =SUM(D19:I19) -> 0
I21: TOTAL | J21: =SUM(J7:J20) -> 36.867

Sheet BRICK WORK MB
A1: COMPANY- OMAXE PANCHAM REALCON PVT LTD
A2: PROJECT- TOWER-E
A3: LOCATION- NAINI, PRAYAGRAJ
A4: MB SHEET- BRICK WORK BELOW PLINTH BEAM
A6: S.NO. | B6: DESCRIPTION | C6: UNIT | D6: NOS | E6: NOS | F6: MEASUREMENT | I6: QTY. | J6: REMARKS
F7: L | G7: B | H7: H/T
B8: RAFT OUTTER 115MM BRICK WORK
A9: 1 | B9: GRID (22'-26'/M') | C9: SQM | D9: 1 | E9: 1 | F9: 11.005 | H9: 0.3 | I9: =PRODUCT(D9:H9) -> 3.3015
A10: =+A9+1 -> 2 | B10: GRID (26/M'-Q) | C10: SQM | D10: 1 | E10: 1 | F10: 12.415 | H10: 0.3 | I10: =PRODUCT(D10:H10) -> 3.7245
A11: =+A10+1 -> 3 | B11: GRID (26'-43'/Q') | C11: SQM | D11: 1 | E11: 1 | F11: =25.89+0.515+0.515 -> 26.92 | H11: 0.3 | I11: =PRODUCT(D11:H11) -> 8.076
A12: =+A11+1 -> 4 | B12: GRID (43'/E'-Q') | C12: SQM | D12: 1 | E12: 1 | F12: 21.65 | H12: 0.3 | I12: =PRODUCT(D12:H12) -> 6.495
A13: =+A12+1 -> 5 | B13: GRID (38'-43'/E') | C13: SQM | D13: 1 | E13: 1 | F13: 11.09 | H13: 0.3 | I13: =PRODUCT(D13:H13) -> 3.327
A14: =+A13+1 -> 6 | B14: GRID (38'/A-E') | C14: SQM | D14: 1 | E14: 1 | F14: 10.285 | H14: 0.3 | I14: =PRODUCT(D14:H14) -> 3.0855
A15: =+A14+1 -> 7 | B15: GRID (30-38'/A) | C15: SQM | D15: 1 | E15: 1 | F15: 8.875 | H15: 0.3 | I15: =PRODUCT(D15:H15) -> 2.6625
A16: =+A15+1 -> 8 | B16: GRID (30/A-A') | C16: SQM | D16: 1 | E16: 1 | F16: 1.5 | H16: 0.3 | I16: =PRODUCT(D16:H16) -> 0.45
A17: =+A16+1 -> 9 | B17: GRID (27'-30/A') | C17: SQM | D17: 1 | E17: 1 | F17: 3.95 | H17: 0.3 | I17: =PRODUCT(D17:H17) -> 1.185
A18: =+A17+1 -> 10 | B18: GRID (27'/A'-B) | C18: SQM | D18: 1 | E18: 1 | F18: 0.815 | H18: 0.3 | I18: =PRODUCT(D18:H18) -> 0.2445
A19: =+A18+1 -> 11 | B19: GRID (26'-27'/B) | C19: SQM | D19: 1 | E19: 1 | F19: 1.695 | H19: 0.3 | I19: =PRODUCT(D19:H19) -> 0.5085
A20: =+A19+1 -> 12 | B20: GRID (26'/B-B') | C20: SQM | D20: 1 | E20: 1 | F20: 1.405 | H20: 0.3 | I20: =PRODUCT(D20:H20) -> 0.4215
A21: =+A20+1 -> 13 | B21: GRID (22'-26'/B') | C21: SQM | D21: 1 | E21: 1 | F21: 11.285 | H21: 0.3 | I21: =PRODUCT(D21:H21) -> 3.3855
H24: TOTAL | I24: =SUM(I8:I23) -> 36.867

Sheet TMT STEEL RECO.
A1: MARCO ENTERPRISES
A2: TOWER-E
A3: Reconcialation of TMT Steel
A4: S.NO. | B4: Description | C4: Unit | D4: Dia wise | K4: Total
D5: 6mm | E5: 8mm | F5: 10mm | G5: 12mm | H5: 16mm | I5: 20mm | J5: 25mm
A6: A | B6: Total Steel Received upto date | C6: Kg | D6: ='TMT STEEL REC.'!D12 -> 0 | E6: ='TMT STEEL REC.'!E12 -> 9070 | F6: ='TMT STEEL REC.'!F12 -> 6840 | G6: ='TMT STEEL REC.'!G12 -> 7700 | H6: ='TMT STEEL REC.'!H12 -> 67471 | I6: ='TMT STEEL REC.'!I12 -> 29380 | J6: ='TMT STEEL REC.'!J12 -> 15324 | K6: =SUM(E6:J6) -> 135785
A8: B | B8: Consumption Detail
A9: 4.1.1 | B9: Up To Stilt Floor Lvl. | C9: Kg | D9: ='TMT SUMMARY'!F9 -> 0 | E9: ='TMT SUMMARY'!G9 -> 0 | F9: ='TMT SUMMARY'!H9 -> 1205.4389 | G9: ='TMT SUMMARY'!I9 -> 1461.0184 | H9: ='TMT SUMMARY'!J9 -> 25667.402 | I9: ='TMT SUMMARY'!K9 -> 16032.785 | J9: ='TMT SUMMARY'!L9 -> 8560.5934 | K9: =SUM(E9:J9) -> 52927.237
A10: 4.1.2 | B10: Stilt Floor level to to Terrace Including OHT, Mumty, Machine Room, Parapet) | C10: Kg | D10: ='TMT SUMMARY'!F14 -> 0 | E10: ='TMT SUMMARY'!G14 -> 0 | F10: ='TMT SUMMARY'!H14 -> 0 | G10: ='TMT SUMMARY'!I14 -> 0 | H10: ='TMT SUMMARY'!J14 -> 0 | I10: ='TMT SUMMARY'!K14 -> 0 | J10: ='TMT SUMMARY'!L14 -> 0 | K10: =SUM(E10:J10) -> 0
A11: 4.1.3 | B11: All type of Moulding, Bands, Elevation/Architectural Features as per drawing and as directed by EIC. at all level | C11: Kg | D11: ='TMT SUMMARY'!F19 -> 0 | E11: ='TMT SUMMARY'!G19 -> 0 | F11: ='TMT SUMMARY'!H19 -> 0 | G11: ='TMT SUMMARY'!I19 -> 0 | H11: ='TMT SUMMARY'!J19 -> 0 | I11: ='TMT SUMMARY'!K19 -> 0 | J11: ='TMT SUMMARY'!L19 -> 0 | K11: =SUM(E11:J11) -> 0
A13: C | B13: Total consumption | D13: =SUM(D9:D12) -> 0 | E13: =SUM(E9:E12) -> 0 | F13: =SUM(F9:F12) -> 1205.4389 | G13: =SUM(G9:G12) -> 1461.0184 | H13: =SUM(H9:H12) -> 25667.402 | I13: =SUM(I9:I12) -> 16032.785 | J13: =SUM(J9:J12) -> 8560.5934 | K13: =SUM(K9:K12) -> 52927.237
A14: D | B14: Theoretical Balance | C14: Kg | D14: =D6-D13 -> 0 | E14: =E6-E13 -> 9070 | F14: =F6-F13 -> 5634.5611 | G14: =G6-G13 -> 6238.9816 | H14: =H6-H13 -> 41803.598 | I14: =I6-I13 -> 13347.215 | J14: =J6-J13 -> 6763.4066 | K14: =SUM(E14:J14) -> 82857.763
A15: E | B15: Steel available at yard | C15: Kg | E15: 9070 | F15: 5560 | G15: 6180 | H15: 41450 | I15: 13300 | J15: 6650 | K15: =SUM(E15:J15) -> 82210
A16: F | B16: W.I.P. Steel in column lap/lintel/kit Plateform etc | C16: Kg | K16: =SUM(E16:J16) -> 0
K17: =SUM(E17:J17) -> 0
A18: G | B18: Total In Progress | C18: Kg | D18: =SUM(D16:D17) -> 0 | E18: =SUM(E16:E17) -> 0 | F18: =SUM(F16:F17) -> 0 | G18: =SUM(G16:G17) -> 0 | H18: =SUM(H16:H17) -> 0 | I18: =SUM(I16:I17) -> 0 | J18: =SUM(J16:J17) -> 0 | K18: =SUM(E18:J18) -> 0
A21: H | B21: Wastage (D-E-F) | C21: Kg | D21: =D14-D15-D16 -> 0 | E21: =E14-E15-E16 -> 0 | F21: =F14-F15-F16 -> 74.561133 | G21: =G14-G15-G16 -> 58.981592 | H21: =H14-H15-H16 -> 353.59822 | I21: =I14-I15-I16 -> 47.215185 | J21: =J14-J15-J16 -> 113.40664 | K21: =SUM(E21:J21) -> 647.76277 | L21: =+K21/K13 -> 0.012238741
B22: SCRAP SALE | K22: 0
B23: Allowed Wastage 2.5% | C23: Kg | K23: =K13*2.5% -> 1323.1809

Sheet TMT STEEL REC.
A1: (OMAXE TOWER-E, PRAYAGRAJ )
A2: TMT STEEL BAR ISSUE BY OMAXE
A3: S.NO. | B3: DATE | C3: Unit | D3: 6MM Dia. | E3: 8mm Dia. | F3: 10mm Dia. | G3: 12mm Dia. | H3: 16mm Dia. | I3: 20mm Dia. | J3: 25mm Dia. | K3: TOTAL | L3: COMULAT.
A5: 1 | B5: RECEIVED AT 13/5/25 | C5: KG | E5: 9070 | F5: 6840 | I5: 20010 | K5: =SUM(E5:J5) -> 35920 | L5: =K5 -> 35920
A6: 2 | B6: RECEIVED AT 19/5/24 | C6: KG | G6: 7700 | H6: 37621 | I6: 9370 | J6: 5474 | K6: =SUM(E6:J6) -> 60165 | L6: =L5+K6 -> 96085
A7: 3 | B7: RECEIVED AT 24/5/25 | C7: KG | H7: 29850 | J7: 9850 | K7: =SUM(E7:J7) -> 39700 | L7: =L6+K7 -> 135785
K8: =SUM(E8:J8) -> 0 | L8: =L7+K8 -> 135785
K9: =SUM(E9:J9) -> 0 | L9: =L8+K9 -> 135785
B12: TOTAL QTY. | D12: =SUM(D4:D11) -> 0 | E12: =SUM(E4:E11) -> 9070 | F12: =SUM(F4:F11) -> 6840 | G12: =SUM(G4:G11) -> 7700 | H12: =SUM(H4:H11) -> 67471 | I12: =SUM(I4:I11) -> 29380 | J12: =SUM(J4:J11) -> 15324 | K12: =SUM(K4:K11) -> 135785 | L12: KG

Sheet TMT SUMMARY
A1: (OMAXE TOWER-E, PRAYAGRAJ )
A2: STEEL CONSUMPTION SUMMARY
A3: S.NO. | B3: DESCRIPTION | C3: LOCATION | D3: Unit | E3: NOS | F3: 6mm Dia. | G3: 8mm Dia. | H3: 10mm Dia. | I3: 12mm Dia. | J3: 16mm Dia. | K3: 20mm Dia. | L3: 25mm Dia. | M3: TOTAL
B4: 4.1 TMT REINFORCEMENT
A5: 4.1.1. | B5: UPTO STILRT FLOOR LVL
A6: 1 | B6: TOWER-E COLUMN GRID (22-23/A-Q) | C6: UPTO RAFT | D6: KG | E6: 1 | G6: ='COLUMN BBS'!P590*$E$6 -> 0 | H6: ='COLUMN BBS'!Q590*$E$6 -> 631.1908 | I6: ='COLUMN BBS'!R590*$E$6 -> 322.96205 | J6: ='COLUMN BBS'!S590*$E$6 -> 773.44476 | K6: ='COLUMN BBS'!T590*$E$6 -> 656.77869 | L6: ='COLUMN BBS'!U590*$E$6 -> 76.61988 | M6: =SUM(F6:L6) -> 2460.9962
A7: 2 | B7: TOWER-E RAFT GRID (22-23/A-Q) | C7: AS SUB-STRUCTURE | D7: KG | E7: 1 | G7: ='RAFT BBS'!Q786*$E$7 -> 0 | H7: ='RAFT BBS'!R786*$E$7 -> 574.24807 | I7: ='RAFT BBS'!S786*$E$7 -> 1138.0564 | J7: ='RAFT BBS'!T786*$E$7 -> 24893.957 | K7: ='RAFT BBS'!U786*$E$7 -> 15376.006 | L7: ='RAFT BBS'!V786*$E$7 -> 8483.9735 | M7: =SUM(F7:L7) -> 50466.241
F9: =SUM(F6:F8) -> 0 | G9: =SUM(G6:G8) -> 0 | H9: =SUM(H6:H8) -> 1205.4389 | I9: =SUM(I6:I8) -> 1461.0184 | J9: =SUM(J6:J8) -> 25667.402 | K9: =SUM(K6:K8) -> 16032.785 | L9: =SUM(L6:L8) -> 8560.5934 | M9: =SUM(M6:M8) -> 52927.237
A10: 4.1.2. | B10: Stilt Floor level to to Terrace Including OHT, Mumty, Machine Room, Parapet)
A11: 1 | M11: =SUM(F11:L11) -> 0
A12: 2 | M12: =SUM(F12:L12) -> 0
F14: =SUM(F11:F13) -> 0 | G14: =SUM(G11:G13) -> 0 | H14: =SUM(H11:H13) -> 0 | I14: =SUM(I11:I13) -> 0 | J14: =SUM(J11:J13) -> 0 | K14: =SUM(K11:K13) -> 0 | L14: =SUM(L11:L13) -> 0 | M14: =SUM(M11:M13) -> 0
A15: 4.1.3. | B15: All type of Moulding, Bands, Elevation/Architectural Features as per drawing and as directed by EIC. at all level
A16: 1 | M16: =SUM(F16:L16) -> 0
A17: 2 | M17: =SUM(F17:L17) -> 0
F19: =SUM(F16:F18) -> 0 | G19: =SUM(G16:G18) -> 0 | H19: =SUM(H16:H18) -> 0 | I19: =SUM(I16:I18) -> 0 | J19: =SUM(J16:J18) -> 0 | K19: =SUM(K16:K18) -> 0 | L19: =SUM(L16:L18) -> 0 | M19: =SUM(M16:M18) -> 0

Sheet RAFT BBS
A1: TOWER-E RAFT BBS
A3: S.No. | B3: Description | C3: Shape of Bar in mm | G3: Spacing c/c | H3: Dia of Bar | I3: No's of Set | J3: No's of Bar | K3: Actual Length | L3: Lap | M3: No. Of Bend | N3: Deduction In mm | O3: Cut Length | P3: Total Length | Q3: TMT BAR Fe-500D or EQR | W3: Remarks
A4: A | B4: RAFT | Q4: 8mm | R4: 10mm | S4: 12mm | T4: 16mm | U4: 20mm | V4: 25mm
B5: BOTTOM MAIN BAR | Q5: =IF($H5=8,$P5,"") | R5: =IF($H5=10,$P5,"") | S5: =IF($H5=12,$P5,"") | T5: =IF($H5=16,$P5,"") | U5: =IF($H5=20,$P5,"") | V5: =IF($H5=25,$P5,"")
A6: 1 | B6: GRID (39'-43/E'-Q') | Q6: =IF($H6=8,$P6,"") | R6: =IF($H6=10,$P6,"") | S6: =IF($H6=12,$P6,"") | T6: =IF($H6=16,$P6,"") | U6: =IF($H6=20,$P6,"") | V6: =IF($H6=25,$P6,"")
